Workbook

Sheet Overview
A1: Daily flash sales by destination (metric tonnes)
A2: Source: user-supplied "hist_flash_sales.xlsx" (USDA FAS daily export sales). "Not Available" = unknown destinations. "Other" groups destinations with 3 or fewer sales.
A4: By delivery marketing year (USDA "Marketing Year": season the grain ships in)
A6: Corn
A7: Destination | B7: 2010/2011 | C7: 2011/2012 | D7: 2012/2013 | E7: 2013/2014 | F7: 2014/2015 | G7: 2015/2016 | H7: 2016/2017 | I7: 2017/2018 | J7: 2018/2019 | K7: 2019/2020 | L7: 2020/2021 | M7: 2021/2022 | N7: 2022/2023 | O7: 2023/2024 | P7: 2024/2025 | Q7: 2025/2026 | R7: 2026/2027 | S7: 2027/2028 | T7: 2028/2029 | U7: Total
A8: Not Available | B8: =SUMIFS('Not Available'!$H:$H,'Not Available'!$E:$E,B$7,'Not Available'!$G:$G,"Corn") -> 130000 | C8: =SUMIFS('Not Available'!$H:$H,'Not Available'!$E:$E,C$7,'Not Available'!$G:$G,"Corn") -> 100000 | D8: =SUMIFS('Not Available'!$H:$H,'Not Available'!$E:$E,D$7,'Not Available'!$G:$G,"Corn") -> 58928 | E8: =SUMIFS('Not Available'!$H:$H,'Not Available'!$E:$E,E$7,'Not Available'!$G:$G,"Corn") -> 978280 | F8: =SUMIFS('Not Available'!$H:$H,'Not Available'!$E:$E,F$7,'Not Available'!$G:$G,"Corn") -> 16256 | G8: =SUMIFS('Not Available'!$H:$H,'Not Available'!$E:$E,G$7,'Not Available'!$G:$G,"Corn") -> 1644690 | H8: =SUMIFS('Not Available'!$H:$H,'Not Available'!$E:$E,H$7,'Not Available'!$G:$G,"Corn") -> 3606283 | I8: =SUMIFS('Not Available'!$H:$H,'Not Available'!$E:$E,I$7,'Not Available'!$G:$G,"Corn") -> 4388664 | ... T8: =SUMIFS('Not Available'!$H:$H,'Not Available'!$E:$E,T$7,'Not Available'!$G:$G,"Corn") -> 0 | U8: =SUM(B8:T8) -> 38070189
A9: China | B9: =SUMIFS(China!$H:$H,China!$E:$E,B$7,China!$G:$G,"Corn") -> 0 | C9: =SUMIFS(China!$H:$H,China!$E:$E,C$7,China!$G:$G,"Corn") -> 0 | D9: =SUMIFS(China!$H:$H,China!$E:$E,D$7,China!$G:$G,"Corn") -> 0 | E9: =SUMIFS(China!$H:$H,China!$E:$E,E$7,China!$G:$G,"Corn") -> 1080000 | F9: =SUMIFS(China!$H:$H,China!$E:$E,F$7,China!$G:$G,"Corn") -> 0 | G9: =SUMIFS(China!$H:$H,China!$E:$E,G$7,China!$G:$G,"Corn") -> 0 | H9: =SUMIFS(China!$H:$H,China!$E:$E,H$7,China!$G:$G,"Corn") -> 0 | I9: =SUMIFS(China!$H:$H,China!$E:$E,I$7,China!$G:$G,"Corn") -> 0 | ... T9: =SUMIFS(China!$H:$H,China!$E:$E,T$7,China!$G:$G,"Corn") -> 0 | U9: =SUM(B9:T9) -> 44964000
A10: Mexico | B10: =SUMIFS(Mexico!$H:$H,Mexico!$E:$E,B$7,Mexico!$G:$G,"Corn") -> 0 | C10: =SUMIFS(Mexico!$H:$H,Mexico!$E:$E,C$7,Mexico!$G:$G,"Corn") -> 0 | D10: =SUMIFS(Mexico!$H:$H,Mexico!$E:$E,D$7,Mexico!$G:$G,"Corn") -> 11000 | E10: =SUMIFS(Mexico!$H:$H,Mexico!$E:$E,E$7,Mexico!$G:$G,"Corn") -> 677353 | F10: =SUMIFS(Mexico!$H:$H,Mexico!$E:$E,F$7,Mexico!$G:$G,"Corn") -> 243150 | G10: =SUMIFS(Mexico!$H:$H,Mexico!$E:$E,G$7,Mexico!$G:$G,"Corn") -> 460440 | H10: =SUMIFS(Mexico!$H:$H,Mexico!$E:$E,H$7,Mexico!$G:$G,"Corn") -> 2835048 | I10: =SUMIFS(Mexico!$H:$H,Mexico!$E:$E,I$7,Mexico!$G:$G,"Corn") -> 4573677 | ... T10: =SUMIFS(Mexico!$H:$H,Mexico!$E:$E,T$7,Mexico!$G:$G,"Corn") -> 22400 | U10: =SUM(B10:T10) -> 59200680
A11: Japan | B11: =SUMIFS(Japan!$H:$H,Japan!$E:$E,B$7,Japan!$G:$G,"Corn") -> 0 | C11: =SUMIFS(Japan!$H:$H,Japan!$E:$E,C$7,Japan!$G:$G,"Corn") -> 0 | D11: =SUMIFS(Japan!$H:$H,Japan!$E:$E,D$7,Japan!$G:$G,"Corn") -> 0 | E11: =SUMIFS(Japan!$H:$H,Japan!$E:$E,E$7,Japan!$G:$G,"Corn") -> 223040 | F11: =SUMIFS(Japan!$H:$H,Japan!$E:$E,F$7,Japan!$G:$G,"Corn") -> 458384 | G11: =SUMIFS(Japan!$H:$H,Japan!$E:$E,G$7,Japan!$G:$G,"Corn") -> 1146884 | H11: =SUMIFS(Japan!$H:$H,Japan!$E:$E,H$7,Japan!$G:$G,"Corn") -> 1139704 | I11: =SUMIFS(Japan!$H:$H,Japan!$E:$E,I$7,Japan!$G:$G,"Corn") -> 981456 | ... T11: =SUMIFS(Japan!$H:$H,Japan!$E:$E,T$7,Japan!$G:$G,"Corn") -> 0 | U11: =SUM(B11:T11) -> 7884108
A12: South Korea | B12: =SUMIFS('South Korea'!$H:$H,'South Korea'!$E:$E,B$7,'South Korea'!$G:$G,"Corn") -> 0 | C12: =SUMIFS('South Korea'!$H:$H,'South Korea'!$E:$E,C$7,'South Korea'!$G:$G,"Corn") -> 357000 | D12: =SUMIFS('South Korea'!$H:$H,'South Korea'!$E:$E,D$7,'South Korea'!$G:$G,"Corn") -> 0 | E12: =SUMIFS('South Korea'!$H:$H,'South Korea'!$E:$E,E$7,'South Korea'!$G:$G,"Corn") -> 444000 | F12: =SUMIFS('South Korea'!$H:$H,'South Korea'!$E:$E,F$7,'South Korea'!$G:$G,"Corn") -> 0 | G12: =SUMIFS('South Korea'!$H:$H,'South Korea'!$E:$E,G$7,'South Korea'!$G:$G,"Corn") -> 197000 | H12: =SUMIFS('South Korea'!$H:$H,'South Korea'!$E:$E,H$7,'South Korea'!$G:$G,"Corn") -> 1081000 | I12: =SUMIFS('South Korea'!$H:$H,'South Korea'!$E:$E,I$7,'South Korea'!$G:$G,"Corn") -> 613000 | ... T12: =SUMIFS('South Korea'!$H:$H,'South Korea'!$E:$E,T$7,'South Korea'!$G:$G,"Corn") -> 0 | U12: =SUM(B12:T12) -> 6671000
A13: Colombia | B13: =SUMIFS(Colombia!$H:$H,Colombia!$E:$E,B$7,Colombia!$G:$G,"Corn") -> 0 | C13: =SUMIFS(Colombia!$H:$H,Colombia!$E:$E,C$7,Colombia!$G:$G,"Corn") -> 0 | D13: =SUMIFS(Colombia!$H:$H,Colombia!$E:$E,D$7,Colombia!$G:$G,"Corn") -> 0 | E13: =SUMIFS(Colombia!$H:$H,Colombia!$E:$E,E$7,Colombia!$G:$G,"Corn") -> 0 | F13: =SUMIFS(Colombia!$H:$H,Colombia!$E:$E,F$7,Colombia!$G:$G,"Corn") -> 0 | G13: =SUMIFS(Colombia!$H:$H,Colombia!$E:$E,G$7,Colombia!$G:$G,"Corn") -> 525000 | H13: =SUMIFS(Colombia!$H:$H,Colombia!$E:$E,H$7,Colombia!$G:$G,"Corn") -> 105000 | I13: =SUMIFS(Colombia!$H:$H,Colombia!$E:$E,I$7,Colombia!$G:$G,"Corn") -> 250000 | ... T13: =SUMIFS(Colombia!$H:$H,Colombia!$E:$E,T$7,Colombia!$G:$G,"Corn") -> 0 | U13: =SUM(B13:T13) -> 3771800
A14: Egypt | B14: =SUMIFS(Egypt!$H:$H,Egypt!$E:$E,B$7,Egypt!$G:$G,"Corn") -> 120000 | C14: =SUMIFS(Egypt!$H:$H,Egypt!$E:$E,C$7,Egypt!$G:$G,"Corn") -> 240000 | D14: =SUMIFS(Egypt!$H:$H,Egypt!$E:$E,D$7,Egypt!$G:$G,"Corn") -> 0 | E14: =SUMIFS(Egypt!$H:$H,Egypt!$E:$E,E$7,Egypt!$G:$G,"Corn") -> 664000 | F14: =SUMIFS(Egypt!$H:$H,Egypt!$E:$E,F$7,Egypt!$G:$G,"Corn") -> 176000 | G14: =SUMIFS(Egypt!$H:$H,Egypt!$E:$E,G$7,Egypt!$G:$G,"Corn") -> 0 | H14: =SUMIFS(Egypt!$H:$H,Egypt!$E:$E,H$7,Egypt!$G:$G,"Corn") -> 0 | I14: =SUMIFS(Egypt!$H:$H,Egypt!$E:$E,I$7,Egypt!$G:$G,"Corn") -> 560000 | ... T14: =SUMIFS(Egypt!$H:$H,Egypt!$E:$E,T$7,Egypt!$G:$G,"Corn") -> 0 | U14: =SUM(B14:T14) -> 1813000
A15: Spain | B15: =SUMIFS(Spain!$H:$H,Spain!$E:$E,B$7,Spain!$G:$G,"Corn") -> 0 | C15: =SUMIFS(Spain!$H:$H,Spain!$E:$E,C$7,Spain!$G:$G,"Corn") -> 0 | D15: =SUMIFS(Spain!$H:$H,Spain!$E:$E,D$7,Spain!$G:$G,"Corn") -> 0 | E15: =SUMIFS(Spain!$H:$H,Spain!$E:$E,E$7,Spain!$G:$G,"Corn") -> 150000 | F15: =SUMIFS(Spain!$H:$H,Spain!$E:$E,F$7,Spain!$G:$G,"Corn") -> 0 | G15: =SUMIFS(Spain!$H:$H,Spain!$E:$E,G$7,Spain!$G:$G,"Corn") -> 0 | H15: =SUMIFS(Spain!$H:$H,Spain!$E:$E,H$7,Spain!$G:$G,"Corn") -> 0 | I15: =SUMIFS(Spain!$H:$H,Spain!$E:$E,I$7,Spain!$G:$G,"Corn") -> 384000 | ... T15: =SUMIFS(Spain!$H:$H,Spain!$E:$E,T$7,Spain!$G:$G,"Corn") -> 0 | U15: =SUM(B15:T15) -> 1386452
A16: Taiwan | B16: =SUMIFS(Taiwan!$H:$H,Taiwan!$E:$E,B$7,Taiwan!$G:$G,"Corn") -> 0 | C16: =SUMIFS(Taiwan!$H:$H,Taiwan!$E:$E,C$7,Taiwan!$G:$G,"Corn") -> 0 | D16: =SUMIFS(Taiwan!$H:$H,Taiwan!$E:$E,D$7,Taiwan!$G:$G,"Corn") -> 0 | E16: =SUMIFS(Taiwan!$H:$H,Taiwan!$E:$E,E$7,Taiwan!$G:$G,"Corn") -> 0 | F16: =SUMIFS(Taiwan!$H:$H,Taiwan!$E:$E,F$7,Taiwan!$G:$G,"Corn") -> 0 | G16: =SUMIFS(Taiwan!$H:$H,Taiwan!$E:$E,G$7,Taiwan!$G:$G,"Corn") -> 445000 | H16: =SUMIFS(Taiwan!$H:$H,Taiwan!$E:$E,H$7,Taiwan!$G:$G,"Corn") -> 195000 | I16: =SUMIFS(Taiwan!$H:$H,Taiwan!$E:$E,I$7,Taiwan!$G:$G,"Corn") -> 0 | ... T16: =SUMIFS(Taiwan!$H:$H,Taiwan!$E:$E,T$7,Taiwan!$G:$G,"Corn") -> 0 | U16: =SUM(B16:T16) -> 885000
A17: Costa Rica | B17: =SUMIFS('Costa Rica'!$H:$H,'Costa Rica'!$E:$E,B$7,'Costa Rica'!$G:$G,"Corn") -> 0 | C17: =SUMIFS('Costa Rica'!$H:$H,'Costa Rica'!$E:$E,C$7,'Costa Rica'!$G:$G,"Corn") -> 0 | D17: =SUMIFS('Costa Rica'!$H:$H,'Costa Rica'!$E:$E,D$7,'Costa Rica'!$G:$G,"Corn") -> 0 | E17: =SUMIFS('Costa Rica'!$H:$H,'Costa Rica'!$E:$E,E$7,'Costa Rica'!$G:$G,"Corn") -> 0 | F17: =SUMIFS('Costa Rica'!$H:$H,'Costa Rica'!$E:$E,F$7,'Costa Rica'!$G:$G,"Corn") -> 0 | G17: =SUMIFS('Costa Rica'!$H:$H,'Costa Rica'!$E:$E,G$7,'Costa Rica'!$G:$G,"Corn") -> 106162 | H17: =SUMIFS('Costa Rica'!$H:$H,'Costa Rica'!$E:$E,H$7,'Costa Rica'!$G:$G,"Corn") -> 0 | I17: =SUMIFS('Costa Rica'!$H:$H,'Costa Rica'!$E:$E,I$7,'Costa Rica'!$G:$G,"Corn") -> 134503 | ... T17: =SUMIFS('Costa Rica'!$H:$H,'Costa Rica'!$E:$E,T$7,'Costa Rica'!$G:$G,"Corn") -> 0 | U17: =SUM(B17:T17) -> 843555
A18: Guatemala | B18: =SUMIFS(Guatemala!$H:$H,Guatemala!$E:$E,B$7,Guatemala!$G:$G,"Corn") -> 0 | C18: =SUMIFS(Guatemala!$H:$H,Guatemala!$E:$E,C$7,Guatemala!$G:$G,"Corn") -> 0 | D18: =SUMIFS(Guatemala!$H:$H,Guatemala!$E:$E,D$7,Guatemala!$G:$G,"Corn") -> 0 | E18: =SUMIFS(Guatemala!$H:$H,Guatemala!$E:$E,E$7,Guatemala!$G:$G,"Corn") -> 0 | F18: =SUMIFS(Guatemala!$H:$H,Guatemala!$E:$E,F$7,Guatemala!$G:$G,"Corn") -> 0 | G18: =SUMIFS(Guatemala!$H:$H,Guatemala!$E:$E,G$7,Guatemala!$G:$G,"Corn") -> 0 | H18: =SUMIFS(Guatemala!$H:$H,Guatemala!$E:$E,H$7,Guatemala!$G:$G,"Corn") -> 0 | I18: =SUMIFS(Guatemala!$H:$H,Guatemala!$E:$E,I$7,Guatemala!$G:$G,"Corn") -> 0 | ... T18: =SUMIFS(Guatemala!$H:$H,Guatemala!$E:$E,T$7,Guatemala!$G:$G,"Corn") -> 0 | U18: =SUM(B18:T18) -> 764153
A19: Saudi Arabia | B19: =SUMIFS('Saudi Arabia'!$H:$H,'Saudi Arabia'!$E:$E,B$7,'Saudi Arabia'!$G:$G,"Corn") -> 0 | C19: =SUMIFS('Saudi Arabia'!$H:$H,'Saudi Arabia'!$E:$E,C$7,'Saudi Arabia'!$G:$G,"Corn") -> 0 | D19: =SUMIFS('Saudi Arabia'!$H:$H,'Saudi Arabia'!$E:$E,D$7,'Saudi Arabia'!$G:$G,"Corn") -> 0 | E19: =SUMIFS('Saudi Arabia'!$H:$H,'Saudi Arabia'!$E:$E,E$7,'Saudi Arabia'!$G:$G,"Corn") -> 0 | F19: =SUMIFS('Saudi Arabia'!$H:$H,'Saudi Arabia'!$E:$E,F$7,'Saudi Arabia'!$G:$G,"Corn") -> 140000 | G19: =SUMIFS('Saudi Arabia'!$H:$H,'Saudi Arabia'!$E:$E,G$7,'Saudi Arabia'!$G:$G,"Corn") -> 210000 | H19: =SUMIFS('Saudi Arabia'!$H:$H,'Saudi Arabia'!$E:$E,H$7,'Saudi Arabia'!$G:$G,"Corn") -> 140000 | I19: =SUMIFS('Saudi Arabia'!$H:$H,'Saudi Arabia'!$E:$E,I$7,'Saudi Arabia'!$G:$G,"Corn") -> 70000 | ... T19: =SUMIFS('Saudi Arabia'!$H:$H,'Saudi Arabia'!$E:$E,T$7,'Saudi Arabia'!$G:$G,"Corn") -> 0 | U19: =SUM(B19:T19) -> 630000
A20: Argentina | B20: =SUMIFS(Argentina!$H:$H,Argentina!$E:$E,B$7,Argentina!$G:$G,"Corn") -> 0 | C20: =SUMIFS(Argentina!$H:$H,Argentina!$E:$E,C$7,Argentina!$G:$G,"Corn") -> 0 | D20: =SUMIFS(Argentina!$H:$H,Argentina!$E:$E,D$7,Argentina!$G:$G,"Corn") -> 0 | E20: =SUMIFS(Argentina!$H:$H,Argentina!$E:$E,E$7,Argentina!$G:$G,"Corn") -> 0 | F20: =SUMIFS(Argentina!$H:$H,Argentina!$E:$E,F$7,Argentina!$G:$G,"Corn") -> 0 | G20: =SUMIFS(Argentina!$H:$H,Argentina!$E:$E,G$7,Argentina!$G:$G,"Corn") -> 0 | H20: =SUMIFS(Argentina!$H:$H,Argentina!$E:$E,H$7,Argentina!$G:$G,"Corn") -> 0 | I20: =SUMIFS(Argentina!$H:$H,Argentina!$E:$E,I$7,Argentina!$G:$G,"Corn") -> 80000 | ... T20: =SUMIFS(Argentina!$H:$H,Argentina!$E:$E,T$7,Argentina!$G:$G,"Corn") -> 0 | U20: =SUM(B20:T20) -> 80000
A21: Pakistan | B21: =SUMIFS(Pakistan!$H:$H,Pakistan!$E:$E,B$7,Pakistan!$G:$G,"Corn") -> 0 | C21: =SUMIFS(Pakistan!$H:$H,Pakistan!$E:$E,C$7,Pakistan!$G:$G,"Corn") -> 0 | D21: =SUMIFS(Pakistan!$H:$H,Pakistan!$E:$E,D$7,Pakistan!$G:$G,"Corn") -> 0 | E21: =SUMIFS(Pakistan!$H:$H,Pakistan!$E:$E,E$7,Pakistan!$G:$G,"Corn") -> 0 | F21: =SUMIFS(Pakistan!$H:$H,Pakistan!$E:$E,F$7,Pakistan!$G:$G,"Corn") -> 0 | G21: =SUMIFS(Pakistan!$H:$H,Pakistan!$E:$E,G$7,Pakistan!$G:$G,"Corn") -> 0 | H21: =SUMIFS(Pakistan!$H:$H,Pakistan!$E:$E,H$7,Pakistan!$G:$G,"Corn") -> 0 | I21: =SUMIFS(Pakistan!$H:$H,Pakistan!$E:$E,I$7,Pakistan!$G:$G,"Corn") -> 0 | ... T21: =SUMIFS(Pakistan!$H:$H,Pakistan!$E:$E,T$7,Pakistan!$G:$G,"Corn") -> 0 | U21: =SUM(B21:T21) -> 0
A22: Other | B22: =SUMIFS(Other!$H:$H,Other!$E:$E,B$7,Other!$G:$G,"Corn") -> 0 | C22: =SUMIFS(Other!$H:$H,Other!$E:$E,C$7,Other!$G:$G,"Corn") -> 0 | D22: =SUMIFS(Other!$H:$H,Other!$E:$E,D$7,Other!$G:$G,"Corn") -> 0 | E22: =SUMIFS(Other!$H:$H,Other!$E:$E,E$7,Other!$G:$G,"Corn") -> 0 | F22: =SUMIFS(Other!$H:$H,Other!$E:$E,F$7,Other!$G:$G,"Corn") -> 0 | G22: =SUMIFS(Other!$H:$H,Other!$E:$E,G$7,Other!$G:$G,"Corn") -> 132000 | H22: =SUMIFS(Other!$H:$H,Other!$E:$E,H$7,Other!$G:$G,"Corn") -> 100973 | I22: =SUMIFS(Other!$H:$H,Other!$E:$E,I$7,Other!$G:$G,"Corn") -> 110000 | ... T22: =SUMIFS(Other!$H:$H,Other!$E:$E,T$7,Other!$G:$G,"Corn") -> 0 | U22: =SUM(B22:T22) -> 1009073
A23: Total | B23: =SUM(B8:B22) -> 250000 | C23: =SUM(C8:C22) -> 697000 | D23: =SUM(D8:D22) -> 69928 | E23: =SUM(E8:E22) -> 4216673 | F23: =SUM(F8:F22) -> 1033790 | G23: =SUM(G8:G22) -> 4867176 | H23: =SUM(H8:H22) -> 9203008 | I23: =SUM(I8:I22) -> 12145300 | ... U23: =SUM(U8:U22) -> 167973010
A26: Soybean
A27: Destination | B27: 2010/2011 | C27: 2011/2012 | D27: 2012/2013 | E27: 2013/2014 | F27: 2014/2015 | G27: 2015/2016 | H27: 2016/2017 | I27: 2017/2018 | J27: 2018/2019 | K27: 2019/2020 | L27: 2020/2021 | M27: 2021/2022 | N27: 2022/2023 | O27: 2023/2024 | P27: 2024/2025 | Q27: 2025/2026 | R27: 2026/2027 | S27: 2027/2028 | T27: 2028/2029 | U27: Total
A28: Not Available | B28: =SUMIFS('Not Available'!$H:$H,'Not Available'!$E:$E,B$27,'Not Available'!$G:$G,"Soybean") -> 0 | C28: =SUMIFS('Not Available'!$H:$H,'Not Available'!$E:$E,C$27,'Not Available'!$G:$G,"Soybean") -> 0 | D28: =SUMIFS('Not Available'!$H:$H,'Not Available'!$E:$E,D$27,'Not Available'!$G:$G,"Soybean") -> 75450 | E28: =SUMIFS('Not Available'!$H:$H,'Not Available'!$E:$E,E$27,'Not Available'!$G:$G,"Soybean") -> 3383650 | F28: =SUMIFS('Not Available'!$H:$H,'Not Available'!$E:$E,F$27,'Not Available'!$G:$G,"Soybean") -> 435000 | G28: =SUMIFS('Not Available'!$H:$H,'Not Available'!$E:$E,G$27,'Not Available'!$G:$G,"Soybean") -> 2756500 | H28: =SUMIFS('Not Available'!$H:$H,'Not Available'!$E:$E,H$27,'Not Available'!$G:$G,"Soybean") -> 10305291 | I28: =SUMIFS('Not Available'!$H:$H,'Not Available'!$E:$E,I$27,'Not Available'!$G:$G,"Soybean") -> 8560600 | ... T28: =SUMIFS('Not Available'!$H:$H,'Not Available'!$E:$E,T$27,'Not Available'!$G:$G,"Soybean") -> 0 | U28: =SUM(B28:T28) -> 88620406
A29: China | B29: =SUMIFS(China!$H:$H,China!$E:$E,B$27,China!$G:$G,"Soybean") -> 132000 | C29: =SUMIFS(China!$H:$H,China!$E:$E,C$27,China!$G:$G,"Soybean") -> 773000 | D29: =SUMIFS(China!$H:$H,China!$E:$E,D$27,China!$G:$G,"Soybean") -> 2750000 | E29: =SUMIFS(China!$H:$H,China!$E:$E,E$27,China!$G:$G,"Soybean") -> 5005000 | F29: =SUMIFS(China!$H:$H,China!$E:$E,F$27,China!$G:$G,"Soybean") -> 477000 | G29: =SUMIFS(China!$H:$H,China!$E:$E,G$27,China!$G:$G,"Soybean") -> 1219000 | H29: =SUMIFS(China!$H:$H,China!$E:$E,H$27,China!$G:$G,"Soybean") -> 11002570 | I29: =SUMIFS(China!$H:$H,China!$E:$E,I$27,China!$G:$G,"Soybean") -> 9965000 | ... T29: =SUMIFS(China!$H:$H,China!$E:$E,T$27,China!$G:$G,"Soybean") -> 0 | U29: =SUM(B29:T29) -> 102951270
A30: Mexico | B30: =SUMIFS(Mexico!$H:$H,Mexico!$E:$E,B$27,Mexico!$G:$G,"Soybean") -> 0 | C30: =SUMIFS(Mexico!$H:$H,Mexico!$E:$E,C$27,Mexico!$G:$G,"Soybean") -> 0 | D30: =SUMIFS(Mexico!$H:$H,Mexico!$E:$E,D$27,Mexico!$G:$G,"Soybean") -> 0 | E30: =SUMIFS(Mexico!$H:$H,Mexico!$E:$E,E$27,Mexico!$G:$G,"Soybean") -> 0 | F30: =SUMIFS(Mexico!$H:$H,Mexico!$E:$E,F$27,Mexico!$G:$G,"Soybean") -> 0 | G30: =SUMIFS(Mexico!$H:$H,Mexico!$E:$E,G$27,Mexico!$G:$G,"Soybean") -> 47500 | H30: =SUMIFS(Mexico!$H:$H,Mexico!$E:$E,H$27,Mexico!$G:$G,"Soybean") -> 517000 | I30: =SUMIFS(Mexico!$H:$H,Mexico!$E:$E,I$27,Mexico!$G:$G,"Soybean") -> 601546 | ... T30: =SUMIFS(Mexico!$H:$H,Mexico!$E:$E,T$27,Mexico!$G:$G,"Soybean") -> 0 | U30: =SUM(B30:T30) -> 11851974
A31: Japan | B31: =SUMIFS(Japan!$H:$H,Japan!$E:$E,B$27,Japan!$G:$G,"Soybean") -> 0 | C31: =SUMIFS(Japan!$H:$H,Japan!$E:$E,C$27,Japan!$G:$G,"Soybean") -> 0 | D31: =SUMIFS(Japan!$H:$H,Japan!$E:$E,D$27,Japan!$G:$G,"Soybean") -> 0 | E31: =SUMIFS(Japan!$H:$H,Japan!$E:$E,E$27,Japan!$G:$G,"Soybean") -> 0 | F31: =SUMIFS(Japan!$H:$H,Japan!$E:$E,F$27,Japan!$G:$G,"Soybean") -> 0 | G31: =SUMIFS(Japan!$H:$H,Japan!$E:$E,G$27,Japan!$G:$G,"Soybean") -> 0 | H31: =SUMIFS(Japan!$H:$H,Japan!$E:$E,H$27,Japan!$G:$G,"Soybean") -> 0 | I31: =SUMIFS(Japan!$H:$H,Japan!$E:$E,I$27,Japan!$G:$G,"Soybean") -> 0 | ... T31: =SUMIFS(Japan!$H:$H,Japan!$E:$E,T$27,Japan!$G:$G,"Soybean") -> 0 | U31: =SUM(B31:T31) -> 0
A32: South Korea | B32: =SUMIFS('South Korea'!$H:$H,'South Korea'!$E:$E,B$27,'South Korea'!$G:$G,"Soybean") -> 0 | C32: =SUMIFS('South Korea'!$H:$H,'South Korea'!$E:$E,C$27,'South Korea'!$G:$G,"Soybean") -> 0 | D32: =SUMIFS('South Korea'!$H:$H,'South Korea'!$E:$E,D$27,'South Korea'!$G:$G,"Soybean") -> 0 | E32: =SUMIFS('South Korea'!$H:$H,'South Korea'!$E:$E,E$27,'South Korea'!$G:$G,"Soybean") -> 0 | F32: =SUMIFS('South Korea'!$H:$H,'South Korea'!$E:$E,F$27,'South Korea'!$G:$G,"Soybean") -> 0 | G32: =SUMIFS('South Korea'!$H:$H,'South Korea'!$E:$E,G$27,'South Korea'!$G:$G,"Soybean") -> 0 | H32: =SUMIFS('South Korea'!$H:$H,'South Korea'!$E:$E,H$27,'South Korea'!$G:$G,"Soybean") -> 0 | I32: =SUMIFS('South Korea'!$H:$H,'South Korea'!$E:$E,I$27,'South Korea'!$G:$G,"Soybean") -> 0 | ... T32: =SUMIFS('South Korea'!$H:$H,'South Korea'!$E:$E,T$27,'South Korea'!$G:$G,"Soybean") -> 0 | U32: =SUM(B32:T32) -> 0
A33: Colombia | B33: =SUMIFS(Colombia!$H:$H,Colombia!$E:$E,B$27,Colombia!$G:$G,"Soybean") -> 0 | C33: =SUMIFS(Colombia!$H:$H,Colombia!$E:$E,C$27,Colombia!$G:$G,"Soybean") -> 0 | D33: =SUMIFS(Colombia!$H:$H,Colombia!$E:$E,D$27,Colombia!$G:$G,"Soybean") -> 0 | E33: =SUMIFS(Colombia!$H:$H,Colombia!$E:$E,E$27,Colombia!$G:$G,"Soybean") -> 0 | F33: =SUMIFS(Colombia!$H:$H,Colombia!$E:$E,F$27,Colombia!$G:$G,"Soybean") -> 0 | G33: =SUMIFS(Colombia!$H:$H,Colombia!$E:$E,G$27,Colombia!$G:$G,"Soybean") -> 0 | H33: =SUMIFS(Colombia!$H:$H,Colombia!$E:$E,H$27,Colombia!$G:$G,"Soybean") -> 0 | I33: =SUMIFS(Colombia!$H:$H,Colombia!$E:$E,I$27,Colombia!$G:$G,"Soybean") -> 0 | ... T33: =SUMIFS(Colombia!$H:$H,Colombia!$E:$E,T$27,Colombia!$G:$G,"Soybean") -> 0 | U33: =SUM(B33:T33) -> 188000
A34: Egypt | B34: =SUMIFS(Egypt!$H:$H,Egypt!$E:$E,B$27,Egypt!$G:$G,"Soybean") -> 0 | C34: =SUMIFS(Egypt!$H:$H,Egypt!$E:$E,C$27,Egypt!$G:$G,"Soybean") -> 0 | D34: =SUMIFS(Egypt!$H:$H,Egypt!$E:$E,D$27,Egypt!$G:$G,"Soybean") -> 0 | E34: =SUMIFS(Egypt!$H:$H,Egypt!$E:$E,E$27,Egypt!$G:$G,"Soybean") -> 114000 | F34: =SUMIFS(Egypt!$H:$H,Egypt!$E:$E,F$27,Egypt!$G:$G,"Soybean") -> 120000 | G34: =SUMIFS(Egypt!$H:$H,Egypt!$E:$E,G$27,Egypt!$G:$G,"Soybean") -> 0 | H34: =SUMIFS(Egypt!$H:$H,Egypt!$E:$E,H$27,Egypt!$G:$G,"Soybean") -> 0 | I34: =SUMIFS(Egypt!$H:$H,Egypt!$E:$E,I$27,Egypt!$G:$G,"Soybean") -> 120000 | ... T34: =SUMIFS(Egypt!$H:$H,Egypt!$E:$E,T$27,Egypt!$G:$G,"Soybean") -> 0 | U34: =SUM(B34:T34) -> 1502000
A35: Spain | B35: =SUMIFS(Spain!$H:$H,Spain!$E:$E,B$27,Spain!$G:$G,"Soybean") -> 0 | C35: =SUMIFS(Spain!$H:$H,Spain!$E:$E,C$27,Spain!$G:$G,"Soybean") -> 0 | D35: =SUMIFS(Spain!$H:$H,Spain!$E:$E,D$27,Spain!$G:$G,"Soybean") -> 0 | E35: =SUMIFS(Spain!$H:$H,Spain!$E:$E,E$27,Spain!$G:$G,"Soybean") -> 0 | F35: =SUMIFS(Spain!$H:$H,Spain!$E:$E,F$27,Spain!$G:$G,"Soybean") -> 0 | G35: =SUMIFS(Spain!$H:$H,Spain!$E:$E,G$27,Spain!$G:$G,"Soybean") -> 0 | H35: =SUMIFS(Spain!$H:$H,Spain!$E:$E,H$27,Spain!$G:$G,"Soybean") -> 0 | I35: =SUMIFS(Spain!$H:$H,Spain!$E:$E,I$27,Spain!$G:$G,"Soybean") -> 0 | ... T35: =SUMIFS(Spain!$H:$H,Spain!$E:$E,T$27,Spain!$G:$G,"Soybean") -> 0 | U35: =SUM(B35:T35) -> 550000
A36: Taiwan | B36: =SUMIFS(Taiwan!$H:$H,Taiwan!$E:$E,B$27,Taiwan!$G:$G,"Soybean") -> 0 | C36: =SUMIFS(Taiwan!$H:$H,Taiwan!$E:$E,C$27,Taiwan!$G:$G,"Soybean") -> 0 | D36: =SUMIFS(Taiwan!$H:$H,Taiwan!$E:$E,D$27,Taiwan!$G:$G,"Soybean") -> 0 | E36: =SUMIFS(Taiwan!$H:$H,Taiwan!$E:$E,E$27,Taiwan!$G:$G,"Soybean") -> 120000 | F36: =SUMIFS(Taiwan!$H:$H,Taiwan!$E:$E,F$27,Taiwan!$G:$G,"Soybean") -> 0 | G36: =SUMIFS(Taiwan!$H:$H,Taiwan!$E:$E,G$27,Taiwan!$G:$G,"Soybean") -> 0 | H36: =SUMIFS(Taiwan!$H:$H,Taiwan!$E:$E,H$27,Taiwan!$G:$G,"Soybean") -> 118000 | I36: =SUMIFS(Taiwan!$H:$H,Taiwan!$E:$E,I$27,Taiwan!$G:$G,"Soybean") -> 0 | ... T36: =SUMIFS(Taiwan!$H:$H,Taiwan!$E:$E,T$27,Taiwan!$G:$G,"Soybean") -> 0 | U36: =SUM(B36:T36) -> 342000
A37: Costa Rica | B37: =SUMIFS('Costa Rica'!$H:$H,'Costa Rica'!$E:$E,B$27,'Costa Rica'!$G:$G,"Soybean") -> 0 | C37: =SUMIFS('Costa Rica'!$H:$H,'Costa Rica'!$E:$E,C$27,'Costa Rica'!$G:$G,"Soybean") -> 0 | D37: =SUMIFS('Costa Rica'!$H:$H,'Costa Rica'!$E:$E,D$27,'Costa Rica'!$G:$G,"Soybean") -> 0 | E37: =SUMIFS('Costa Rica'!$H:$H,'Costa Rica'!$E:$E,E$27,'Costa Rica'!$G:$G,"Soybean") -> 0 | F37: =SUMIFS('Costa Rica'!$H:$H,'Costa Rica'!$E:$E,F$27,'Costa Rica'!$G:$G,"Soybean") -> 0 | G37: =SUMIFS('Costa Rica'!$H:$H,'Costa Rica'!$E:$E,G$27,'Costa Rica'!$G:$G,"Soybean") -> 0 | H37: =SUMIFS('Costa Rica'!$H:$H,'Costa Rica'!$E:$E,H$27,'Costa Rica'!$G:$G,"Soybean") -> 0 | I37: =SUMIFS('Costa Rica'!$H:$H,'Costa Rica'!$E:$E,I$27,'Costa Rica'!$G:$G,"Soybean") -> 0 | ... T37: =SUMIFS('Costa Rica'!$H:$H,'Costa Rica'!$E:$E,T$27,'Costa Rica'!$G:$G,"Soybean") -> 0 | U37: =SUM(B37:T37) -> 0
A38: Guatemala | B38: =SUMIFS(Guatemala!$H:$H,Guatemala!$E:$E,B$27,Guatemala!$G:$G,"Soybean") -> 0 | C38: =SUMIFS(Guatemala!$H:$H,Guatemala!$E:$E,C$27,Guatemala!$G:$G,"Soybean") -> 0 | D38: =SUMIFS(Guatemala!$H:$H,Guatemala!$E:$E,D$27,Guatemala!$G:$G,"Soybean") -> 0 | E38: =SUMIFS(Guatemala!$H:$H,Guatemala!$E:$E,E$27,Guatemala!$G:$G,"Soybean") -> 0 | F38: =SUMIFS(Guatemala!$H:$H,Guatemala!$E:$E,F$27,Guatemala!$G:$G,"Soybean") -> 0 | G38: =SUMIFS(Guatemala!$H:$H,Guatemala!$E:$E,G$27,Guatemala!$G:$G,"Soybean") -> 0 | H38: =SUMIFS(Guatemala!$H:$H,Guatemala!$E:$E,H$27,Guatemala!$G:$G,"Soybean") -> 0 | I38: =SUMIFS(Guatemala!$H:$H,Guatemala!$E:$E,I$27,Guatemala!$G:$G,"Soybean") -> 0 | ... T38: =SUMIFS(Guatemala!$H:$H,Guatemala!$E:$E,T$27,Guatemala!$G:$G,"Soybean") -> 0 | U38: =SUM(B38:T38) -> 0
A39: Saudi Arabia | B39: =SUMIFS('Saudi Arabia'!$H:$H,'Saudi Arabia'!$E:$E,B$27,'Saudi Arabia'!$G:$G,"Soybean") -> 0 | C39: =SUMIFS('Saudi Arabia'!$H:$H,'Saudi Arabia'!$E:$E,C$27,'Saudi Arabia'!$G:$G,"Soybean") -> 0 | D39: =SUMIFS('Saudi Arabia'!$H:$H,'Saudi Arabia'!$E:$E,D$27,'Saudi Arabia'!$G:$G,"Soybean") -> 0 | E39: =SUMIFS('Saudi Arabia'!$H:$H,'Saudi Arabia'!$E:$E,E$27,'Saudi Arabia'!$G:$G,"Soybean") -> 0 | F39: =SUMIFS('Saudi Arabia'!$H:$H,'Saudi Arabia'!$E:$E,F$27,'Saudi Arabia'!$G:$G,"Soybean") -> 0 | G39: =SUMIFS('Saudi Arabia'!$H:$H,'Saudi Arabia'!$E:$E,G$27,'Saudi Arabia'!$G:$G,"Soybean") -> 0 | H39: =SUMIFS('Saudi Arabia'!$H:$H,'Saudi Arabia'!$E:$E,H$27,'Saudi Arabia'!$G:$G,"Soybean") -> 0 | I39: =SUMIFS('Saudi Arabia'!$H:$H,'Saudi Arabia'!$E:$E,I$27,'Saudi Arabia'!$G:$G,"Soybean") -> 0 | ... T39: =SUMIFS('Saudi Arabia'!$H:$H,'Saudi Arabia'!$E:$E,T$27,'Saudi Arabia'!$G:$G,"Soybean") -> 0 | U39: =SUM(B39:T39) -> 66000
A40: Argentina | B40: =SUMIFS(Argentina!$H:$H,Argentina!$E:$E,B$27,Argentina!$G:$G,"Soybean") -> 0 | C40: =SUMIFS(Argentina!$H:$H,Argentina!$E:$E,C$27,Argentina!$G:$G,"Soybean") -> 0 | D40: =SUMIFS(Argentina!$H:$H,Argentina!$E:$E,D$27,Argentina!$G:$G,"Soybean") -> 0 | E40: =SUMIFS(Argentina!$H:$H,Argentina!$E:$E,E$27,Argentina!$G:$G,"Soybean") -> 0 | F40: =SUMIFS(Argentina!$H:$H,Argentina!$E:$E,F$27,Argentina!$G:$G,"Soybean") -> 0 | G40: =SUMIFS(Argentina!$H:$H,Argentina!$E:$E,G$27,Argentina!$G:$G,"Soybean") -> 0 | H40: =SUMIFS(Argentina!$H:$H,Argentina!$E:$E,H$27,Argentina!$G:$G,"Soybean") -> 0 | I40: =SUMIFS(Argentina!$H:$H,Argentina!$E:$E,I$27,Argentina!$G:$G,"Soybean") -> 60000 | ... T40: =SUMIFS(Argentina!$H:$H,Argentina!$E:$E,T$27,Argentina!$G:$G,"Soybean") -> 0 | U40: =SUM(B40:T40) -> 490000
A41: Pakistan | B41: =SUMIFS(Pakistan!$H:$H,Pakistan!$E:$E,B$27,Pakistan!$G:$G,"Soybean") -> 0 | C41: =SUMIFS(Pakistan!$H:$H,Pakistan!$E:$E,C$27,Pakistan!$G:$G,"Soybean") -> 0 | D41: =SUMIFS(Pakistan!$H:$H,Pakistan!$E:$E,D$27,Pakistan!$G:$G,"Soybean") -> 0 | E41: =SUMIFS(Pakistan!$H:$H,Pakistan!$E:$E,E$27,Pakistan!$G:$G,"Soybean") -> 0 | F41: =SUMIFS(Pakistan!$H:$H,Pakistan!$E:$E,F$27,Pakistan!$G:$G,"Soybean") -> 0 | G41: =SUMIFS(Pakistan!$H:$H,Pakistan!$E:$E,G$27,Pakistan!$G:$G,"Soybean") -> 0 | H41: =SUMIFS(Pakistan!$H:$H,Pakistan!$E:$E,H$27,Pakistan!$G:$G,"Soybean") -> 0 | I41: =SUMIFS(Pakistan!$H:$H,Pakistan!$E:$E,I$27,Pakistan!$G:$G,"Soybean") -> 0 | ... T41: =SUMIFS(Pakistan!$H:$H,Pakistan!$E:$E,T$27,Pakistan!$G:$G,"Soybean") -> 0 | U41: =SUM(B41:T41) -> 1028500
A42: Other | B42: =SUMIFS(Other!$H:$H,Other!$E:$E,B$27,Other!$G:$G,"Soybean") -> 0 | C42: =SUMIFS(Other!$H:$H,Other!$E:$E,C$27,Other!$G:$G,"Soybean") -> 0 | D42: =SUMIFS(Other!$H:$H,Other!$E:$E,D$27,Other!$G:$G,"Soybean") -> 0 | E42: =SUMIFS(Other!$H:$H,Other!$E:$E,E$27,Other!$G:$G,"Soybean") -> 120000 | F42: =SUMIFS(Other!$H:$H,Other!$E:$E,F$27,Other!$G:$G,"Soybean") -> 0 | G42: =SUMIFS(Other!$H:$H,Other!$E:$E,G$27,Other!$G:$G,"Soybean") -> 217000 | H42: =SUMIFS(Other!$H:$H,Other!$E:$E,H$27,Other!$G:$G,"Soybean") -> 110000 | I42: =SUMIFS(Other!$H:$H,Other!$E:$E,I$27,Other!$G:$G,"Soybean") -> 0 | ... T42: =SUMIFS(Other!$H:$H,Other!$E:$E,T$27,Other!$G:$G,"Soybean") -> 0 | U42: =SUM(B42:T42) -> 711500
A43: Total | B43: =SUM(B28:B42) -> 132000 | C43: =SUM(C28:C42) -> 773000 | D43: =SUM(D28:D42) -> 2825450 | E43: =SUM(E28:E42) -> 8742650 | F43: =SUM(F28:F42) -> 1032000 | G43: =SUM(G28:G42) -> 4240000 | H43: =SUM(H28:H42) -> 22052861 | I43: =SUM(I28:I42) -> 19307146 | ... U43: =SUM(U28:U42) -> 208301650
A46: Corn + Soybean
...

Sheet Not Available
A1: Not Available — USDA daily flash sales (metric tonnes)
A2: Detail sorted by sale date. Summaries on the right are formulas over the detail.
J3: By delivery marketing year (USDA "Marketing Year": season the grain ships in)
A4: Sale Date | B4: Reported in | C4: Week Ending Date | D4: Destination | E4: Delivery MY (USDA) | F4: Sale Season (Sep-Aug) | G4: Product | H4: Quantity | J4: Delivery MY | K4: Corn | L4: Soybean | M4: Total | N4: # Sales
A5: 40721 | B5: 40738 | C5: 40731 | D5: Not Available | E5: 2010/2011 | F5: 2010/2011 | G5: Corn | H5: 130000 | J5: 2010/2011 | K5: =SUMIFS($H$5:$H$757,$E$5:$E$757,J5,$G$5:$G$757,"Corn") -> 130000 | L5: =SUMIFS($H$5:$H$757,$E$5:$E$757,J5,$G$5:$G$757,"Soybean") -> 0 | M5: =K5+L5 -> 130000 | N5: =COUNTIFS($E$5:$E$757,J5) -> 1
A6: 40721 | B6: 40738 | C6: 40731 | D6: Not Available | E6: 2011/2012 | F6: 2010/2011 | G6: Corn | H6: 100000 | J6: 2011/2012 | K6: =SUMIFS($H$5:$H$757,$E$5:$E$757,J6,$G$5:$G$757,"Corn") -> 100000 | L6: =SUMIFS($H$5:$H$757,$E$5:$E$757,J6,$G$5:$G$757,"Soybean") -> 0 | M6: =K6+L6 -> 100000 | N6: =COUNTIFS($E$5:$E$757,J6) -> 1
A7: 41291 | B7: 41305 | C7: 41298 | D7: Not Available | E7: 2013/2014 | F7: 2012/2013 | G7: Soybean | H7: 240000 | J7: 2012/2013 | K7: =SUMIFS($H$5:$H$757,$E$5:$E$757,J7,$G$5:$G$757,"Corn") -> 58928 | L7: =SUMIFS($H$5:$H$757,$E$5:$E$757,J7,$G$5:$G$757,"Soybean") -> 75450 | M7: =K7+L7 -> 134378 | N7: =COUNTIFS($E$5:$E$757,J7) -> 3
A8: 41326 | B8: 41340 | C8: 41333 | D8: Not Available | E8: 2012/2013 | F8: 2012/2013 | G8: Soybean | H8: 75450 | J8: 2013/2014 | K8: =SUMIFS($H$5:$H$757,$E$5:$E$757,J8,$G$5:$G$757,"Corn") -> 978280 | L8: =SUMIFS($H$5:$H$757,$E$5:$E$757,J8,$G$5:$G$757,"Soybean") -> 3383650 | M8: =K8+L8 -> 4361930 | N8: =COUNTIFS($E$5:$E$757,J8) -> 26
A9: 41326 | B9: 41340 | C9: 41333 | D9: Not Available | E9: 2013/2014 | F9: 2012/2013 | G9: Soybean | H9: 55000 | J9: 2014/2015 | K9: =SUMIFS($H$5:$H$757,$E$5:$E$757,J9,$G$5:$G$757,"Corn") -> 16256 | L9: =SUMIFS($H$5:$H$757,$E$5:$E$757,J9,$G$5:$G$757,"Soybean") -> 435000 | M9: =K9+L9 -> 451256 | N9: =COUNTIFS($E$5:$E$757,J9) -> 4
A10: 41330 | B10: 41347 | C10: 41340 | D10: Not Available | E10: 2012/2013 | F10: 2012/2013 | G10: Corn | H10: 50800 | J10: 2015/2016 | K10: =SUMIFS($H$5:$H$757,$E$5:$E$757,J10,$G$5:$G$757,"Corn") -> 1644690 | L10: =SUMIFS($H$5:$H$757,$E$5:$E$757,J10,$G$5:$G$757,"Soybean") -> 2756500 | M10: =K10+L10 -> 4401190 | N10: =COUNTIFS($E$5:$E$757,J10) -> 29
A11: 41330 | B11: 41347 | C11: 41340 | D11: Not Available | E11: 2013/2014 | F11: 2012/2013 | G11: Corn | H11: 76200 | J11: 2016/2017 | K11: =SUMIFS($H$5:$H$757,$E$5:$E$757,J11,$G$5:$G$757,"Corn") -> 3606283 | L11: =SUMIFS($H$5:$H$757,$E$5:$E$757,J11,$G$5:$G$757,"Soybean") -> 10305291 | M11: =K11+L11 -> 13911574 | N11: =COUNTIFS($E$5:$E$757,J11) -> 93
A12: 41452 | B12: 41466 | C12: 41459 | D12: Not Available | E12: 2013/2014 | F12: 2012/2013 | G12: Soybean | H12: 172500 | J12: 2017/2018 | K12: =SUMIFS($H$5:$H$757,$E$5:$E$757,J12,$G$5:$G$757,"Corn") -> 4388664 | L12: =SUMIFS($H$5:$H$757,$E$5:$E$757,J12,$G$5:$G$757,"Soybean") -> 8560600 | M12: =K12+L12 -> 12949264 | N12: =COUNTIFS($E$5:$E$757,J12) -> 76
A13: 41466 | B13: 41480 | C13: 41473 | D13: Not Available | E13: 2013/2014 | F13: 2012/2013 | G13: Soybean | H13: 120000 | J13: 2018/2019 | K13: =SUMIFS($H$5:$H$757,$E$5:$E$757,J13,$G$5:$G$757,"Corn") -> 1998484 | L13: =SUMIFS($H$5:$H$757,$E$5:$E$757,J13,$G$5:$G$757,"Soybean") -> 8553006 | M13: =K13+L13 -> 10551490 | N13: =COUNTIFS($E$5:$E$757,J13) -> 65
A14: 41470 | B14: 41487 | C14: 41480 | D14: Not Available | E14: 2013/2014 | F14: 2012/2013 | G14: Corn | H14: 120000 | J14: 2019/2020 | K14: =SUMIFS($H$5:$H$757,$E$5:$E$757,J14,$G$5:$G$757,"Corn") -> 1902009 | L14: =SUMIFS($H$5:$H$757,$E$5:$E$757,J14,$G$5:$G$757,"Soybean") -> 4068579 | M14: =K14+L14 -> 5970588 | N14: =COUNTIFS($E$5:$E$757,J14) -> 46
A15: 41481 | B15: 41501 | C15: 41494 | D15: Not Available | E15: 2012/2013 | F15: 2012/2013 | G15: Corn | H15: 8128 | J15: 2020/2021 | K15: =SUMIFS($H$5:$H$757,$E$5:$E$757,J15,$G$5:$G$757,"Corn") -> 5430028 | L15: =SUMIFS($H$5:$H$757,$E$5:$E$757,J15,$G$5:$G$757,"Soybean") -> 9149550 | M15: =K15+L15 -> 14579578 | N15: =COUNTIFS($E$5:$E$757,J15) -> 82
A16: 41481 | B16: 41501 | C16: 41494 | D16: Not Available | E16: 2013/2014 | F16: 2012/2013 | G16: Corn | H16: 203200 | J16: 2021/2022 | K16: =SUMIFS($H$5:$H$757,$E$5:$E$757,J16,$G$5:$G$757,"Corn") -> 2846684 | L16: =SUMIFS($H$5:$H$757,$E$5:$E$757,J16,$G$5:$G$757,"Soybean") -> 9363030 | M16: =K16+L16 -> 12209714 | N16: =COUNTIFS($E$5:$E$757,J16) -> 68
... A21: 41527 | B21: 41543 | C21: 41536 | D21: Not Available | E21: 2013/2014 | F21: 2013/2014 | G21: Soybean | H21: 121000 | J21: 2026/2027 | K21: =SUMIFS($H$5:$H$757,$E$5:$E$757,J21,$G$5:$G$757,"Corn") -> 532272 | L21: =SUMIFS($H$5:$H$757,$E$5:$E$757,J21,$G$5:$G$757,"Soybean") -> 4172250 | M21: =K21+L21 -> 4704522 | N21: =COUNTIFS($E$5:$E$757,J21) -> 27
A22: 41535 | B22: 41550 | C22: 41543 | D22: Not Available | E22: 2013/2014 | F22: 2013/2014 | G22: Soybean | H22: 182000 | J22: Total | K22: =SUM(K5:K21) -> 38070189 | L22: =SUM(L5:L21) -> 88620406 | M22: =SUM(M5:M21) -> 126690595 | N22: =SUM(N5:N21) -> 753
A23: 41536 | B23: 41550 | C23: 41543 | D23: Not Available | E23: 2013/2014 | F23: 2013/2014 | G23: Soybean | H23: 120000
A24: 41542 | B24: 41557 | C24: 41550 | D24: Not Available | E24: 2013/2014 | F24: 2013/2014 | G24: Soybean | H24: 140000
A25: 41565 | B25: 41585 | C25: 41578 | D25: Not Available | E25: 2013/2014 | F25: 2013/2014 | G25: Soybean | H25: 140000 | J25: By sale season (Sep 1 – Aug 31, based on the date the sale was made)
A26: 41568 | B26: 41585 | C26: 41578 | D26: Not Available | E26: 2013/2014 | F26: 2013/2014 | G26: Soybean | H26: 235000 | J26: Sale Season | K26: Corn | L26: Soybean | M26: Total | N26: # Sales
A27: 41583 | B27: 41599 | C27: 41592 | D27: Not Available | E27: 2013/2014 | F27: 2013/2014 | G27: Corn | H27: 126000 | J27: 2010/2011 | K27: =SUMIFS($H$5:$H$757,$F$5:$F$757,J27,$G$5:$G$757,"Corn") -> 230000 | L27: =SUMIFS($H$5:$H$757,$F$5:$F$757,J27,$G$5:$G$757,"Soybean") -> 0 | M27: =K27+L27 -> 230000 | N27: =COUNTIFS($F$5:$F$757,J27) -> 2
A28: 41603 | B28: 41620 | C28: 41613 | D28: Not Available | E28: 2014/2015 | F28: 2013/2014 | G28: Soybean | H28: 120000 | J28: 2012/2013 | K28: =SUMIFS($H$5:$H$757,$F$5:$F$757,J28,$G$5:$G$757,"Corn") -> 458328 | L28: =SUMIFS($H$5:$H$757,$F$5:$F$757,J28,$G$5:$G$757,"Soybean") -> 1338950 | M28: =K28+L28 -> 1797278 | N28: =COUNTIFS($F$5:$F$757,J28) -> 14
A29: 41604 | B29: 41620 | C29: 41613 | D29: Not Available | E29: 2013/2014 | F29: 2013/2014 | G29: Soybean | H29: 360000 | J29: 2013/2014 | K29: =SUMIFS($H$5:$H$757,$F$5:$F$757,J29,$G$5:$G$757,"Corn") -> 595136 | L29: =SUMIFS($H$5:$H$757,$F$5:$F$757,J29,$G$5:$G$757,"Soybean") -> 2555150 | M29: =K29+L29 -> 3150286 | N29: =COUNTIFS($F$5:$F$757,J29) -> 19
A30: 41614 | B30: 41634 | C30: 41627 | D30: Not Available | E30: 2013/2014 | F30: 2013/2014 | G30: Soybean | H30: 189150 | J30: 2015/2016 | K30: =SUMIFS($H$5:$H$757,$F$5:$F$757,J30,$G$5:$G$757,"Corn") -> 2616488 | L30: =SUMIFS($H$5:$H$757,$F$5:$F$757,J30,$G$5:$G$757,"Soybean") -> 6800700 | M30: =K30+L30 -> 9417188 | N30: =COUNTIFS($F$5:$F$757,J30) -> 61
A31: 41614 | B31: 41634 | C31: 41627 | D31: Not Available | E31: 2014/2015 | F31: 2013/2014 | G31: Soybean | H31: 195000 | J31: 2016/2017 | K31: =SUMIFS($H$5:$H$757,$F$5:$F$757,J31,$G$5:$G$757,"Corn") -> 2919785 | L31: =SUMIFS($H$5:$H$757,$F$5:$F$757,J31,$G$5:$G$757,"Soybean") -> 7836091 | M31: =K31+L31 -> 10755876 | N31: =COUNTIFS($F$5:$F$757,J31) -> 74
A32: 41619 | B32: 41634 | C32: 41627 | D32: Not Available | E32: 2013/2014 | F32: 2013/2014 | G32: Corn | H32: 120000 | J32: 2017/2018 | K32: =SUMIFS($H$5:$H$757,$F$5:$F$757,J32,$G$5:$G$757,"Corn") -> 5088936 | L32: =SUMIFS($H$5:$H$757,$F$5:$F$757,J32,$G$5:$G$757,"Soybean") -> 10284300 | M32: =K32+L32 -> 15373236 | N32: =COUNTIFS($F$5:$F$757,J32) -> 89
A33: 41620 | B33: 41634 | C33: 41627 | D33: Not Available | E33: 2013/2014 | F33: 2013/2014 | G33: Corn | H33: 120000 | J33: 2018/2019 | K33: =SUMIFS($H$5:$H$757,$F$5:$F$757,J33,$G$5:$G$757,"Corn") -> 1138525 | L33: =SUMIFS($H$5:$H$757,$F$5:$F$757,J33,$G$5:$G$757,"Soybean") -> 6477806 | M33: =K33+L33 -> 7616331 | N33: =COUNTIFS($F$5:$F$757,J33) -> 49
A34: 41627 | B34: 41641 | C34: 41634 | D34: Not Available | E34: 2013/2014 | F34: 2013/2014 | G34: Corn | H34: 111280 | J34: 2019/2020 | K34: =SUMIFS($H$5:$H$757,$F$5:$F$757,J34,$G$5:$G$757,"Corn") -> 2969908 | L34: =SUMIFS($H$5:$H$757,$F$5:$F$757,J34,$G$5:$G$757,"Soybean") -> 6224879 | M34: =K34+L34 -> 9194787 | N34: =COUNTIFS($F$5:$F$757,J34) -> 63
A35: 41627 | B35: 41641 | C35: 41634 | D35: Not Available | E35: 2014/2015 | F35: 2013/2014 | G35: Corn | H35: 16256 | J35: 2020/2021 | K35: =SUMIFS($H$5:$H$757,$F$5:$F$757,J35,$G$5:$G$757,"Corn") -> 5132332 | L35: =SUMIFS($H$5:$H$757,$F$5:$F$757,J35,$G$5:$G$757,"Soybean") -> 8496900 | M35: =K35+L35 -> 13629232 | N35: =COUNTIFS($F$5:$F$757,J35) -> 77
A36: 41632 | B36: 41648 | C36: 41641 | D36: Not Available | E36: 2013/2014 | F36: 2013/2014 | G36: Soybean | H36: 65000 | J36: 2021/2022 | K36: =SUMIFS($H$5:$H$757,$F$5:$F$757,J36,$G$5:$G$757,"Corn") -> 2121668 | L36: =SUMIFS($H$5:$H$757,$F$5:$F$757,J36,$G$5:$G$757,"Soybean") -> 9141380 | M36: =K36+L36 -> 11263048 | N36: =COUNTIFS($F$5:$F$757,J36) -> 65
A37: 41632 | B37: 41648 | C37: 41641 | D37: Not Available | E37: 2014/2015 | F37: 2013/2014 | G37: Soybean | H37: 120000 | J37: 2022/2023 | K37: =SUMIFS($H$5:$H$757,$F$5:$F$757,J37,$G$5:$G$757,"Corn") -> 872600 | L37: =SUMIFS($H$5:$H$757,$F$5:$F$757,J37,$G$5:$G$757,"Soybean") -> 7701450 | M37: =K37+L37 -> 8574050 | N37: =COUNTIFS($F$5:$F$757,J37) -> 42
A38: 41695 | B38: 41711 | C38: 41704 | D38: Not Available | E38: 2013/2014 | F38: 2013/2014 | G38: Soybean | H38: 568000 | J38: 2023/2024 | K38: =SUMIFS($H$5:$H$757,$F$5:$F$757,J38,$G$5:$G$757,"Corn") -> 1307208 | L38: =SUMIFS($H$5:$H$757,$F$5:$F$757,J38,$G$5:$G$757,"Soybean") -> 7918750 | M38: =K38+L38 -> 9225958 | N38: =COUNTIFS($F$5:$F$757,J38) -> 51
... A41: 42380 | B41: 42397 | C41: 42390 | D41: Not Available | E41: 2015/2016 | F41: 2015/2016 | G41: Soybean | H41: 248000 | J41: 2026/2027 | K41: =SUMIFS($H$5:$H$757,$F$5:$F$757,J41,$G$5:$G$757,"Corn") -> 0 | L41: =SUMIFS($H$5:$H$757,$F$5:$F$757,J41,$G$5:$G$757,"Soybean") -> 766100 | M41: =K41+L41 -> 766100 | N41: =COUNTIFS($F$5:$F$757,J41) -> 5
A42: 42381 | B42: 42397 | C42: 42390 | D42: Not Available | E42: 2015/2016 | F42: 2015/2016 | G42: Soybean | H42: 140000 | J42: Total | K42: =SUM(K27:K41) -> 38070189 | L42: =SUM(L27:L41) -> 88620406 | M42: =SUM(M27:M41) -> 126690595 | N42: =SUM(N27:N41) -> 753
A43: 42388 | B43: 42404 | C43: 42397 | D43: Not Available | E43: 2015/2016 | F43: 2015/2016 | G43: Corn | H43: 110500
A44: 42410 | B44: 42425 | C44: 42418 | D44: Not Available | E44: 2015/2016 | F44: 2015/2016 | G44: Corn | H44: 152400
A45: 42430 | B45: 42446 | C45: 42439 | D45: Not Available | E45: 2015/2016 | F45: 2015/2016 | G45: Soybean | H45: 140000
A46: 42437 | B46: 42453 | C46: 42446 | D46: Not Available | E46: 2015/2016 | F46: 2015/2016 | G46: Soybean | H46: 70000
...

Sheet China
A1: China — USDA daily flash sales (metric tonnes)
A2: Detail sorted by sale date. Summaries on the right are formulas over the detail.
J3: By delivery marketing year (USDA "Marketing Year": season the grain ships in)
A4: Sale Date | B4: Reported in | C4: Week Ending Date | D4: Destination | E4: Delivery MY (USDA) | F4: Sale Season (Sep-Aug) | G4: Product | H4: Quantity | J4: Delivery MY | K4: Corn | L4: Soybean | M4: Total | N4: # Sales
A5: 40721 | B5: 40738 | C5: 40731 | D5: China | E5: 2010/2011 | F5: 2010/2011 | G5: Soybean | H5: 132000 | J5: 2010/2011 | K5: =SUMIFS($H$5:$H$527,$E$5:$E$527,J5,$G$5:$G$527,"Corn") -> 0 | L5: =SUMIFS($H$5:$H$527,$E$5:$E$527,J5,$G$5:$G$527,"Soybean") -> 132000 | M5: =K5+L5 -> 132000 | N5: =COUNTIFS($E$5:$E$527,J5) -> 1
A6: 40949 | B6: 40969 | C6: 40962 | D6: China | E6: 2011/2012 | F6: 2011/2012 | G6: Soybean | H6: 120000 | J6: 2011/2012 | K6: =SUMIFS($H$5:$H$527,$E$5:$E$527,J6,$G$5:$G$527,"Corn") -> 0 | L6: =SUMIFS($H$5:$H$527,$E$5:$E$527,J6,$G$5:$G$527,"Soybean") -> 773000 | M6: =K6+L6 -> 773000 | N6: =COUNTIFS($E$5:$E$527,J6) -> 3
A7: 40956 | B7: 40976 | C7: 40969 | D7: China | E7: 2011/2012 | F7: 2011/2012 | G7: Soybean | H7: 173000 | J7: 2012/2013 | K7: =SUMIFS($H$5:$H$527,$E$5:$E$527,J7,$G$5:$G$527,"Corn") -> 0 | L7: =SUMIFS($H$5:$H$527,$E$5:$E$527,J7,$G$5:$G$527,"Soybean") -> 2750000 | M7: =K7+L7 -> 2750000 | N7: =COUNTIFS($E$5:$E$527,J7) -> 1
A8: 40956 | B8: 40976 | C8: 40969 | D8: China | E8: 2012/2013 | F8: 2011/2012 | G8: Soybean | H8: 2750000 | J8: 2013/2014 | K8: =SUMIFS($H$5:$H$527,$E$5:$E$527,J8,$G$5:$G$527,"Corn") -> 1080000 | L8: =SUMIFS($H$5:$H$527,$E$5:$E$527,J8,$G$5:$G$527,"Soybean") -> 5005000 | M8: =K8+L8 -> 6085000 | N8: =COUNTIFS($E$5:$E$527,J8) -> 18
A9: 41046 | B9: 41060 | C9: 41053 | D9: China | E9: 2011/2012 | F9: 2011/2012 | G9: Soybean | H9: 480000 | J9: 2014/2015 | K9: =SUMIFS($H$5:$H$527,$E$5:$E$527,J9,$G$5:$G$527,"Corn") -> 0 | L9: =SUMIFS($H$5:$H$527,$E$5:$E$527,J9,$G$5:$G$527,"Soybean") -> 477000 | M9: =K9+L9 -> 477000 | N9: =COUNTIFS($E$5:$E$527,J9) -> 3
A10: 41330 | B10: 41347 | C10: 41340 | D10: China | E10: 2013/2014 | F10: 2012/2013 | G10: Soybean | H10: 120000 | J10: 2015/2016 | K10: =SUMIFS($H$5:$H$527,$E$5:$E$527,J10,$G$5:$G$527,"Corn") -> 0 | L10: =SUMIFS($H$5:$H$527,$E$5:$E$527,J10,$G$5:$G$527,"Soybean") -> 1219000 | M10: =K10+L10 -> 1219000 | N10: =COUNTIFS($E$5:$E$527,J10) -> 8
A11: 41443 | B11: 41459 | C11: 41452 | D11: China | E11: 2013/2014 | F11: 2012/2013 | G11: Soybean | H11: 240000 | J11: 2016/2017 | K11: =SUMIFS($H$5:$H$527,$E$5:$E$527,J11,$G$5:$G$527,"Corn") -> 0 | L11: =SUMIFS($H$5:$H$527,$E$5:$E$527,J11,$G$5:$G$527,"Soybean") -> 11002570 | M11: =K11+L11 -> 11002570 | N11: =COUNTIFS($E$5:$E$527,J11) -> 51
A12: 41466 | B12: 41480 | C12: 41473 | D12: China | E12: 2013/2014 | F12: 2012/2013 | G12: Corn | H12: 120000 | J12: 2017/2018 | K12: =SUMIFS($H$5:$H$527,$E$5:$E$527,J12,$G$5:$G$527,"Corn") -> 0 | L12: =SUMIFS($H$5:$H$527,$E$5:$E$527,J12,$G$5:$G$527,"Soybean") -> 9965000 | M12: =K12+L12 -> 9965000 | N12: =COUNTIFS($E$5:$E$527,J12) -> 42
A13: 41467 | B13: 41487 | C13: 41480 | D13: China | E13: 2013/2014 | F13: 2012/2013 | G13: Corn | H13: 960000 | J13: 2018/2019 | K13: =SUMIFS($H$5:$H$527,$E$5:$E$527,J13,$G$5:$G$527,"Corn") -> 300000 | L13: =SUMIFS($H$5:$H$527,$E$5:$E$527,J13,$G$5:$G$527,"Soybean") -> 12235000 | M13: =K13+L13 -> 12535000 | N13: =COUNTIFS($E$5:$E$527,J13) -> 20
A14: 41472 | B14: 41487 | C14: 41480 | D14: China | E14: 2013/2014 | F14: 2012/2013 | G14: Soybean | H14: 165000 | J14: 2019/2020 | K14: =SUMIFS($H$5:$H$527,$E$5:$E$527,J14,$G$5:$G$527,"Corn") -> 1955000 | L14: =SUMIFS($H$5:$H$527,$E$5:$E$527,J14,$G$5:$G$527,"Soybean") -> 6740000 | M14: =K14+L14 -> 8695000 | N14: =COUNTIFS($E$5:$E$527,J14) -> 37
A15: 41481 | B15: 41501 | C15: 41494 | D15: China | E15: 2013/2014 | F15: 2012/2013 | G15: Soybean | H15: 220000 | J15: 2020/2021 | K15: =SUMIFS($H$5:$H$527,$E$5:$E$527,J15,$G$5:$G$527,"Corn") -> 20005000 | L15: =SUMIFS($H$5:$H$527,$E$5:$E$527,J15,$G$5:$G$527,"Soybean") -> 13377000 | M15: =K15+L15 -> 33382000 | N15: =COUNTIFS($E$5:$E$527,J15) -> 84
A16: 41498 | B16: 41515 | C16: 41508 | D16: China | E16: 2013/2014 | F16: 2012/2013 | G16: Soybean | H16: 713000 | J16: 2021/2022 | K16: =SUMIFS($H$5:$H$527,$E$5:$E$527,J16,$G$5:$G$527,"Corn") -> 13759000 | L16: =SUMIFS($H$5:$H$527,$E$5:$E$527,J16,$G$5:$G$527,"Soybean") -> 7769000 | M16: =K16+L16 -> 21528000 | N16: =COUNTIFS($E$5:$E$527,J16) -> 68
... A21: 41535 | B21: 41550 | C21: 41543 | D21: China | E21: 2013/2014 | F21: 2013/2014 | G21: Soybean | H21: 1930000 | J21: 2026/2027 | K21: =SUMIFS($H$5:$H$527,$E$5:$E$527,J21,$G$5:$G$527,"Corn") -> 0 | L21: =SUMIFS($H$5:$H$527,$E$5:$E$527,J21,$G$5:$G$527,"Soybean") -> 6175000 | M21: =K21+L21 -> 6175000 | N21: =COUNTIFS($E$5:$E$527,J21) -> 28
A22: 41548 | B22: 41564 | C22: 41557 | D22: China | E22: 2013/2014 | F22: 2013/2014 | G22: Soybean | H22: 113000 | J22: Total | K22: =SUM(K5:K21) -> 44964000 | L22: =SUM(L5:L21) -> 102951270 | M22: =SUM(M5:M21) -> 147915270 | N22: =SUM(N5:N21) -> 523
A23: 41565 | B23: 41585 | C23: 41578 | D23: China | E23: 2013/2014 | F23: 2013/2014 | G23: Soybean | H23: 222000
A24: 41572 | B24: 41592 | C24: 41585 | D24: China | E24: 2013/2014 | F24: 2013/2014 | G24: Soybean | H24: 120000
A25: 41579 | B25: 41599 | C25: 41592 | D25: China | E25: 2013/2014 | F25: 2013/2014 | G25: Soybean | H25: 115000 | J25: By sale season (Sep 1 – Aug 31, based on the date the sale was made)
A26: 41591 | B26: 41606 | C26: 41599 | D26: China | E26: 2013/2014 | F26: 2013/2014 | G26: Soybean | H26: 123000 | J26: Sale Season | K26: Corn | L26: Soybean | M26: Total | N26: # Sales
A27: 41597 | B27: 41613 | C27: 41606 | D27: China | E27: 2014/2015 | F27: 2013/2014 | G27: Soybean | H27: 240000 | J27: 2010/2011 | K27: =SUMIFS($H$5:$H$527,$F$5:$F$527,J27,$G$5:$G$527,"Corn") -> 0 | L27: =SUMIFS($H$5:$H$527,$F$5:$F$527,J27,$G$5:$G$527,"Soybean") -> 132000 | M27: =K27+L27 -> 132000 | N27: =COUNTIFS($F$5:$F$527,J27) -> 1
A28: 41604 | B28: 41620 | C28: 41613 | D28: China | E28: 2013/2014 | F28: 2013/2014 | G28: Soybean | H28: 300000 | J28: 2011/2012 | K28: =SUMIFS($H$5:$H$527,$F$5:$F$527,J28,$G$5:$G$527,"Corn") -> 0 | L28: =SUMIFS($H$5:$H$527,$F$5:$F$527,J28,$G$5:$G$527,"Soybean") -> 3523000 | M28: =K28+L28 -> 3523000 | N28: =COUNTIFS($F$5:$F$527,J28) -> 4
A29: 41613 | B29: 41627 | C29: 41620 | D29: China | E29: 2014/2015 | F29: 2013/2014 | G29: Soybean | H29: 111000 | J29: 2012/2013 | K29: =SUMIFS($H$5:$H$527,$F$5:$F$527,J29,$G$5:$G$527,"Corn") -> 1080000 | L29: =SUMIFS($H$5:$H$527,$F$5:$F$527,J29,$G$5:$G$527,"Soybean") -> 2082000 | M29: =K29+L29 -> 3162000 | N29: =COUNTIFS($F$5:$F$527,J29) -> 11
A30: 41663 | B30: 41683 | C30: 41676 | D30: China | E30: 2014/2015 | F30: 2013/2014 | G30: Soybean | H30: 126000 | J30: 2013/2014 | K30: =SUMIFS($H$5:$H$527,$F$5:$F$527,J30,$G$5:$G$527,"Corn") -> 0 | L30: =SUMIFS($H$5:$H$527,$F$5:$F$527,J30,$G$5:$G$527,"Soybean") -> 3400000 | M30: =K30+L30 -> 3400000 | N30: =COUNTIFS($F$5:$F$527,J30) -> 10
A31: 42376 | B31: 42390 | C31: 42383 | D31: China | E31: 2015/2016 | F31: 2015/2016 | G31: Soybean | H31: 246000 | J31: 2015/2016 | K31: =SUMIFS($H$5:$H$527,$F$5:$F$527,J31,$G$5:$G$527,"Corn") -> 0 | L31: =SUMIFS($H$5:$H$527,$F$5:$F$527,J31,$G$5:$G$527,"Soybean") -> 5189000 | M31: =K31+L31 -> 5189000 | N31: =COUNTIFS($F$5:$F$527,J31) -> 28
A32: 42380 | B32: 42397 | C32: 42390 | D32: China | E32: 2015/2016 | F32: 2015/2016 | G32: Soybean | H32: 120000 | J32: 2016/2017 | K32: =SUMIFS($H$5:$H$527,$F$5:$F$527,J32,$G$5:$G$527,"Corn") -> 0 | L32: =SUMIFS($H$5:$H$527,$F$5:$F$527,J32,$G$5:$G$527,"Soybean") -> 10029570 | M32: =K32+L32 -> 10029570 | N32: =COUNTIFS($F$5:$F$527,J32) -> 43
A33: 42397 | B33: 42411 | C33: 42404 | D33: China | E33: 2015/2016 | F33: 2015/2016 | G33: Soybean | H33: 395000 | J33: 2017/2018 | K33: =SUMIFS($H$5:$H$527,$F$5:$F$527,J33,$G$5:$G$527,"Corn") -> 0 | L33: =SUMIFS($H$5:$H$527,$F$5:$F$527,J33,$G$5:$G$527,"Soybean") -> 8408000 | M33: =K33+L33 -> 8408000 | N33: =COUNTIFS($F$5:$F$527,J33) -> 35
A34: 42437 | B34: 42453 | C34: 42446 | D34: China | E34: 2016/2017 | F34: 2015/2016 | G34: Soybean | H34: 110000 | J34: 2018/2019 | K34: =SUMIFS($H$5:$H$527,$F$5:$F$527,J34,$G$5:$G$527,"Corn") -> 300000 | L34: =SUMIFS($H$5:$H$527,$F$5:$F$527,J34,$G$5:$G$527,"Soybean") -> 10858000 | M34: =K34+L34 -> 11158000 | N34: =COUNTIFS($F$5:$F$527,J34) -> 16
A35: 42474 | B35: 42488 | C35: 42481 | D35: China | E35: 2016/2017 | F35: 2015/2016 | G35: Soybean | H35: 132000 | J35: 2019/2020 | K35: =SUMIFS($H$5:$H$527,$F$5:$F$527,J35,$G$5:$G$527,"Corn") -> 9960000 | L35: =SUMIFS($H$5:$H$527,$F$5:$F$527,J35,$G$5:$G$527,"Soybean") -> 14696000 | M35: =K35+L35 -> 24656000 | N35: =COUNTIFS($F$5:$F$527,J35) -> 81
A36: 42509 | B36: 42523 | C36: 42516 | D36: China | E36: 2015/2016 | F36: 2015/2016 | G36: Soybean | H36: 129000 | J36: 2020/2021 | K36: =SUMIFS($H$5:$H$527,$F$5:$F$527,J36,$G$5:$G$527,"Corn") -> 22744000 | L36: =SUMIFS($H$5:$H$527,$F$5:$F$527,J36,$G$5:$G$527,"Soybean") -> 8711000 | M36: =K36+L36 -> 31455000 | N36: =COUNTIFS($F$5:$F$527,J36) -> 68
A37: 42517 | B37: 42537 | C37: 42530 | D37: China | E37: 2016/2017 | F37: 2015/2016 | G37: Soybean | H37: 110000 | J37: 2021/2022 | K37: =SUMIFS($H$5:$H$527,$F$5:$F$527,J37,$G$5:$G$527,"Corn") -> 5797000 | L37: =SUMIFS($H$5:$H$527,$F$5:$F$527,J37,$G$5:$G$527,"Soybean") -> 9875000 | M37: =K37+L37 -> 15672000 | N37: =COUNTIFS($F$5:$F$527,J37) -> 76
A38: 42528 | B38: 42544 | C38: 42537 | D38: China | E38: 2016/2017 | F38: 2015/2016 | G38: Soybean | H38: 180000 | J38: 2022/2023 | K38: =SUMIFS($H$5:$H$527,$F$5:$F$527,J38,$G$5:$G$527,"Corn") -> 5083000 | L38: =SUMIFS($H$5:$H$527,$F$5:$F$527,J38,$G$5:$G$527,"Soybean") -> 4390700 | M38: =K38+L38 -> 9473700 | N38: =COUNTIFS($F$5:$F$527,J38) -> 42
... A42: 42538 | B42: 42558 | C42: 42551 | D42: China | E42: 2016/2017 | F42: 2015/2016 | G42: Soybean | H42: 63000 | J42: 2026/2027 | K42: =SUMIFS($H$5:$H$527,$F$5:$F$527,J42,$G$5:$G$527,"Corn") -> 0 | L42: =SUMIFS($H$5:$H$527,$F$5:$F$527,J42,$G$5:$G$527,"Soybean") -> 1253000 | M42: =K42+L42 -> 1253000 | N42: =COUNTIFS($F$5:$F$527,J42) -> 6
A43: 42542 | B43: 42558 | C43: 42551 | D43: China | E43: 2016/2017 | F43: 2015/2016 | G43: Soybean | H43: 132000 | J43: Total | K43: =SUM(K27:K42) -> 44964000 | L43: =SUM(L27:L42) -> 102951270 | M43: =SUM(M27:M42) -> 147915270 | N43: =SUM(N27:N42) -> 523
A44: 42558 | B44: 42572 | C44: 42565 | D44: China | E44: 2016/2017 | F44: 2015/2016 | G44: Soybean | H44: 120000
A45: 42578 | B45: 42593 | C45: 42586 | D45: China | E45: 2015/2016 | F45: 2015/2016 | G45: Soybean | H45: 65000
A46: 42578 | B46: 42593 | C46: 42586 | D46: China | E46: 2016/2017 | F46: 2015/2016 | G46: Soybean | H46: 66000
A47: 42579 | B47: 42593 | C47: 42586 | D47: China | E47: 2015/2016 | F47: 2015/2016 | G47: Soybean | H47: 66000
...

Sheet Mexico
A1: Mexico — USDA daily flash sales (metric tonnes)
A2: Detail sorted by sale date. Summaries on the right are formulas over the detail.
J3: By delivery marketing year (USDA "Marketing Year": season the grain ships in)
A4: Sale Date | B4: Reported in | C4: Week Ending Date | D4: Destination | E4: Delivery MY (USDA) | F4: Sale Season (Sep-Aug) | G4: Product | H4: Quantity | J4: Delivery MY | K4: Corn | L4: Soybean | M4: Total | N4: # Sales
A5: 41478 | B5: 41494 | C5: 41487 | D5: Mexico | E5: 2012/2013 | F5: 2012/2013 | G5: Corn | H5: 11000 | J5: 2012/2013 | K5: =SUMIFS($H$5:$H$365,$E$5:$E$365,J5,$G$5:$G$365,"Corn") -> 11000 | L5: =SUMIFS($H$5:$H$365,$E$5:$E$365,J5,$G$5:$G$365,"Soybean") -> 0 | M5: =K5+L5 -> 11000 | N5: =COUNTIFS($E$5:$E$365,J5) -> 1
A6: 41478 | B6: 41494 | C6: 41487 | D6: Mexico | E6: 2013/2014 | F6: 2012/2013 | G6: Corn | H6: 95400 | J6: 2013/2014 | K6: =SUMIFS($H$5:$H$365,$E$5:$E$365,J6,$G$5:$G$365,"Corn") -> 677353 | L6: =SUMIFS($H$5:$H$365,$E$5:$E$365,J6,$G$5:$G$365,"Soybean") -> 0 | M6: =K6+L6 -> 677353 | N6: =COUNTIFS($E$5:$E$365,J6) -> 4
A7: 41498 | B7: 41515 | C7: 41508 | D7: Mexico | E7: 2013/2014 | F7: 2012/2013 | G7: Corn | H7: 252153 | J7: 2014/2015 | K7: =SUMIFS($H$5:$H$365,$E$5:$E$365,J7,$G$5:$G$365,"Corn") -> 243150 | L7: =SUMIFS($H$5:$H$365,$E$5:$E$365,J7,$G$5:$G$365,"Soybean") -> 0 | M7: =K7+L7 -> 243150 | N7: =COUNTIFS($E$5:$E$365,J7) -> 2
A8: 41540 | B8: 41557 | C8: 41550 | D8: Mexico | E8: 2013/2014 | F8: 2013/2014 | G8: Corn | H8: 197200 | J8: 2015/2016 | K8: =SUMIFS($H$5:$H$365,$E$5:$E$365,J8,$G$5:$G$365,"Corn") -> 460440 | L8: =SUMIFS($H$5:$H$365,$E$5:$E$365,J8,$G$5:$G$365,"Soybean") -> 47500 | M8: =K8+L8 -> 507940 | N8: =COUNTIFS($E$5:$E$365,J8) -> 5
A9: 41571 | B9: 41585 | C9: 41578 | D9: Mexico | E9: 2014/2015 | F9: 2013/2014 | G9: Corn | H9: 210000 | J9: 2016/2017 | K9: =SUMIFS($H$5:$H$365,$E$5:$E$365,J9,$G$5:$G$365,"Corn") -> 2835048 | L9: =SUMIFS($H$5:$H$365,$E$5:$E$365,J9,$G$5:$G$365,"Soybean") -> 517000 | M9: =K9+L9 -> 3352048 | N9: =COUNTIFS($E$5:$E$365,J9) -> 15
A10: 41612 | B10: 41627 | C10: 41620 | D10: Mexico | E10: 2013/2014 | F10: 2013/2014 | G10: Corn | H10: 132600 | J10: 2017/2018 | K10: =SUMIFS($H$5:$H$365,$E$5:$E$365,J10,$G$5:$G$365,"Corn") -> 4573677 | L10: =SUMIFS($H$5:$H$365,$E$5:$E$365,J10,$G$5:$G$365,"Soybean") -> 601546 | M10: =K10+L10 -> 5175223 | N10: =COUNTIFS($E$5:$E$365,J10) -> 30
A11: 41612 | B11: 41627 | C11: 41620 | D11: Mexico | E11: 2014/2015 | F11: 2013/2014 | G11: Corn | H11: 33150 | J11: 2018/2019 | K11: =SUMIFS($H$5:$H$365,$E$5:$E$365,J11,$G$5:$G$365,"Corn") -> 5111605 | L11: =SUMIFS($H$5:$H$365,$E$5:$E$365,J11,$G$5:$G$365,"Soybean") -> 1707246 | M11: =K11+L11 -> 6818851 | N11: =COUNTIFS($E$5:$E$365,J11) -> 29
A12: 42383 | B12: 42397 | C12: 42390 | D12: Mexico | E12: 2015/2016 | F12: 2015/2016 | G12: Corn | H12: 102100 | J12: 2019/2020 | K12: =SUMIFS($H$5:$H$365,$E$5:$E$365,J12,$G$5:$G$365,"Corn") -> 5360532 | L12: =SUMIFS($H$5:$H$365,$E$5:$E$365,J12,$G$5:$G$365,"Soybean") -> 1386584 | M12: =K12+L12 -> 6747116 | N12: =COUNTIFS($E$5:$E$365,J12) -> 27
A13: 42389 | B13: 42404 | C13: 42397 | D13: Mexico | E13: 2015/2016 | F13: 2015/2016 | G13: Corn | H13: 243100 | J13: 2020/2021 | K13: =SUMIFS($H$5:$H$365,$E$5:$E$365,J13,$G$5:$G$365,"Corn") -> 4544553 | L13: =SUMIFS($H$5:$H$365,$E$5:$E$365,J13,$G$5:$G$365,"Soybean") -> 1233013 | M13: =K13+L13 -> 5777566 | N13: =COUNTIFS($E$5:$E$365,J13) -> 31
A14: 42408 | B14: 42425 | C14: 42418 | D14: Mexico | E14: 2015/2016 | F14: 2015/2016 | G14: Corn | H14: 100000 | J14: 2021/2022 | K14: =SUMIFS($H$5:$H$365,$E$5:$E$365,J14,$G$5:$G$365,"Corn") -> 5509685 | L14: =SUMIFS($H$5:$H$365,$E$5:$E$365,J14,$G$5:$G$365,"Soybean") -> 1900466 | M14: =K14+L14 -> 7410151 | N14: =COUNTIFS($E$5:$E$365,J14) -> 38
A15: 42478 | B15: 42495 | C15: 42488 | D15: Mexico | E15: 2015/2016 | F15: 2015/2016 | G15: Soybean | H15: 47500 | J15: 2022/2023 | K15: =SUMIFS($H$5:$H$365,$E$5:$E$365,J15,$G$5:$G$365,"Corn") -> 4649566 | L15: =SUMIFS($H$5:$H$365,$E$5:$E$365,J15,$G$5:$G$365,"Soybean") -> 1079559 | M15: =K15+L15 -> 5729125 | N15: =COUNTIFS($E$5:$E$365,J15) -> 29
A16: 42478 | B16: 42495 | C16: 42488 | D16: Mexico | E16: 2016/2017 | F16: 2015/2016 | G16: Soybean | H16: 332500 | J16: 2023/2024 | K16: =SUMIFS($H$5:$H$365,$E$5:$E$365,J16,$G$5:$G$365,"Corn") -> 6488894 | L16: =SUMIFS($H$5:$H$365,$E$5:$E$365,J16,$G$5:$G$365,"Soybean") -> 1099394 | M16: =K16+L16 -> 7588288 | N16: =COUNTIFS($E$5:$E$365,J16) -> 43
... A21: 42558 | B21: 42572 | C21: 42565 | D21: Mexico | E21: 2017/2018 | F21: 2015/2016 | G21: Corn | H21: 30480 | J21: 2028/2029 | K21: =SUMIFS($H$5:$H$365,$E$5:$E$365,J21,$G$5:$G$365,"Corn") -> 22400 | L21: =SUMIFS($H$5:$H$365,$E$5:$E$365,J21,$G$5:$G$365,"Soybean") -> 0 | M21: =K21+L21 -> 22400 | N21: =COUNTIFS($E$5:$E$365,J21) -> 1
A22: 42590 | B22: 42607 | C22: 42600 | D22: Mexico | E22: 2016/2017 | F22: 2015/2016 | G22: Corn | H22: 162569 | J22: Total | K22: =SUM(K5:K21) -> 59200680 | L22: =SUM(L5:L21) -> 11851974 | M22: =SUM(M5:M21) -> 71052654 | N22: =SUM(N5:N21) -> 361
A23: 42592 | B23: 42607 | C23: 42600 | D23: Mexico | E23: 2016/2017 | F23: 2015/2016 | G23: Corn | H23: 143650
A24: 42613 | B24: 42628 | C24: 42621 | D24: Mexico | E24: 2016/2017 | F24: 2015/2016 | G24: Corn | H24: 275000
A25: 42614 | B25: 42628 | C25: 42621 | D25: Mexico | E25: 2016/2017 | F25: 2016/2017 | G25: Corn | H25: 99060 | J25: By sale season (Sep 1 – Aug 31, based on the date the sale was made)
A26: 42614 | B26: 42628 | C26: 42621 | D26: Mexico | E26: 2017/2018 | F26: 2016/2017 | G26: Corn | H26: 30480 | J26: Sale Season | K26: Corn | L26: Soybean | M26: Total | N26: # Sales
A27: 42632 | B27: 42649 | C27: 42642 | D27: Mexico | E27: 2016/2017 | F27: 2016/2017 | G27: Corn | H27: 191000 | J27: 2012/2013 | K27: =SUMIFS($H$5:$H$365,$F$5:$F$365,J27,$G$5:$G$365,"Corn") -> 358553 | L27: =SUMIFS($H$5:$H$365,$F$5:$F$365,J27,$G$5:$G$365,"Soybean") -> 0 | M27: =K27+L27 -> 358553 | N27: =COUNTIFS($F$5:$F$365,J27) -> 3
A28: 42641 | B28: 42656 | C28: 42649 | D28: Mexico | E28: 2016/2017 | F28: 2016/2017 | G28: Corn | H28: 1036320 | J28: 2013/2014 | K28: =SUMIFS($H$5:$H$365,$F$5:$F$365,J28,$G$5:$G$365,"Corn") -> 572950 | L28: =SUMIFS($H$5:$H$365,$F$5:$F$365,J28,$G$5:$G$365,"Soybean") -> 0 | M28: =K28+L28 -> 572950 | N28: =COUNTIFS($F$5:$F$365,J28) -> 4
A29: 42641 | B29: 42656 | C29: 42649 | D29: Mexico | E29: 2017/2018 | F29: 2016/2017 | G29: Corn | H29: 541020 | J29: 2015/2016 | K29: =SUMIFS($H$5:$H$365,$F$5:$F$365,J29,$G$5:$G$365,"Corn") -> 1283979 | L29: =SUMIFS($H$5:$H$365,$F$5:$F$365,J29,$G$5:$G$365,"Soybean") -> 380000 | M29: =K29+L29 -> 1663979 | N29: =COUNTIFS($F$5:$F$365,J29) -> 13
A30: 42675 | B30: 42691 | C30: 42684 | D30: Mexico | E30: 2016/2017 | F30: 2016/2017 | G30: Corn | H30: 212344 | J30: 2016/2017 | K30: =SUMIFS($H$5:$H$365,$F$5:$F$365,J30,$G$5:$G$365,"Corn") -> 3706744 | L30: =SUMIFS($H$5:$H$365,$F$5:$F$365,J30,$G$5:$G$365,"Soybean") -> 254500 | M30: =K30+L30 -> 3961244 | N30: =COUNTIFS($F$5:$F$365,J30) -> 20
A31: 42677 | B31: 42691 | C31: 42684 | D31: Mexico | E31: 2016/2017 | F31: 2016/2017 | G31: Corn | H31: 432000 | J31: 2017/2018 | K31: =SUMIFS($H$5:$H$365,$F$5:$F$365,J31,$G$5:$G$365,"Corn") -> 3933705 | L31: =SUMIFS($H$5:$H$365,$F$5:$F$365,J31,$G$5:$G$365,"Soybean") -> 1280216 | M31: =K31+L31 -> 5213921 | N31: =COUNTIFS($F$5:$F$365,J31) -> 30
A32: 42726 | B32: 42740 | C32: 42733 | D32: Mexico | E32: 2016/2017 | F32: 2016/2017 | G32: Corn | H32: 100400 | J32: 2018/2019 | K32: =SUMIFS($H$5:$H$365,$F$5:$F$365,J32,$G$5:$G$365,"Corn") -> 6118191 | L32: =SUMIFS($H$5:$H$365,$F$5:$F$365,J32,$G$5:$G$365,"Soybean") -> 1324498 | M32: =K32+L32 -> 7442689 | N32: =COUNTIFS($F$5:$F$365,J32) -> 26
A33: 42759 | B33: 42775 | C33: 42768 | D33: Mexico | E33: 2016/2017 | F33: 2016/2017 | G33: Soybean | H33: 42000 | J33: 2019/2020 | K33: =SUMIFS($H$5:$H$365,$F$5:$F$365,J33,$G$5:$G$365,"Corn") -> 4557643 | L33: =SUMIFS($H$5:$H$365,$F$5:$F$365,J33,$G$5:$G$365,"Soybean") -> 1685577 | M33: =K33+L33 -> 6243220 | N33: =COUNTIFS($F$5:$F$365,J33) -> 29
A34: 42759 | B34: 42775 | C34: 42768 | D34: Mexico | E34: 2017/2018 | F34: 2016/2017 | G34: Soybean | H34: 70000 | J34: 2020/2021 | K34: =SUMIFS($H$5:$H$365,$F$5:$F$365,J34,$G$5:$G$365,"Corn") -> 5036443 | L34: =SUMIFS($H$5:$H$365,$F$5:$F$365,J34,$G$5:$G$365,"Soybean") -> 1187788 | M34: =K34+L34 -> 6224231 | N34: =COUNTIFS($F$5:$F$365,J34) -> 32
A35: 42780 | B35: 42796 | C35: 42789 | D35: Mexico | E35: 2016/2017 | F35: 2016/2017 | G35: Soybean | H35: 142500 | J35: 2021/2022 | K35: =SUMIFS($H$5:$H$365,$F$5:$F$365,J35,$G$5:$G$365,"Corn") -> 4884495 | L35: =SUMIFS($H$5:$H$365,$F$5:$F$365,J35,$G$5:$G$365,"Soybean") -> 1780882 | M35: =K35+L35 -> 6665377 | N35: =COUNTIFS($F$5:$F$365,J35) -> 35
A36: 42808 | B36: 42824 | C36: 42817 | D36: Mexico | E36: 2017/2018 | F36: 2016/2017 | G36: Corn | H36: 120000 | J36: 2022/2023 | K36: =SUMIFS($H$5:$H$365,$F$5:$F$365,J36,$G$5:$G$365,"Corn") -> 5701859 | L36: =SUMIFS($H$5:$H$365,$F$5:$F$365,J36,$G$5:$G$365,"Soybean") -> 1066617 | M36: =K36+L36 -> 6768476 | N36: =COUNTIFS($F$5:$F$365,J36) -> 35
A37: 42902 | B37: 42922 | C37: 42915 | D37: Mexico | E37: 2017/2018 | F37: 2016/2017 | G37: Corn | H37: 120000 | J37: 2023/2024 | K37: =SUMIFS($H$5:$H$365,$F$5:$F$365,J37,$G$5:$G$365,"Corn") -> 6872074 | L37: =SUMIFS($H$5:$H$365,$F$5:$F$365,J37,$G$5:$G$365,"Soybean") -> 959722 | M37: =K37+L37 -> 7831796 | N37: =COUNTIFS($F$5:$F$365,J37) -> 47
A38: 42919 | B38: 42936 | C38: 42929 | D38: Mexico | E38: 2017/2018 | F38: 2016/2017 | G38: Corn | H38: 22860 | J38: 2024/2025 | K38: =SUMIFS($H$5:$H$365,$F$5:$F$365,J38,$G$5:$G$365,"Corn") -> 8478400 | L38: =SUMIFS($H$5:$H$365,$F$5:$F$365,J38,$G$5:$G$365,"Soybean") -> 1092016 | M38: =K38+L38 -> 9570416 | N38: =COUNTIFS($F$5:$F$365,J38) -> 46
... A40: 42923 | B40: 42943 | C40: 42936 | D40: Mexico | E40: 2016/2017 | F40: 2016/2017 | G40: Corn | H40: 11000 | J40: 2026/2027 | K40: =SUMIFS($H$5:$H$365,$F$5:$F$365,J40,$G$5:$G$365,"Corn") -> 895020 | L40: =SUMIFS($H$5:$H$365,$F$5:$F$365,J40,$G$5:$G$365,"Soybean") -> 0 | M40: =K40+L40 -> 895020 | N40: =COUNTIFS($F$5:$F$365,J40) -> 7
A41: 42923 | B41: 42943 | C41: 42936 | D41: Mexico | E41: 2017/2018 | F41: 2016/2017 | G41: Corn | H41: 132000 | J41: Total | K41: =SUM(K27:K40) -> 59200680 | L41: =SUM(L27:L40) -> 11851974 | M41: =SUM(M27:M40) -> 71052654 | N41: =SUM(N27:N40) -> 361
A42: 42954 | B42: 42971 | C42: 42964 | D42: Mexico | E42: 2017/2018 | F42: 2016/2017 | G42: Corn | H42: 180800
A43: 42975 | B43: 42992 | C43: 42985 | D43: Mexico | E43: 2017/2018 | F43: 2016/2017 | G43: Corn | H43: 160020
A44: 42976 | B44: 42992 | C44: 42985 | D44: Mexico | E44: 2017/2018 | F44: 2016/2017 | G44: Corn | H44: 226000
A45: 42983 | B45: 42999 | C45: 42992 | D45: Mexico | E45: 2017/2018 | F45: 2017/2018 | G45: Corn | H45: 143650
...

Sheet Japan
A1: Japan — USDA daily flash sales (metric tonnes)
A2: Detail sorted by sale date. Summaries on the right are formulas over the detail.
J3: By delivery marketing year (USDA "Marketing Year": season the grain ships in)
A4: Sale Date | B4: Reported in | C4: Week Ending Date | D4: Destination | E4: Delivery MY (USDA) | F4: Sale Season (Sep-Aug) | G4: Product | H4: Quantity | J4: Delivery MY | K4: Corn | L4: Soybean | M4: Total | N4: # Sales
A5: 41578 | B5: 41592 | C5: 41585 | D5: Japan | E5: 2013/2014 | F5: 2013/2014 | G5: Corn | H5: 123040 | J5: 2013/2014 | K5: =SUMIFS($H$5:$H$63,$E$5:$E$63,J5,$G$5:$G$63,"Corn") -> 223040 | L5: =SUMIFS($H$5:$H$63,$E$5:$E$63,J5,$G$5:$G$63,"Soybean") -> 0 | M5: =K5+L5 -> 223040 | N5: =COUNTIFS($E$5:$E$63,J5) -> 2
A6: 41625 | B6: 41641 | C6: 41634 | D6: Japan | E6: 2014/2015 | F6: 2013/2014 | G6: Corn | H6: 278384 | J6: 2014/2015 | K6: =SUMIFS($H$5:$H$63,$E$5:$E$63,J6,$G$5:$G$63,"Corn") -> 458384 | L6: =SUMIFS($H$5:$H$63,$E$5:$E$63,J6,$G$5:$G$63,"Soybean") -> 0 | M6: =K6+L6 -> 458384 | N6: =COUNTIFS($E$5:$E$63,J6) -> 2
A7: 41628 | B7: 41648 | C7: 41641 | D7: Japan | E7: 2014/2015 | F7: 2013/2014 | G7: Corn | H7: 180000 | J7: 2015/2016 | K7: =SUMIFS($H$5:$H$63,$E$5:$E$63,J7,$G$5:$G$63,"Corn") -> 1146884 | L7: =SUMIFS($H$5:$H$63,$E$5:$E$63,J7,$G$5:$G$63,"Soybean") -> 0 | M7: =K7+L7 -> 1146884 | N7: =COUNTIFS($E$5:$E$63,J7) -> 9
A8: 41663 | B8: 41683 | C8: 41676 | D8: Japan | E8: 2013/2014 | F8: 2013/2014 | G8: Corn | H8: 100000 | J8: 2016/2017 | K8: =SUMIFS($H$5:$H$63,$E$5:$E$63,J8,$G$5:$G$63,"Corn") -> 1139704 | L8: =SUMIFS($H$5:$H$63,$E$5:$E$63,J8,$G$5:$G$63,"Soybean") -> 0 | M8: =K8+L8 -> 1139704 | N8: =COUNTIFS($E$5:$E$63,J8) -> 10
