Workbook

Sheet Summary
A1: US Imports of UCO & Tallow - Annual Totals (mln lbs.)
A3: Commodity | B3: 2020 | C3: 2021 | D3: 2022 | E3: 2023 | F3: 2024 | G3: 2025 | H3: 2026 (Jan-Aug)
A4: UCO (1518004000) | B4: =UCO!N4 -> 181.77012 | C4: =UCO!N32 -> 283.65253 | D4: =UCO!N60 -> 870.74883 | E4: =UCO!N92 -> 3026.3832 | F4: =UCO!N140 -> 5426.6699 | G4: =UCO!N189 -> 4780.1717 | H4: =UCO!N232 -> 2802.5525
A5: Inedible Tallow (1502100040) | B5: ='Inedible Tallow'!N4 -> 511.70646 | C5: ='Inedible Tallow'!N14 -> 702.4415 | D5: ='Inedible Tallow'!N25 -> 1148.6827 | E5: ='Inedible Tallow'!N36 -> 1698.3564 | F5: ='Inedible Tallow'!N54 -> 1930.5387 | G5: ='Inedible Tallow'!N75 -> 2241.2695 | H5: ='Inedible Tallow'!N96 -> 1419.9673
A6: Edible Tallow (1502100020) | B6: ='Edible Tallow'!N4 -> 24.095008 | C6: ='Edible Tallow'!N9 -> 30.371243 | D6: ='Edible Tallow'!N13 -> 72.747729 | E6: ='Edible Tallow'!N18 -> 32.906349 | F6: ='Edible Tallow'!N23 -> 22.236765 | G6: ='Edible Tallow'!N30 -> 39.358768 | H6: ='Edible Tallow'!N37 -> 46.106953
A9: Notes
A10: - Source: U.S. Census Bureau, USA Trade Online (two files exported Oct 7, 2026). Data through Aug 2026.
A11: - Volumes are General Imports (Quantity 1 Gen) in kg, converted at 2.20462262 lbs/kg (Data!B1) and shown in million lbs.
A12: - UCO = HTS 1518.00.4000 (animal & vegetable fats/oils, chemically modified), the statistical line under which used cooking oil enters the US.
A13: It can also include other chemically modified fats/oils, so treat it as a close UCO proxy rather than pure UCO.
A14: - HS 150210 (6-digit parent) carried no quantities in the export and is excluded; its 10-digit lines (edible/inedible) are used instead.
A15: - Regional aggregates (Asia, Europe, etc.) are excluded; country rows sum exactly to the Census world total.
A16: - Australia / New Zealand include their territories as reported by Census.

Sheet UCO
A1: US Imports of UCO - HTS 1518.00.4000 Animal & Veg. Fats/Oils, Chemically Modified (mln lbs.)
B3: Jan-20 | C3: Feb-20 | D3: Mar-20 | E3: Apr-20 | F3: May-20 | G3: Jun-20 | H3: Jul-20 | I3: Aug-20 | J3: Sep-20 | K3: Oct-20 | L3: Nov-20 | M3: Dec-20 | N3: Total | Q3: Monthly World Total by Marketing Year (Oct-Sep), mln lbs
A4: World Total | B4: =SUM(B5:B29) -> 17.556916 | C4: =SUM(C5:C29) -> 12.681357 | D4: =SUM(D5:D29) -> 20.558055 | E4: =SUM(E5:E29) -> 16.556789 | F4: =SUM(F5:F29) -> 18.625124 | G4: =SUM(G5:G29) -> 16.680494 | H4: =SUM(H5:H29) -> 12.795041 | I4: =SUM(I5:I29) -> 11.893161 | ... M4: =SUM(M5:M29) -> 14.590991 | N4: =SUM(B4:M4) -> 181.77012 | Q4: Month | R4: 2020/21 | S4: 2021/22 | T4: 2022/23 | U4: 2023/24 | V4: 2024/25 | W4: 2025/26
A5: Canada | B5: =SUMIFS(Data!$H$4:$H$2311,Data!$B$4:$B$2311,"UCO",Data!$C$4:$C$2311,"Canada",Data!$E$4:$E$2311,2020,Data!$F$4:$F$2311,1) -> 14.94218 | C5: =SUMIFS(Data!$H$4:$H$2311,Data!$B$4:$B$2311,"UCO",Data!$C$4:$C$2311,"Canada",Data!$E$4:$E$2311,2020,Data!$F$4:$F$2311,2) -> 9.4344995 | D5: =SUMIFS(Data!$H$4:$H$2311,Data!$B$4:$B$2311,"UCO",Data!$C$4:$C$2311,"Canada",Data!$E$4:$E$2311,2020,Data!$F$4:$F$2311,3) -> 17.295231 | E5: =SUMIFS(Data!$H$4:$H$2311,Data!$B$4:$B$2311,"UCO",Data!$C$4:$C$2311,"Canada",Data!$E$4:$E$2311,2020,Data!$F$4:$F$2311,4) -> 15.296227 | F5: =SUMIFS(Data!$H$4:$H$2311,Data!$B$4:$B$2311,"UCO",Data!$C$4:$C$2311,"Canada",Data!$E$4:$E$2311,2020,Data!$F$4:$F$2311,5) -> 17.384666 | G5: =SUMIFS(Data!$H$4:$H$2311,Data!$B$4:$B$2311,"UCO",Data!$C$4:$C$2311,"Canada",Data!$E$4:$E$2311,2020,Data!$F$4:$F$2311,6) -> 15.550954 | H5: =SUMIFS(Data!$H$4:$H$2311,Data!$B$4:$B$2311,"UCO",Data!$C$4:$C$2311,"Canada",Data!$E$4:$E$2311,2020,Data!$F$4:$F$2311,7) -> 11.381598 | I5: =SUMIFS(Data!$H$4:$H$2311,Data!$B$4:$B$2311,"UCO",Data!$C$4:$C$2311,"Canada",Data!$E$4:$E$2311,2020,Data!$F$4:$F$2311,8) -> 10.200668 | J5: =SUMIFS(Data!$H$4:$H$2311,Data!$B$4:$B$2311,"UCO",Data!$C$4:$C$2311,"Canada",Data!$E$4:$E$2311,2020,Data!$F$4:$F$2311,9) -> 11.015315 | K5: =SUMIFS(Data!$H$4:$H$2311,Data!$B$4:$B$2311,"UCO",Data!$C$4:$C$2311,"Canada",Data!$E$4:$E$2311,2020,Data!$F$4:$F$2311,10) -> 10.415164 | L5: =SUMIFS(Data!$H$4:$H$2311,Data!$B$4:$B$2311,"UCO",Data!$C$4:$C$2311,"Canada",Data!$E$4:$E$2311,2020,Data!$F$4:$F$2311,11) -> 14.181167 | M5: =SUMIFS(Data!$H$4:$H$2311,Data!$B$4:$B$2311,"UCO",Data!$C$4:$C$2311,"Canada",Data!$E$4:$E$2311,2020,Data!$F$4:$F$2311,12) -> 12.222044 | N5: =SUM(B5:M5) -> 159.31971 | Q5: Oct | R5: =SUMIFS(Data!$H$4:$H$2311,Data!$B$4:$B$2311,"UCO",Data!$C$4:$C$2311,"World Total",Data!$E$4:$E$2311,2020,Data!$F$4:$F$2311,10) -> 11.508758 | S5: =SUMIFS(Data!$H$4:$H$2311,Data!$B$4:$B$2311,"UCO",Data!$C$4:$C$2311,"World Total",Data!$E$4:$E$2311,2021,Data!$F$4:$F$2311,10) -> 29.971915 | T5: =SUMIFS(Data!$H$4:$H$2311,Data!$B$4:$B$2311,"UCO",Data!$C$4:$C$2311,"World Total",Data!$E$4:$E$2311,2022,Data!$F$4:$F$2311,10) -> 138.19786 | U5: =SUMIFS(Data!$H$4:$H$2311,Data!$B$4:$B$2311,"UCO",Data!$C$4:$C$2311,"World Total",Data!$E$4:$E$2311,2023,Data!$F$4:$F$2311,10) -> 414.54916 | V5: =SUMIFS(Data!$H$4:$H$2311,Data!$B$4:$B$2311,"UCO",Data!$C$4:$C$2311,"World Total",Data!$E$4:$E$2311,2024,Data!$F$4:$F$2311,10) -> 500.29727 | W5: =SUMIFS(Data!$H$4:$H$2311,Data!$B$4:$B$2311,"UCO",Data!$C$4:$C$2311,"World Total",Data!$E$4:$E$2311,2025,Data!$F$4:$F$2311,10) -> 282.68229
A6: Chile | B6: =SUMIFS(Data!$H$4:$H$2311,Data!$B$4:$B$2311,"UCO",Data!$C$4:$C$2311,"Chile",Data!$E$4:$E$2311,2020,Data!$F$4:$F$2311,1) -> 1.6464783 | C6: =SUMIFS(Data!$H$4:$H$2311,Data!$B$4:$B$2311,"UCO",Data!$C$4:$C$2311,"Chile",Data!$E$4:$E$2311,2020,Data!$F$4:$F$2311,2) -> 2.5705569 | D6: =SUMIFS(Data!$H$4:$H$2311,Data!$B$4:$B$2311,"UCO",Data!$C$4:$C$2311,"Chile",Data!$E$4:$E$2311,2020,Data!$F$4:$F$2311,3) -> 2.3008809 | E6: =SUMIFS(Data!$H$4:$H$2311,Data!$B$4:$B$2311,"UCO",Data!$C$4:$C$2311,"Chile",Data!$E$4:$E$2311,2020,Data!$F$4:$F$2311,4) -> 0.58768625 | F6: =SUMIFS(Data!$H$4:$H$2311,Data!$B$4:$B$2311,"UCO",Data!$C$4:$C$2311,"Chile",Data!$E$4:$E$2311,2020,Data!$F$4:$F$2311,5) -> 0.81198456 | G6: =SUMIFS(Data!$H$4:$H$2311,Data!$B$4:$B$2311,"UCO",Data!$C$4:$C$2311,"Chile",Data!$E$4:$E$2311,2020,Data!$F$4:$F$2311,6) -> 0.71317337 | H6: =SUMIFS(Data!$H$4:$H$2311,Data!$B$4:$B$2311,"UCO",Data!$C$4:$C$2311,"Chile",Data!$E$4:$E$2311,2020,Data!$F$4:$F$2311,7) -> 0.72988441 | I6: =SUMIFS(Data!$H$4:$H$2311,Data!$B$4:$B$2311,"UCO",Data!$C$4:$C$2311,"Chile",Data!$E$4:$E$2311,2020,Data!$F$4:$F$2311,8) -> 0.82056054 | J6: =SUMIFS(Data!$H$4:$H$2311,Data!$B$4:$B$2311,"UCO",Data!$C$4:$C$2311,"Chile",Data!$E$4:$E$2311,2020,Data!$F$4:$F$2311,9) -> 0.53997822 | K6: =SUMIFS(Data!$H$4:$H$2311,Data!$B$4:$B$2311,"UCO",Data!$C$4:$C$2311,"Chile",Data!$E$4:$E$2311,2020,Data!$F$4:$F$2311,10) -> 0.7439499 | L6: =SUMIFS(Data!$H$4:$H$2311,Data!$B$4:$B$2311,"UCO",Data!$C$4:$C$2311,"Chile",Data!$E$4:$E$2311,2020,Data!$F$4:$F$2311,11) -> 0.92790362 | M6: =SUMIFS(Data!$H$4:$H$2311,Data!$B$4:$B$2311,"UCO",Data!$C$4:$C$2311,"Chile",Data!$E$4:$E$2311,2020,Data!$F$4:$F$2311,12) -> 1.5952649 | N6: =SUM(B6:M6) -> 13.988302 | Q6: Nov | R6: =SUMIFS(Data!$H$4:$H$2311,Data!$B$4:$B$2311,"UCO",Data!$C$4:$C$2311,"World Total",Data!$E$4:$E$2311,2020,Data!$F$4:$F$2311,11) -> 16.037053 | S6: =SUMIFS(Data!$H$4:$H$2311,Data!$B$4:$B$2311,"UCO",Data!$C$4:$C$2311,"World Total",Data!$E$4:$E$2311,2021,Data!$F$4:$F$2311,11) -> 42.301646 | T6: =SUMIFS(Data!$H$4:$H$2311,Data!$B$4:$B$2311,"UCO",Data!$C$4:$C$2311,"World Total",Data!$E$4:$E$2311,2022,Data!$F$4:$F$2311,11) -> 102.39591 | U6: =SUMIFS(Data!$H$4:$H$2311,Data!$B$4:$B$2311,"UCO",Data!$C$4:$C$2311,"World Total",Data!$E$4:$E$2311,2023,Data!$F$4:$F$2311,11) -> 241.00435 | V6: =SUMIFS(Data!$H$4:$H$2311,Data!$B$4:$B$2311,"UCO",Data!$C$4:$C$2311,"World Total",Data!$E$4:$E$2311,2024,Data!$F$4:$F$2311,11) -> 612.5293 | W6: =SUMIFS(Data!$H$4:$H$2311,Data!$B$4:$B$2311,"UCO",Data!$C$4:$C$2311,"World Total",Data!$E$4:$E$2311,2025,Data!$F$4:$F$2311,11) -> 448.92207
A7: Mexico | B7: =SUMIFS(Data!$H$4:$H$2311,Data!$B$4:$B$2311,"UCO",Data!$C$4:$C$2311,"Mexico",Data!$E$4:$E$2311,2020,Data!$F$4:$F$2311,1) -> 0.48281235 | C7: =SUMIFS(Data!$H$4:$H$2311,Data!$B$4:$B$2311,"UCO",Data!$C$4:$C$2311,"Mexico",Data!$E$4:$E$2311,2020,Data!$F$4:$F$2311,2) -> 0.34015122 | D7: =SUMIFS(Data!$H$4:$H$2311,Data!$B$4:$B$2311,"UCO",Data!$C$4:$C$2311,"Mexico",Data!$E$4:$E$2311,2020,Data!$F$4:$F$2311,3) -> 0.50675456 | E7: =SUMIFS(Data!$H$4:$H$2311,Data!$B$4:$B$2311,"UCO",Data!$C$4:$C$2311,"Mexico",Data!$E$4:$E$2311,2020,Data!$F$4:$F$2311,4) -> 0.31989074 | F7: =SUMIFS(Data!$H$4:$H$2311,Data!$B$4:$B$2311,"UCO",Data!$C$4:$C$2311,"Mexico",Data!$E$4:$E$2311,2020,Data!$F$4:$F$2311,5) -> 0.17279832 | G7: =SUMIFS(Data!$H$4:$H$2311,Data!$B$4:$B$2311,"UCO",Data!$C$4:$C$2311,"Mexico",Data!$E$4:$E$2311,2020,Data!$F$4:$F$2311,6) -> 0.16111382 | H7: =SUMIFS(Data!$H$4:$H$2311,Data!$B$4:$B$2311,"UCO",Data!$C$4:$C$2311,"Mexico",Data!$E$4:$E$2311,2020,Data!$F$4:$F$2311,7) -> 0.51905635 | I7: =SUMIFS(Data!$H$4:$H$2311,Data!$B$4:$B$2311,"UCO",Data!$C$4:$C$2311,"Mexico",Data!$E$4:$E$2311,2020,Data!$F$4:$F$2311,8) -> 0.6905319 | J7: =SUMIFS(Data!$H$4:$H$2311,Data!$B$4:$B$2311,"UCO",Data!$C$4:$C$2311,"Mexico",Data!$E$4:$E$2311,2020,Data!$F$4:$F$2311,9) -> 0.17628383 | K7: =SUMIFS(Data!$H$4:$H$2311,Data!$B$4:$B$2311,"UCO",Data!$C$4:$C$2311,"Mexico",Data!$E$4:$E$2311,2020,Data!$F$4:$F$2311,10) -> 0.21792695 | L7: =SUMIFS(Data!$H$4:$H$2311,Data!$B$4:$B$2311,"UCO",Data!$C$4:$C$2311,"Mexico",Data!$E$4:$E$2311,2020,Data!$F$4:$F$2311,11) -> 0.67714984 | M7: =SUMIFS(Data!$H$4:$H$2311,Data!$B$4:$B$2311,"UCO",Data!$C$4:$C$2311,"Mexico",Data!$E$4:$E$2311,2020,Data!$F$4:$F$2311,12) -> 0.27068357 | N7: =SUM(B7:M7) -> 4.5351534 | Q7: Dec | R7: =SUMIFS(Data!$H$4:$H$2311,Data!$B$4:$B$2311,"UCO",Data!$C$4:$C$2311,"World Total",Data!$E$4:$E$2311,2020,Data!$F$4:$F$2311,12) -> 14.590991 | S7: =SUMIFS(Data!$H$4:$H$2311,Data!$B$4:$B$2311,"UCO",Data!$C$4:$C$2311,"World Total",Data!$E$4:$E$2311,2021,Data!$F$4:$F$2311,12) -> 27.701099 | T7: =SUMIFS(Data!$H$4:$H$2311,Data!$B$4:$B$2311,"UCO",Data!$C$4:$C$2311,"World Total",Data!$E$4:$E$2311,2022,Data!$F$4:$F$2311,12) -> 116.1182 | U7: =SUMIFS(Data!$H$4:$H$2311,Data!$B$4:$B$2311,"UCO",Data!$C$4:$C$2311,"World Total",Data!$E$4:$E$2311,2023,Data!$F$4:$F$2311,12) -> 392.99265 | V7: =SUMIFS(Data!$H$4:$H$2311,Data!$B$4:$B$2311,"UCO",Data!$C$4:$C$2311,"World Total",Data!$E$4:$E$2311,2024,Data!$F$4:$F$2311,12) -> 381.09339 | W7: =SUMIFS(Data!$H$4:$H$2311,Data!$B$4:$B$2311,"UCO",Data!$C$4:$C$2311,"World Total",Data!$E$4:$E$2311,2025,Data!$F$4:$F$2311,12) -> 395.60813
A8: Brazil | B8: =SUMIFS(Data!$H$4:$H$2311,Data!$B$4:$B$2311,"UCO",Data!$C$4:$C$2311,"Brazil",Data!$E$4:$E$2311,2020,Data!$F$4:$F$2311,1) -> 0.044092452 | C8: =SUMIFS(Data!$H$4:$H$2311,Data!$B$4:$B$2311,"UCO",Data!$C$4:$C$2311,"Brazil",Data!$E$4:$E$2311,2020,Data!$F$4:$F$2311,2) -> 0.077690901 | D8: =SUMIFS(Data!$H$4:$H$2311,Data!$B$4:$B$2311,"UCO",Data!$C$4:$C$2311,"Brazil",Data!$E$4:$E$2311,2020,Data!$F$4:$F$2311,3) -> 0.17636981 | E8: =SUMIFS(Data!$H$4:$H$2311,Data!$B$4:$B$2311,"UCO",Data!$C$4:$C$2311,"Brazil",Data!$E$4:$E$2311,2020,Data!$F$4:$F$2311,4) -> 0.10025962 | F8: =SUMIFS(Data!$H$4:$H$2311,Data!$B$4:$B$2311,"UCO",Data!$C$4:$C$2311,"Brazil",Data!$E$4:$E$2311,2020,Data!$F$4:$F$2311,5) -> 0.16587581 | G8: =SUMIFS(Data!$H$4:$H$2311,Data!$B$4:$B$2311,"UCO",Data!$C$4:$C$2311,"Brazil",Data!$E$4:$E$2311,2020,Data!$F$4:$F$2311,6) -> 0.13137346 | H8: =SUMIFS(Data!$H$4:$H$2311,Data!$B$4:$B$2311,"UCO",Data!$C$4:$C$2311,"Brazil",Data!$E$4:$E$2311,2020,Data!$F$4:$F$2311,7) -> 0.055858523 | I8: =SUMIFS(Data!$H$4:$H$2311,Data!$B$4:$B$2311,"UCO",Data!$C$4:$C$2311,"Brazil",Data!$E$4:$E$2311,2020,Data!$F$4:$F$2311,8) -> 0.10609967 | J8: =SUMIFS(Data!$H$4:$H$2311,Data!$B$4:$B$2311,"UCO",Data!$C$4:$C$2311,"Brazil",Data!$E$4:$E$2311,2020,Data!$F$4:$F$2311,9) -> 0.31001844 | K8: =SUMIFS(Data!$H$4:$H$2311,Data!$B$4:$B$2311,"UCO",Data!$C$4:$C$2311,"Brazil",Data!$E$4:$E$2311,2020,Data!$F$4:$F$2311,10) -> 0 | L8: =SUMIFS(Data!$H$4:$H$2311,Data!$B$4:$B$2311,"UCO",Data!$C$4:$C$2311,"Brazil",Data!$E$4:$E$2311,2020,Data!$F$4:$F$2311,11) -> 0.044370235 | M8: =SUMIFS(Data!$H$4:$H$2311,Data!$B$4:$B$2311,"UCO",Data!$C$4:$C$2311,"Brazil",Data!$E$4:$E$2311,2020,Data!$F$4:$F$2311,12) -> 0.077690901 | N8: =SUM(B8:M8) -> 1.2896998 | Q8: Jan | R8: =SUMIFS(Data!$H$4:$H$2311,Data!$B$4:$B$2311,"UCO",Data!$C$4:$C$2311,"World Total",Data!$E$4:$E$2311,2021,Data!$F$4:$F$2311,1) -> 16.636858 | S8: =SUMIFS(Data!$H$4:$H$2311,Data!$B$4:$B$2311,"UCO",Data!$C$4:$C$2311,"World Total",Data!$E$4:$E$2311,2022,Data!$F$4:$F$2311,1) -> 53.667486 | T8: =SUMIFS(Data!$H$4:$H$2311,Data!$B$4:$B$2311,"UCO",Data!$C$4:$C$2311,"World Total",Data!$E$4:$E$2311,2023,Data!$F$4:$F$2311,1) -> 140.08276 | U8: =SUMIFS(Data!$H$4:$H$2311,Data!$B$4:$B$2311,"UCO",Data!$C$4:$C$2311,"World Total",Data!$E$4:$E$2311,2024,Data!$F$4:$F$2311,1) -> 492.76875 | V8: =SUMIFS(Data!$H$4:$H$2311,Data!$B$4:$B$2311,"UCO",Data!$C$4:$C$2311,"World Total",Data!$E$4:$E$2311,2025,Data!$F$4:$F$2311,1) -> 605.53327 | W8: =SUMIFS(Data!$H$4:$H$2311,Data!$B$4:$B$2311,"UCO",Data!$C$4:$C$2311,"World Total",Data!$E$4:$E$2311,2026,Data!$F$4:$F$2311,1) -> 108.5921
A9: India | B9: =SUMIFS(Data!$H$4:$H$2311,Data!$B$4:$B$2311,"UCO",Data!$C$4:$C$2311,"India",Data!$E$4:$E$2311,2020,Data!$F$4:$F$2311,1) -> 0.053257069 | C9: =SUMIFS(Data!$H$4:$H$2311,Data!$B$4:$B$2311,"UCO",Data!$C$4:$C$2311,"India",Data!$E$4:$E$2311,2020,Data!$F$4:$F$2311,2) -> 0.083444966 | D9: =SUMIFS(Data!$H$4:$H$2311,Data!$B$4:$B$2311,"UCO",Data!$C$4:$C$2311,"India",Data!$E$4:$E$2311,2020,Data!$F$4:$F$2311,3) -> 0.11810825 | E9: =SUMIFS(Data!$H$4:$H$2311,Data!$B$4:$B$2311,"UCO",Data!$C$4:$C$2311,"India",Data!$E$4:$E$2311,2020,Data!$F$4:$F$2311,4) -> 0.036180062 | F9: =SUMIFS(Data!$H$4:$H$2311,Data!$B$4:$B$2311,"UCO",Data!$C$4:$C$2311,"India",Data!$E$4:$E$2311,2020,Data!$F$4:$F$2311,5) -> 0.037875417 | G9: =SUMIFS(Data!$H$4:$H$2311,Data!$B$4:$B$2311,"UCO",Data!$C$4:$C$2311,"India",Data!$E$4:$E$2311,2020,Data!$F$4:$F$2311,6) -> 0.03668492 | H9: =SUMIFS(Data!$H$4:$H$2311,Data!$B$4:$B$2311,"UCO",Data!$C$4:$C$2311,"India",Data!$E$4:$E$2311,2020,Data!$F$4:$F$2311,7) -> 0.069899765 | I9: =SUMIFS(Data!$H$4:$H$2311,Data!$B$4:$B$2311,"UCO",Data!$C$4:$C$2311,"India",Data!$E$4:$E$2311,2020,Data!$F$4:$F$2311,8) -> 0.019819557 | J9: =SUMIFS(Data!$H$4:$H$2311,Data!$B$4:$B$2311,"UCO",Data!$C$4:$C$2311,"India",Data!$E$4:$E$2311,2020,Data!$F$4:$F$2311,9) -> 0 | K9: =SUMIFS(Data!$H$4:$H$2311,Data!$B$4:$B$2311,"UCO",Data!$C$4:$C$2311,"India",Data!$E$4:$E$2311,2020,Data!$F$4:$F$2311,10) -> 0.098390103 | L9: =SUMIFS(Data!$H$4:$H$2311,Data!$B$4:$B$2311,"UCO",Data!$C$4:$C$2311,"India",Data!$E$4:$E$2311,2020,Data!$F$4:$F$2311,11) -> 0.11284581 | M9: =SUMIFS(Data!$H$4:$H$2311,Data!$B$4:$B$2311,"UCO",Data!$C$4:$C$2311,"India",Data!$E$4:$E$2311,2020,Data!$F$4:$F$2311,12) -> 0.16868229 | N9: =SUM(B9:M9) -> 0.83518821 | Q9: Feb | R9: =SUMIFS(Data!$H$4:$H$2311,Data!$B$4:$B$2311,"UCO",Data!$C$4:$C$2311,"World Total",Data!$E$4:$E$2311,2021,Data!$F$4:$F$2311,2) -> 18.960098 | S9: =SUMIFS(Data!$H$4:$H$2311,Data!$B$4:$B$2311,"UCO",Data!$C$4:$C$2311,"World Total",Data!$E$4:$E$2311,2022,Data!$F$4:$F$2311,2) -> 26.84455 | T9: =SUMIFS(Data!$H$4:$H$2311,Data!$B$4:$B$2311,"UCO",Data!$C$4:$C$2311,"World Total",Data!$E$4:$E$2311,2023,Data!$F$4:$F$2311,2) -> 204.01455 | U9: =SUMIFS(Data!$H$4:$H$2311,Data!$B$4:$B$2311,"UCO",Data!$C$4:$C$2311,"World Total",Data!$E$4:$E$2311,2024,Data!$F$4:$F$2311,2) -> 183.95752 | V9: =SUMIFS(Data!$H$4:$H$2311,Data!$B$4:$B$2311,"UCO",Data!$C$4:$C$2311,"World Total",Data!$E$4:$E$2311,2025,Data!$F$4:$F$2311,2) -> 455.01216 | W9: =SUMIFS(Data!$H$4:$H$2311,Data!$B$4:$B$2311,"UCO",Data!$C$4:$C$2311,"World Total",Data!$E$4:$E$2311,2026,Data!$F$4:$F$2311,2) -> 232.93503
A10: France | B10: =SUMIFS(Data!$H$4:$H$2311,Data!$B$4:$B$2311,"UCO",Data!$C$4:$C$2311,"France",Data!$E$4:$E$2311,2020,Data!$F$4:$F$2311,1) -> 0.014239658 | C10: =SUMIFS(Data!$H$4:$H$2311,Data!$B$4:$B$2311,"UCO",Data!$C$4:$C$2311,"France",Data!$E$4:$E$2311,2020,Data!$F$4:$F$2311,2) -> 0.064130267 | D10: =SUMIFS(Data!$H$4:$H$2311,Data!$B$4:$B$2311,"UCO",Data!$C$4:$C$2311,"France",Data!$E$4:$E$2311,2020,Data!$F$4:$F$2311,3) -> 0.086952521 | E10: =SUMIFS(Data!$H$4:$H$2311,Data!$B$4:$B$2311,"UCO",Data!$C$4:$C$2311,"France",Data!$E$4:$E$2311,2020,Data!$F$4:$F$2311,4) -> 0.20255411 | F10: =SUMIFS(Data!$H$4:$H$2311,Data!$B$4:$B$2311,"UCO",Data!$C$4:$C$2311,"France",Data!$E$4:$E$2311,2020,Data!$F$4:$F$2311,5) -> 0.04142045 | G10: =SUMIFS(Data!$H$4:$H$2311,Data!$B$4:$B$2311,"UCO",Data!$C$4:$C$2311,"France",Data!$E$4:$E$2311,2020,Data!$F$4:$F$2311,6) -> 0.029760201 | H10: =SUMIFS(Data!$H$4:$H$2311,Data!$B$4:$B$2311,"UCO",Data!$C$4:$C$2311,"France",Data!$E$4:$E$2311,2020,Data!$F$4:$F$2311,7) -> 0.016876386 | I10: =SUMIFS(Data!$H$4:$H$2311,Data!$B$4:$B$2311,"UCO",Data!$C$4:$C$2311,"France",Data!$E$4:$E$2311,2020,Data!$F$4:$F$2311,8) -> 0.031642948 | J10: =SUMIFS(Data!$H$4:$H$2311,Data!$B$4:$B$2311,"UCO",Data!$C$4:$C$2311,"France",Data!$E$4:$E$2311,2020,Data!$F$4:$F$2311,9) -> 0.0025441345 | K10: =SUMIFS(Data!$H$4:$H$2311,Data!$B$4:$B$2311,"UCO",Data!$C$4:$C$2311,"France",Data!$E$4:$E$2311,2020,Data!$F$4:$F$2311,10) -> 0.01255753 | L10: =SUMIFS(Data!$H$4:$H$2311,Data!$B$4:$B$2311,"UCO",Data!$C$4:$C$2311,"France",Data!$E$4:$E$2311,2020,Data!$F$4:$F$2311,11) -> 0.02184781 | M10: =SUMIFS(Data!$H$4:$H$2311,Data!$B$4:$B$2311,"UCO",Data!$C$4:$C$2311,"France",Data!$E$4:$E$2311,2020,Data!$F$4:$F$2311,12) -> 0.034325974 | N10: =SUM(B10:M10) -> 0.55885199 | Q10: Mar | R10: =SUMIFS(Data!$H$4:$H$2311,Data!$B$4:$B$2311,"UCO",Data!$C$4:$C$2311,"World Total",Data!$E$4:$E$2311,2021,Data!$F$4:$F$2311,3) -> 28.003119 | S10: =SUMIFS(Data!$H$4:$H$2311,Data!$B$4:$B$2311,"UCO",Data!$C$4:$C$2311,"World Total",Data!$E$4:$E$2311,2022,Data!$F$4:$F$2311,3) -> 48.099771 | T10: =SUMIFS(Data!$H$4:$H$2311,Data!$B$4:$B$2311,"UCO",Data!$C$4:$C$2311,"World Total",Data!$E$4:$E$2311,2023,Data!$F$4:$F$2311,3) -> 226.36359 | U10: =SUMIFS(Data!$H$4:$H$2311,Data!$B$4:$B$2311,"UCO",Data!$C$4:$C$2311,"World Total",Data!$E$4:$E$2311,2024,Data!$F$4:$F$2311,3) -> 634.56054 | V10: =SUMIFS(Data!$H$4:$H$2311,Data!$B$4:$B$2311,"UCO",Data!$C$4:$C$2311,"World Total",Data!$E$4:$E$2311,2025,Data!$F$4:$F$2311,3) -> 509.65149 | W10: =SUMIFS(Data!$H$4:$H$2311,Data!$B$4:$B$2311,"UCO",Data!$C$4:$C$2311,"World Total",Data!$E$4:$E$2311,2026,Data!$F$4:$F$2311,3) -> 173.02581
A11: Aruba | B11: =SUMIFS(Data!$H$4:$H$2311,Data!$B$4:$B$2311,"UCO",Data!$C$4:$C$2311,"Aruba",Data!$E$4:$E$2311,2020,Data!$F$4:$F$2311,1) -> 0.048501698 | C11: =SUMIFS(Data!$H$4:$H$2311,Data!$B$4:$B$2311,"UCO",Data!$C$4:$C$2311,"Aruba",Data!$E$4:$E$2311,2020,Data!$F$4:$F$2311,2) -> 0.048501698 | D11: =SUMIFS(Data!$H$4:$H$2311,Data!$B$4:$B$2311,"UCO",Data!$C$4:$C$2311,"Aruba",Data!$E$4:$E$2311,2020,Data!$F$4:$F$2311,3) -> 0.050000841 | E11: =SUMIFS(Data!$H$4:$H$2311,Data!$B$4:$B$2311,"UCO",Data!$C$4:$C$2311,"Aruba",Data!$E$4:$E$2311,2020,Data!$F$4:$F$2311,4) -> 0 | F11: =SUMIFS(Data!$H$4:$H$2311,Data!$B$4:$B$2311,"UCO",Data!$C$4:$C$2311,"Aruba",Data!$E$4:$E$2311,2020,Data!$F$4:$F$2311,5) -> 0 | G11: =SUMIFS(Data!$H$4:$H$2311,Data!$B$4:$B$2311,"UCO",Data!$C$4:$C$2311,"Aruba",Data!$E$4:$E$2311,2020,Data!$F$4:$F$2311,6) -> 0 | H11: =SUMIFS(Data!$H$4:$H$2311,Data!$B$4:$B$2311,"UCO",Data!$C$4:$C$2311,"Aruba",Data!$E$4:$E$2311,2020,Data!$F$4:$F$2311,7) -> 0 | I11: =SUMIFS(Data!$H$4:$H$2311,Data!$B$4:$B$2311,"UCO",Data!$C$4:$C$2311,"Aruba",Data!$E$4:$E$2311,2020,Data!$F$4:$F$2311,8) -> 0 | J11: =SUMIFS(Data!$H$4:$H$2311,Data!$B$4:$B$2311,"UCO",Data!$C$4:$C$2311,"Aruba",Data!$E$4:$E$2311,2020,Data!$F$4:$F$2311,9) -> 0 | K11: =SUMIFS(Data!$H$4:$H$2311,Data!$B$4:$B$2311,"UCO",Data!$C$4:$C$2311,"Aruba",Data!$E$4:$E$2311,2020,Data!$F$4:$F$2311,10) -> 0 | L11: =SUMIFS(Data!$H$4:$H$2311,Data!$B$4:$B$2311,"UCO",Data!$C$4:$C$2311,"Aruba",Data!$E$4:$E$2311,2020,Data!$F$4:$F$2311,11) -> 0.048678067 | M11: =SUMIFS(Data!$H$4:$H$2311,Data!$B$4:$B$2311,"UCO",Data!$C$4:$C$2311,"Aruba",Data!$E$4:$E$2311,2020,Data!$F$4:$F$2311,12) -> 0.098634816 | N11: =SUM(B11:M11) -> 0.29431712 | Q11: Apr | R11: =SUMIFS(Data!$H$4:$H$2311,Data!$B$4:$B$2311,"UCO",Data!$C$4:$C$2311,"World Total",Data!$E$4:$E$2311,2021,Data!$F$4:$F$2311,4) -> 19.755196 | S11: =SUMIFS(Data!$H$4:$H$2311,Data!$B$4:$B$2311,"UCO",Data!$C$4:$C$2311,"World Total",Data!$E$4:$E$2311,2022,Data!$F$4:$F$2311,4) -> 44.964096 | T11: =SUMIFS(Data!$H$4:$H$2311,Data!$B$4:$B$2311,"UCO",Data!$C$4:$C$2311,"World Total",Data!$E$4:$E$2311,2023,Data!$F$4:$F$2311,4) -> 136.87119 | U11: =SUMIFS(Data!$H$4:$H$2311,Data!$B$4:$B$2311,"UCO",Data!$C$4:$C$2311,"World Total",Data!$E$4:$E$2311,2024,Data!$F$4:$F$2311,4) -> 274.41585 | V11: =SUMIFS(Data!$H$4:$H$2311,Data!$B$4:$B$2311,"UCO",Data!$C$4:$C$2311,"World Total",Data!$E$4:$E$2311,2025,Data!$F$4:$F$2311,4) -> 213.54033 | W11: =SUMIFS(Data!$H$4:$H$2311,Data!$B$4:$B$2311,"UCO",Data!$C$4:$C$2311,"World Total",Data!$E$4:$E$2311,2026,Data!$F$4:$F$2311,4) -> 230.18706
A12: China | B12: =SUMIFS(Data!$H$4:$H$2311,Data!$B$4:$B$2311,"UCO",Data!$C$4:$C$2311,"China",Data!$E$4:$E$2311,2020,Data!$F$4:$F$2311,1) -> 0.094049201 | C12: =SUMIFS(Data!$H$4:$H$2311,Data!$B$4:$B$2311,"UCO",Data!$C$4:$C$2311,"China",Data!$E$4:$E$2311,2020,Data!$F$4:$F$2311,2) -> 0.046693907 | D12: =SUMIFS(Data!$H$4:$H$2311,Data!$B$4:$B$2311,"UCO",Data!$C$4:$C$2311,"China",Data!$E$4:$E$2311,2020,Data!$F$4:$F$2311,3) -> 0 | E12: =SUMIFS(Data!$H$4:$H$2311,Data!$B$4:$B$2311,"UCO",Data!$C$4:$C$2311,"China",Data!$E$4:$E$2311,2020,Data!$F$4:$F$2311,4) -> 0 | F12: =SUMIFS(Data!$H$4:$H$2311,Data!$B$4:$B$2311,"UCO",Data!$C$4:$C$2311,"China",Data!$E$4:$E$2311,2020,Data!$F$4:$F$2311,5) -> 0 | G12: =SUMIFS(Data!$H$4:$H$2311,Data!$B$4:$B$2311,"UCO",Data!$C$4:$C$2311,"China",Data!$E$4:$E$2311,2020,Data!$F$4:$F$2311,6) -> 0.035273962 | H12: =SUMIFS(Data!$H$4:$H$2311,Data!$B$4:$B$2311,"UCO",Data!$C$4:$C$2311,"China",Data!$E$4:$E$2311,2020,Data!$F$4:$F$2311,7) -> 0.015648411 | I12: =SUMIFS(Data!$H$4:$H$2311,Data!$B$4:$B$2311,"UCO",Data!$C$4:$C$2311,"China",Data!$E$4:$E$2311,2020,Data!$F$4:$F$2311,8) -> 0 | J12: =SUMIFS(Data!$H$4:$H$2311,Data!$B$4:$B$2311,"UCO",Data!$C$4:$C$2311,"China",Data!$E$4:$E$2311,2020,Data!$F$4:$F$2311,9) -> 0.024072274 | K12: =SUMIFS(Data!$H$4:$H$2311,Data!$B$4:$B$2311,"UCO",Data!$C$4:$C$2311,"China",Data!$E$4:$E$2311,2020,Data!$F$4:$F$2311,10) -> 0 | L12: =SUMIFS(Data!$H$4:$H$2311,Data!$B$4:$B$2311,"UCO",Data!$C$4:$C$2311,"China",Data!$E$4:$E$2311,2020,Data!$F$4:$F$2311,11) -> 0 | M12: =SUMIFS(Data!$H$4:$H$2311,Data!$B$4:$B$2311,"UCO",Data!$C$4:$C$2311,"China",Data!$E$4:$E$2311,2020,Data!$F$4:$F$2311,12) -> 0.017636981 | N12: =SUM(B12:M12) -> 0.23337474 | Q12: May | R12: =SUMIFS(Data!$H$4:$H$2311,Data!$B$4:$B$2311,"UCO",Data!$C$4:$C$2311,"World Total",Data!$E$4:$E$2311,2021,Data!$F$4:$F$2311,5) -> 23.516207 | S12: =SUMIFS(Data!$H$4:$H$2311,Data!$B$4:$B$2311,"UCO",Data!$C$4:$C$2311,"World Total",Data!$E$4:$E$2311,2022,Data!$F$4:$F$2311,5) -> 62.582611 | T12: =SUMIFS(Data!$H$4:$H$2311,Data!$B$4:$B$2311,"UCO",Data!$C$4:$C$2311,"World Total",Data!$E$4:$E$2311,2023,Data!$F$4:$F$2311,5) -> 272.9667 | U12: =SUMIFS(Data!$H$4:$H$2311,Data!$B$4:$B$2311,"UCO",Data!$C$4:$C$2311,"World Total",Data!$E$4:$E$2311,2024,Data!$F$4:$F$2311,5) -> 307.47081 | V12: =SUMIFS(Data!$H$4:$H$2311,Data!$B$4:$B$2311,"UCO",Data!$C$4:$C$2311,"World Total",Data!$E$4:$E$2311,2025,Data!$F$4:$F$2311,5) -> 468.51399 | W12: =SUMIFS(Data!$H$4:$H$2311,Data!$B$4:$B$2311,"UCO",Data!$C$4:$C$2311,"World Total",Data!$E$4:$E$2311,2026,Data!$F$4:$F$2311,5) -> 318.22968
A13: Germany | B13: =SUMIFS(Data!$H$4:$H$2311,Data!$B$4:$B$2311,"UCO",Data!$C$4:$C$2311,"Germany",Data!$E$4:$E$2311,2020,Data!$F$4:$F$2311,1) -> 7.4957169e-05 | C13: =SUMIFS(Data!$H$4:$H$2311,Data!$B$4:$B$2311,"UCO",Data!$C$4:$C$2311,"Germany",Data!$E$4:$E$2311,2020,Data!$F$4:$F$2311,2) -> 0.0076390174 | D13: =SUMIFS(Data!$H$4:$H$2311,Data!$B$4:$B$2311,"UCO",Data!$C$4:$C$2311,"Germany",Data!$E$4:$E$2311,2020,Data!$F$4:$F$2311,3) -> 0.008359929 | E13: =SUMIFS(Data!$H$4:$H$2311,Data!$B$4:$B$2311,"UCO",Data!$C$4:$C$2311,"Germany",Data!$E$4:$E$2311,2020,Data!$F$4:$F$2311,4) -> 9.259415e-05 | F13: =SUMIFS(Data!$H$4:$H$2311,Data!$B$4:$B$2311,"UCO",Data!$C$4:$C$2311,"Germany",Data!$E$4:$E$2311,2020,Data!$F$4:$F$2311,5) -> 0.0018584969 | G13: =SUMIFS(Data!$H$4:$H$2311,Data!$B$4:$B$2311,"UCO",Data!$C$4:$C$2311,"Germany",Data!$E$4:$E$2311,2020,Data!$F$4:$F$2311,6) -> 0.014764358 | H13: =SUMIFS(Data!$H$4:$H$2311,Data!$B$4:$B$2311,"UCO",Data!$C$4:$C$2311,"Germany",Data!$E$4:$E$2311,2020,Data!$F$4:$F$2311,7) -> 0.0036530597 | I13: =SUMIFS(Data!$H$4:$H$2311,Data!$B$4:$B$2311,"UCO",Data!$C$4:$C$2311,"Germany",Data!$E$4:$E$2311,2020,Data!$F$4:$F$2311,8) -> 0.0067836238 | J13: =SUMIFS(Data!$H$4:$H$2311,Data!$B$4:$B$2311,"UCO",Data!$C$4:$C$2311,"Germany",Data!$E$4:$E$2311,2020,Data!$F$4:$F$2311,9) -> 0.12974204 | K13: =SUMIFS(Data!$H$4:$H$2311,Data!$B$4:$B$2311,"UCO",Data!$C$4:$C$2311,"Germany",Data!$E$4:$E$2311,2020,Data!$F$4:$F$2311,10) -> 0.01209456 | L13: =SUMIFS(Data!$H$4:$H$2311,Data!$B$4:$B$2311,"UCO",Data!$C$4:$C$2311,"Germany",Data!$E$4:$E$2311,2020,Data!$F$4:$F$2311,11) -> 0.016378141 | M13: =SUMIFS(Data!$H$4:$H$2311,Data!$B$4:$B$2311,"UCO",Data!$C$4:$C$2311,"Germany",Data!$E$4:$E$2311,2020,Data!$F$4:$F$2311,12) -> 0.0062236497 | N13: =SUM(B13:M13) -> 0.20766443 | Q13: Jun | R13: =SUMIFS(Data!$H$4:$H$2311,Data!$B$4:$B$2311,"UCO",Data!$C$4:$C$2311,"World Total",Data!$E$4:$E$2311,2021,Data!$F$4:$F$2311,6) -> 18.141416 | S13: =SUMIFS(Data!$H$4:$H$2311,Data!$B$4:$B$2311,"UCO",Data!$C$4:$C$2311,"World Total",Data!$E$4:$E$2311,2022,Data!$F$4:$F$2311,6) -> 80.114169 | T13: =SUMIFS(Data!$H$4:$H$2311,Data!$B$4:$B$2311,"UCO",Data!$C$4:$C$2311,"World Total",Data!$E$4:$E$2311,2023,Data!$F$4:$F$2311,6) -> 205.2553 | U13: =SUMIFS(Data!$H$4:$H$2311,Data!$B$4:$B$2311,"UCO",Data!$C$4:$C$2311,"World Total",Data!$E$4:$E$2311,2024,Data!$F$4:$F$2311,6) -> 370.33968 | V13: =SUMIFS(Data!$H$4:$H$2311,Data!$B$4:$B$2311,"UCO",Data!$C$4:$C$2311,"World Total",Data!$E$4:$E$2311,2025,Data!$F$4:$F$2311,6) -> 206.36043 | W13: =SUMIFS(Data!$H$4:$H$2311,Data!$B$4:$B$2311,"UCO",Data!$C$4:$C$2311,"World Total",Data!$E$4:$E$2311,2026,Data!$F$4:$F$2311,6) -> 406.81571
A14: Netherlands | B14: =SUMIFS(Data!$H$4:$H$2311,Data!$B$4:$B$2311,"UCO",Data!$C$4:$C$2311,"Netherlands",Data!$E$4:$E$2311,2020,Data!$F$4:$F$2311,1) -> 0.08377566 | C14: =SUMIFS(Data!$H$4:$H$2311,Data!$B$4:$B$2311,"UCO",Data!$C$4:$C$2311,"Netherlands",Data!$E$4:$E$2311,2020,Data!$F$4:$F$2311,2) -> 0 | D14: =SUMIFS(Data!$H$4:$H$2311,Data!$B$4:$B$2311,"UCO",Data!$C$4:$C$2311,"Netherlands",Data!$E$4:$E$2311,2020,Data!$F$4:$F$2311,3) -> 0 | E14: =SUMIFS(Data!$H$4:$H$2311,Data!$B$4:$B$2311,"UCO",Data!$C$4:$C$2311,"Netherlands",Data!$E$4:$E$2311,2020,Data!$F$4:$F$2311,4) -> 0 | F14: =SUMIFS(Data!$H$4:$H$2311,Data!$B$4:$B$2311,"UCO",Data!$C$4:$C$2311,"Netherlands",Data!$E$4:$E$2311,2020,Data!$F$4:$F$2311,5) -> 0 | G14: =SUMIFS(Data!$H$4:$H$2311,Data!$B$4:$B$2311,"UCO",Data!$C$4:$C$2311,"Netherlands",Data!$E$4:$E$2311,2020,Data!$F$4:$F$2311,6) -> 0 | H14: =SUMIFS(Data!$H$4:$H$2311,Data!$B$4:$B$2311,"UCO",Data!$C$4:$C$2311,"Netherlands",Data!$E$4:$E$2311,2020,Data!$F$4:$F$2311,7) -> 0 | I14: =SUMIFS(Data!$H$4:$H$2311,Data!$B$4:$B$2311,"UCO",Data!$C$4:$C$2311,"Netherlands",Data!$E$4:$E$2311,2020,Data!$F$4:$F$2311,8) -> 0 | J14: =SUMIFS(Data!$H$4:$H$2311,Data!$B$4:$B$2311,"UCO",Data!$C$4:$C$2311,"Netherlands",Data!$E$4:$E$2311,2020,Data!$F$4:$F$2311,9) -> 0 | K14: =SUMIFS(Data!$H$4:$H$2311,Data!$B$4:$B$2311,"UCO",Data!$C$4:$C$2311,"Netherlands",Data!$E$4:$E$2311,2020,Data!$F$4:$F$2311,10) -> 0 | L14: =SUMIFS(Data!$H$4:$H$2311,Data!$B$4:$B$2311,"UCO",Data!$C$4:$C$2311,"Netherlands",Data!$E$4:$E$2311,2020,Data!$F$4:$F$2311,11) -> 0 | M14: =SUMIFS(Data!$H$4:$H$2311,Data!$B$4:$B$2311,"UCO",Data!$C$4:$C$2311,"Netherlands",Data!$E$4:$E$2311,2020,Data!$F$4:$F$2311,12) -> 0.08377566 | N14: =SUM(B14:M14) -> 0.16755132 | Q14: Jul | R14: =SUMIFS(Data!$H$4:$H$2311,Data!$B$4:$B$2311,"UCO",Data!$C$4:$C$2311,"World Total",Data!$E$4:$E$2311,2021,Data!$F$4:$F$2311,7) -> 19.58109 | S14: =SUMIFS(Data!$H$4:$H$2311,Data!$B$4:$B$2311,"UCO",Data!$C$4:$C$2311,"World Total",Data!$E$4:$E$2311,2022,Data!$F$4:$F$2311,7) -> 51.014798 | T14: =SUMIFS(Data!$H$4:$H$2311,Data!$B$4:$B$2311,"UCO",Data!$C$4:$C$2311,"World Total",Data!$E$4:$E$2311,2023,Data!$F$4:$F$2311,7) -> 122.48136 | U14: =SUMIFS(Data!$H$4:$H$2311,Data!$B$4:$B$2311,"UCO",Data!$C$4:$C$2311,"World Total",Data!$E$4:$E$2311,2024,Data!$F$4:$F$2311,7) -> 436.63989 | V14: =SUMIFS(Data!$H$4:$H$2311,Data!$B$4:$B$2311,"UCO",Data!$C$4:$C$2311,"World Total",Data!$E$4:$E$2311,2025,Data!$F$4:$F$2311,7) -> 443.719 | W14: =SUMIFS(Data!$H$4:$H$2311,Data!$B$4:$B$2311,"UCO",Data!$C$4:$C$2311,"World Total",Data!$E$4:$E$2311,2026,Data!$F$4:$F$2311,7) -> 746.0067
A15: Peru | B15: =SUMIFS(Data!$H$4:$H$2311,Data!$B$4:$B$2311,"UCO",Data!$C$4:$C$2311,"Peru",Data!$E$4:$E$2311,2020,Data!$F$4:$F$2311,1) -> 0.13957466 | C15: =SUMIFS(Data!$H$4:$H$2311,Data!$B$4:$B$2311,"UCO",Data!$C$4:$C$2311,"Peru",Data!$E$4:$E$2311,2020,Data!$F$4:$F$2311,2) -> 0 | D15: =SUMIFS(Data!$H$4:$H$2311,Data!$B$4:$B$2311,"UCO",Data!$C$4:$C$2311,"Peru",Data!$E$4:$E$2311,2020,Data!$F$4:$F$2311,3) -> 0 | E15: =SUMIFS(Data!$H$4:$H$2311,Data!$B$4:$B$2311,"UCO",Data!$C$4:$C$2311,"Peru",Data!$E$4:$E$2311,2020,Data!$F$4:$F$2311,4) -> 0 | F15: =SUMIFS(Data!$H$4:$H$2311,Data!$B$4:$B$2311,"UCO",Data!$C$4:$C$2311,"Peru",Data!$E$4:$E$2311,2020,Data!$F$4:$F$2311,5) -> 0 | G15: =SUMIFS(Data!$H$4:$H$2311,Data!$B$4:$B$2311,"UCO",Data!$C$4:$C$2311,"Peru",Data!$E$4:$E$2311,2020,Data!$F$4:$F$2311,6) -> 0 | H15: =SUMIFS(Data!$H$4:$H$2311,Data!$B$4:$B$2311,"UCO",Data!$C$4:$C$2311,"Peru",Data!$E$4:$E$2311,2020,Data!$F$4:$F$2311,7) -> 0 | I15: =SUMIFS(Data!$H$4:$H$2311,Data!$B$4:$B$2311,"UCO",Data!$C$4:$C$2311,"Peru",Data!$E$4:$E$2311,2020,Data!$F$4:$F$2311,8) -> 0 | J15: =SUMIFS(Data!$H$4:$H$2311,Data!$B$4:$B$2311,"UCO",Data!$C$4:$C$2311,"Peru",Data!$E$4:$E$2311,2020,Data!$F$4:$F$2311,9) -> 0 | K15: =SUMIFS(Data!$H$4:$H$2311,Data!$B$4:$B$2311,"UCO",Data!$C$4:$C$2311,"Peru",Data!$E$4:$E$2311,2020,Data!$F$4:$F$2311,10) -> 0 | L15: =SUMIFS(Data!$H$4:$H$2311,Data!$B$4:$B$2311,"UCO",Data!$C$4:$C$2311,"Peru",Data!$E$4:$E$2311,2020,Data!$F$4:$F$2311,11) -> 0 | M15: =SUMIFS(Data!$H$4:$H$2311,Data!$B$4:$B$2311,"UCO",Data!$C$4:$C$2311,"Peru",Data!$E$4:$E$2311,2020,Data!$F$4:$F$2311,12) -> 0 | N15: =SUM(B15:M15) -> 0.13957466 | Q15: Aug | R15: =SUMIFS(Data!$H$4:$H$2311,Data!$B$4:$B$2311,"UCO",Data!$C$4:$C$2311,"World Total",Data!$E$4:$E$2311,2021,Data!$F$4:$F$2311,8) -> 21.50892 | S15: =SUMIFS(Data!$H$4:$H$2311,Data!$B$4:$B$2311,"UCO",Data!$C$4:$C$2311,"World Total",Data!$E$4:$E$2311,2022,Data!$F$4:$F$2311,8) -> 108.40624 | T15: =SUMIFS(Data!$H$4:$H$2311,Data!$B$4:$B$2311,"UCO",Data!$C$4:$C$2311,"World Total",Data!$E$4:$E$2311,2023,Data!$F$4:$F$2311,8) -> 286.87084 | U15: =SUMIFS(Data!$H$4:$H$2311,Data!$B$4:$B$2311,"UCO",Data!$C$4:$C$2311,"World Total",Data!$E$4:$E$2311,2024,Data!$F$4:$F$2311,8) -> 540.75592 | V15: =SUMIFS(Data!$H$4:$H$2311,Data!$B$4:$B$2311,"UCO",Data!$C$4:$C$2311,"World Total",Data!$E$4:$E$2311,2025,Data!$F$4:$F$2311,8) -> 361.87405 | W15: =SUMIFS(Data!$H$4:$H$2311,Data!$B$4:$B$2311,"UCO",Data!$C$4:$C$2311,"World Total",Data!$E$4:$E$2311,2026,Data!$F$4:$F$2311,8) -> 586.76043
A16: Malaysia | B16: =SUMIFS(Data!$H$4:$H$2311,Data!$B$4:$B$2311,"UCO",Data!$C$4:$C$2311,"Malaysia",Data!$E$4:$E$2311,2020,Data!$F$4:$F$2311,1) -> 0 | C16: =SUMIFS(Data!$H$4:$H$2311,Data!$B$4:$B$2311,"UCO",Data!$C$4:$C$2311,"Malaysia",Data!$E$4:$E$2311,2020,Data!$F$4:$F$2311,2) -> 0 | D16: =SUMIFS(Data!$H$4:$H$2311,Data!$B$4:$B$2311,"UCO",Data!$C$4:$C$2311,"Malaysia",Data!$E$4:$E$2311,2020,Data!$F$4:$F$2311,3) -> 0 | E16: =SUMIFS(Data!$H$4:$H$2311,Data!$B$4:$B$2311,"UCO",Data!$C$4:$C$2311,"Malaysia",Data!$E$4:$E$2311,2020,Data!$F$4:$F$2311,4) -> 0 | F16: =SUMIFS(Data!$H$4:$H$2311,Data!$B$4:$B$2311,"UCO",Data!$C$4:$C$2311,"Malaysia",Data!$E$4:$E$2311,2020,Data!$F$4:$F$2311,5) -> 0 | G16: =SUMIFS(Data!$H$4:$H$2311,Data!$B$4:$B$2311,"UCO",Data!$C$4:$C$2311,"Malaysia",Data!$E$4:$E$2311,2020,Data!$F$4:$F$2311,6) -> 0 | H16: =SUMIFS(Data!$H$4:$H$2311,Data!$B$4:$B$2311,"UCO",Data!$C$4:$C$2311,"Malaysia",Data!$E$4:$E$2311,2020,Data!$F$4:$F$2311,7) -> 0 | I16: =SUMIFS(Data!$H$4:$H$2311,Data!$B$4:$B$2311,"UCO",Data!$C$4:$C$2311,"Malaysia",Data!$E$4:$E$2311,2020,Data!$F$4:$F$2311,8) -> 0 | J16: =SUMIFS(Data!$H$4:$H$2311,Data!$B$4:$B$2311,"UCO",Data!$C$4:$C$2311,"Malaysia",Data!$E$4:$E$2311,2020,Data!$F$4:$F$2311,9) -> 0.046076613 | K16: =SUMIFS(Data!$H$4:$H$2311,Data!$B$4:$B$2311,"UCO",Data!$C$4:$C$2311,"Malaysia",Data!$E$4:$E$2311,2020,Data!$F$4:$F$2311,10) -> 0 | L16: =SUMIFS(Data!$H$4:$H$2311,Data!$B$4:$B$2311,"UCO",Data!$C$4:$C$2311,"Malaysia",Data!$E$4:$E$2311,2020,Data!$F$4:$F$2311,11) -> 0 | M16: =SUMIFS(Data!$H$4:$H$2311,Data!$B$4:$B$2311,"UCO",Data!$C$4:$C$2311,"Malaysia",Data!$E$4:$E$2311,2020,Data!$F$4:$F$2311,12) -> 0 | N16: =SUM(B16:M16) -> 0.046076613 | Q16: Sep | R16: =SUMIFS(Data!$H$4:$H$2311,Data!$B$4:$B$2311,"UCO",Data!$C$4:$C$2311,"World Total",Data!$E$4:$E$2311,2021,Data!$F$4:$F$2311,9) -> 17.574967 | S16: =SUMIFS(Data!$H$4:$H$2311,Data!$B$4:$B$2311,"UCO",Data!$C$4:$C$2311,"World Total",Data!$E$4:$E$2311,2022,Data!$F$4:$F$2311,9) -> 38.343138 | T16: =SUMIFS(Data!$H$4:$H$2311,Data!$B$4:$B$2311,"UCO",Data!$C$4:$C$2311,"World Total",Data!$E$4:$E$2311,2023,Data!$F$4:$F$2311,9) -> 382.93074 | U16: =SUMIFS(Data!$H$4:$H$2311,Data!$B$4:$B$2311,"UCO",Data!$C$4:$C$2311,"World Total",Data!$E$4:$E$2311,2024,Data!$F$4:$F$2311,9) -> 691.84099 | V16: =SUMIFS(Data!$H$4:$H$2311,Data!$B$4:$B$2311,"UCO",Data!$C$4:$C$2311,"World Total",Data!$E$4:$E$2311,2025,Data!$F$4:$F$2311,9) -> 388.75448
A17: Japan | B17: =SUMIFS(Data!$H$4:$H$2311,Data!$B$4:$B$2311,"UCO",Data!$C$4:$C$2311,"Japan",Data!$E$4:$E$2311,2020,Data!$F$4:$F$2311,1) -> 0.0063493132 | C17: =SUMIFS(Data!$H$4:$H$2311,Data!$B$4:$B$2311,"UCO",Data!$C$4:$C$2311,"Japan",Data!$E$4:$E$2311,2020,Data!$F$4:$F$2311,2) -> 0.0026455471 | D17: =SUMIFS(Data!$H$4:$H$2311,Data!$B$4:$B$2311,"UCO",Data!$C$4:$C$2311,"Japan",Data!$E$4:$E$2311,2020,Data!$F$4:$F$2311,3) -> 0.005555649 | E17: =SUMIFS(Data!$H$4:$H$2311,Data!$B$4:$B$2311,"UCO",Data!$C$4:$C$2311,"Japan",Data!$E$4:$E$2311,2020,Data!$F$4:$F$2311,4) -> 0 | F17: =SUMIFS(Data!$H$4:$H$2311,Data!$B$4:$B$2311,"UCO",Data!$C$4:$C$2311,"Japan",Data!$E$4:$E$2311,2020,Data!$F$4:$F$2311,5) -> 0.0037919509 | G17: =SUMIFS(Data!$H$4:$H$2311,Data!$B$4:$B$2311,"UCO",Data!$C$4:$C$2311,"Japan",Data!$E$4:$E$2311,2020,Data!$F$4:$F$2311,6) -> 0.0022046226 | H17: =SUMIFS(Data!$H$4:$H$2311,Data!$B$4:$B$2311,"UCO",Data!$C$4:$C$2311,"Japan",Data!$E$4:$E$2311,2020,Data!$F$4:$F$2311,7) -> 0 | I17: =SUMIFS(Data!$H$4:$H$2311,Data!$B$4:$B$2311,"UCO",Data!$C$4:$C$2311,"Japan",Data!$E$4:$E$2311,2020,Data!$F$4:$F$2311,8) -> 0.0024691773 | J17: =SUMIFS(Data!$H$4:$H$2311,Data!$B$4:$B$2311,"UCO",Data!$C$4:$C$2311,"Japan",Data!$E$4:$E$2311,2020,Data!$F$4:$F$2311,9) -> 0.0026455471 | K17: =SUMIFS(Data!$H$4:$H$2311,Data!$B$4:$B$2311,"UCO",Data!$C$4:$C$2311,"Japan",Data!$E$4:$E$2311,2020,Data!$F$4:$F$2311,10) -> 0.0055336028 | L17: =SUMIFS(Data!$H$4:$H$2311,Data!$B$4:$B$2311,"UCO",Data!$C$4:$C$2311,"Japan",Data!$E$4:$E$2311,2020,Data!$F$4:$F$2311,11) -> 0.00087303056 | M17: =SUMIFS(Data!$H$4:$H$2311,Data!$B$4:$B$2311,"UCO",Data!$C$4:$C$2311,"Japan",Data!$E$4:$E$2311,2020,Data!$F$4:$F$2311,12) -> 0.010132446 | N17: =SUM(B17:M17) -> 0.042200886
A18: Argentina | B18: =SUMIFS(Data!$H$4:$H$2311,Data!$B$4:$B$2311,"UCO",Data!$C$4:$C$2311,"Argentina",Data!$E$4:$E$2311,2020,Data!$F$4:$F$2311,1) -> 0 | C18: =SUMIFS(Data!$H$4:$H$2311,Data!$B$4:$B$2311,"UCO",Data!$C$4:$C$2311,"Argentina",Data!$E$4:$E$2311,2020,Data!$F$4:$F$2311,2) -> 0 | D18: =SUMIFS(Data!$H$4:$H$2311,Data!$B$4:$B$2311,"UCO",Data!$C$4:$C$2311,"Argentina",Data!$E$4:$E$2311,2020,Data!$F$4:$F$2311,3) -> 0 | E18: =SUMIFS(Data!$H$4:$H$2311,Data!$B$4:$B$2311,"UCO",Data!$C$4:$C$2311,"Argentina",Data!$E$4:$E$2311,2020,Data!$F$4:$F$2311,4) -> 0 | F18: =SUMIFS(Data!$H$4:$H$2311,Data!$B$4:$B$2311,"UCO",Data!$C$4:$C$2311,"Argentina",Data!$E$4:$E$2311,2020,Data!$F$4:$F$2311,5) -> 0 | G18: =SUMIFS(Data!$H$4:$H$2311,Data!$B$4:$B$2311,"UCO",Data!$C$4:$C$2311,"Argentina",Data!$E$4:$E$2311,2020,Data!$F$4:$F$2311,6) -> 0 | H18: =SUMIFS(Data!$H$4:$H$2311,Data!$B$4:$B$2311,"UCO",Data!$C$4:$C$2311,"Argentina",Data!$E$4:$E$2311,2020,Data!$F$4:$F$2311,7) -> 0 | I18: =SUMIFS(Data!$H$4:$H$2311,Data!$B$4:$B$2311,"UCO",Data!$C$4:$C$2311,"Argentina",Data!$E$4:$E$2311,2020,Data!$F$4:$F$2311,8) -> 0 | J18: =SUMIFS(Data!$H$4:$H$2311,Data!$B$4:$B$2311,"UCO",Data!$C$4:$C$2311,"Argentina",Data!$E$4:$E$2311,2020,Data!$F$4:$F$2311,9) -> 0.039683207 | K18: =SUMIFS(Data!$H$4:$H$2311,Data!$B$4:$B$2311,"UCO",Data!$C$4:$C$2311,"Argentina",Data!$E$4:$E$2311,2020,Data!$F$4:$F$2311,10) -> 0 | L18: =SUMIFS(Data!$H$4:$H$2311,Data!$B$4:$B$2311,"UCO",Data!$C$4:$C$2311,"Argentina",Data!$E$4:$E$2311,2020,Data!$F$4:$F$2311,11) -> 0 | M18: =SUMIFS(Data!$H$4:$H$2311,Data!$B$4:$B$2311,"UCO",Data!$C$4:$C$2311,"Argentina",Data!$E$4:$E$2311,2020,Data!$F$4:$F$2311,12) -> 0 | N18: =SUM(B18:M18) -> 0.039683207
A19: Spain | B19: =SUMIFS(Data!$H$4:$H$2311,Data!$B$4:$B$2311,"UCO",Data!$C$4:$C$2311,"Spain",Data!$E$4:$E$2311,2020,Data!$F$4:$F$2311,1) -> 0 | C19: =SUMIFS(Data!$H$4:$H$2311,Data!$B$4:$B$2311,"UCO",Data!$C$4:$C$2311,"Spain",Data!$E$4:$E$2311,2020,Data!$F$4:$F$2311,2) -> 0 | D19: =SUMIFS(Data!$H$4:$H$2311,Data!$B$4:$B$2311,"UCO",Data!$C$4:$C$2311,"Spain",Data!$E$4:$E$2311,2020,Data!$F$4:$F$2311,3) -> 0.0014881203 | E19: =SUMIFS(Data!$H$4:$H$2311,Data!$B$4:$B$2311,"UCO",Data!$C$4:$C$2311,"Spain",Data!$E$4:$E$2311,2020,Data!$F$4:$F$2311,4) -> 0.0089838372 | F19: =SUMIFS(Data!$H$4:$H$2311,Data!$B$4:$B$2311,"UCO",Data!$C$4:$C$2311,"Spain",Data!$E$4:$E$2311,2020,Data!$F$4:$F$2311,5) -> 0.0048523744 | G19: =SUMIFS(Data!$H$4:$H$2311,Data!$B$4:$B$2311,"UCO",Data!$C$4:$C$2311,"Spain",Data!$E$4:$E$2311,2020,Data!$F$4:$F$2311,6) -> 0.0025132698 | H19: =SUMIFS(Data!$H$4:$H$2311,Data!$B$4:$B$2311,"UCO",Data!$C$4:$C$2311,"Spain",Data!$E$4:$E$2311,2020,Data!$F$4:$F$2311,7) -> 0.00066138679 | I19: =SUMIFS(Data!$H$4:$H$2311,Data!$B$4:$B$2311,"UCO",Data!$C$4:$C$2311,"Spain",Data!$E$4:$E$2311,2020,Data!$F$4:$F$2311,8) -> 0.0022046226 | J19: =SUMIFS(Data!$H$4:$H$2311,Data!$B$4:$B$2311,"UCO",Data!$C$4:$C$2311,"Spain",Data!$E$4:$E$2311,2020,Data!$F$4:$F$2311,9) -> 0 | K19: =SUMIFS(Data!$H$4:$H$2311,Data!$B$4:$B$2311,"UCO",Data!$C$4:$C$2311,"Spain",Data!$E$4:$E$2311,2020,Data!$F$4:$F$2311,10) -> 0 | L19: =SUMIFS(Data!$H$4:$H$2311,Data!$B$4:$B$2311,"UCO",Data!$C$4:$C$2311,"Spain",Data!$E$4:$E$2311,2020,Data!$F$4:$F$2311,11) -> 0.0044092452 | M19: =SUMIFS(Data!$H$4:$H$2311,Data!$B$4:$B$2311,"UCO",Data!$C$4:$C$2311,"Spain",Data!$E$4:$E$2311,2020,Data!$F$4:$F$2311,12) -> 0.0030864717 | N19: =SUM(B19:M19) -> 0.028199328
A20: Sweden | B20: =SUMIFS(Data!$H$4:$H$2311,Data!$B$4:$B$2311,"UCO",Data!$C$4:$C$2311,"Sweden",Data!$E$4:$E$2311,2020,Data!$F$4:$F$2311,1) -> 0 | C20: =SUMIFS(Data!$H$4:$H$2311,Data!$B$4:$B$2311,"UCO",Data!$C$4:$C$2311,"Sweden",Data!$E$4:$E$2311,2020,Data!$F$4:$F$2311,2) -> 0.0052381833 | D20: =SUMIFS(Data!$H$4:$H$2311,Data!$B$4:$B$2311,"UCO",Data!$C$4:$C$2311,"Sweden",Data!$E$4:$E$2311,2020,Data!$F$4:$F$2311,3) -> 0 | E20: =SUMIFS(Data!$H$4:$H$2311,Data!$B$4:$B$2311,"UCO",Data!$C$4:$C$2311,"Sweden",Data!$E$4:$E$2311,2020,Data!$F$4:$F$2311,4) -> 0 | F20: =SUMIFS(Data!$H$4:$H$2311,Data!$B$4:$B$2311,"UCO",Data!$C$4:$C$2311,"Sweden",Data!$E$4:$E$2311,2020,Data!$F$4:$F$2311,5) -> 0 | G20: =SUMIFS(Data!$H$4:$H$2311,Data!$B$4:$B$2311,"UCO",Data!$C$4:$C$2311,"Sweden",Data!$E$4:$E$2311,2020,Data!$F$4:$F$2311,6) -> 0 | H20: =SUMIFS(Data!$H$4:$H$2311,Data!$B$4:$B$2311,"UCO",Data!$C$4:$C$2311,"Sweden",Data!$E$4:$E$2311,2020,Data!$F$4:$F$2311,7) -> 0.0019047939 | I20: =SUMIFS(Data!$H$4:$H$2311,Data!$B$4:$B$2311,"UCO",Data!$C$4:$C$2311,"Sweden",Data!$E$4:$E$2311,2020,Data!$F$4:$F$2311,8) -> 0.012381161 | J20: =SUMIFS(Data!$H$4:$H$2311,Data!$B$4:$B$2311,"UCO",Data!$C$4:$C$2311,"Sweden",Data!$E$4:$E$2311,2020,Data!$F$4:$F$2311,9) -> 0 | K20: =SUMIFS(Data!$H$4:$H$2311,Data!$B$4:$B$2311,"UCO",Data!$C$4:$C$2311,"Sweden",Data!$E$4:$E$2311,2020,Data!$F$4:$F$2311,10) -> 0 | L20: =SUMIFS(Data!$H$4:$H$2311,Data!$B$4:$B$2311,"UCO",Data!$C$4:$C$2311,"Sweden",Data!$E$4:$E$2311,2020,Data!$F$4:$F$2311,11) -> 0 | M20: =SUMIFS(Data!$H$4:$H$2311,Data!$B$4:$B$2311,"UCO",Data!$C$4:$C$2311,"Sweden",Data!$E$4:$E$2311,2020,Data!$F$4:$F$2311,12) -> 0 | N20: =SUM(B20:M20) -> 0.019524138
A21: Ecuador | B21: =SUMIFS(Data!$H$4:$H$2311,Data!$B$4:$B$2311,"UCO",Data!$C$4:$C$2311,"Ecuador",Data!$E$4:$E$2311,2020,Data!$F$4:$F$2311,1) -> 0 | C21: =SUMIFS(Data!$H$4:$H$2311,Data!$B$4:$B$2311,"UCO",Data!$C$4:$C$2311,"Ecuador",Data!$E$4:$E$2311,2020,Data!$F$4:$F$2311,2) -> 0 | D21: =SUMIFS(Data!$H$4:$H$2311,Data!$B$4:$B$2311,"UCO",Data!$C$4:$C$2311,"Ecuador",Data!$E$4:$E$2311,2020,Data!$F$4:$F$2311,3) -> 0.0026786165 | E21: =SUMIFS(Data!$H$4:$H$2311,Data!$B$4:$B$2311,"UCO",Data!$C$4:$C$2311,"Ecuador",Data!$E$4:$E$2311,2020,Data!$F$4:$F$2311,4) -> 0 | F21: =SUMIFS(Data!$H$4:$H$2311,Data!$B$4:$B$2311,"UCO",Data!$C$4:$C$2311,"Ecuador",Data!$E$4:$E$2311,2020,Data!$F$4:$F$2311,5) -> 0 | G21: =SUMIFS(Data!$H$4:$H$2311,Data!$B$4:$B$2311,"UCO",Data!$C$4:$C$2311,"Ecuador",Data!$E$4:$E$2311,2020,Data!$F$4:$F$2311,6) -> 0.0026786165 | H21: =SUMIFS(Data!$H$4:$H$2311,Data!$B$4:$B$2311,"UCO",Data!$C$4:$C$2311,"Ecuador",Data!$E$4:$E$2311,2020,Data!$F$4:$F$2311,7) -> 0 | I21: =SUMIFS(Data!$H$4:$H$2311,Data!$B$4:$B$2311,"UCO",Data!$C$4:$C$2311,"Ecuador",Data!$E$4:$E$2311,2020,Data!$F$4:$F$2311,8) -> 0 | J21: =SUMIFS(Data!$H$4:$H$2311,Data!$B$4:$B$2311,"UCO",Data!$C$4:$C$2311,"Ecuador",Data!$E$4:$E$2311,2020,Data!$F$4:$F$2311,9) -> 0 | K21: =SUMIFS(Data!$H$4:$H$2311,Data!$B$4:$B$2311,"UCO",Data!$C$4:$C$2311,"Ecuador",Data!$E$4:$E$2311,2020,Data!$F$4:$F$2311,10) -> 0.0026786165 | L21: =SUMIFS(Data!$H$4:$H$2311,Data!$B$4:$B$2311,"UCO",Data!$C$4:$C$2311,"Ecuador",Data!$E$4:$E$2311,2020,Data!$F$4:$F$2311,11) -> 0 | M21: =SUMIFS(Data!$H$4:$H$2311,Data!$B$4:$B$2311,"UCO",Data!$C$4:$C$2311,"Ecuador",Data!$E$4:$E$2311,2020,Data!$F$4:$F$2311,12) -> 0 | N21: =SUM(B21:M21) -> 0.0080358495
A22: Jamaica | B22: =SUMIFS(Data!$H$4:$H$2311,Data!$B$4:$B$2311,"UCO",Data!$C$4:$C$2311,"Jamaica",Data!$E$4:$E$2311,2020,Data!$F$4:$F$2311,1) -> 0 | C22: =SUMIFS(Data!$H$4:$H$2311,Data!$B$4:$B$2311,"UCO",Data!$C$4:$C$2311,"Jamaica",Data!$E$4:$E$2311,2020,Data!$F$4:$F$2311,2) -> 0 | D22: =SUMIFS(Data!$H$4:$H$2311,Data!$B$4:$B$2311,"UCO",Data!$C$4:$C$2311,"Jamaica",Data!$E$4:$E$2311,2020,Data!$F$4:$F$2311,3) -> 0.0042306708 | E22: =SUMIFS(Data!$H$4:$H$2311,Data!$B$4:$B$2311,"UCO",Data!$C$4:$C$2311,"Jamaica",Data!$E$4:$E$2311,2020,Data!$F$4:$F$2311,4) -> 0 | F22: =SUMIFS(Data!$H$4:$H$2311,Data!$B$4:$B$2311,"UCO",Data!$C$4:$C$2311,"Jamaica",Data!$E$4:$E$2311,2020,Data!$F$4:$F$2311,5) -> 0 | G22: =SUMIFS(Data!$H$4:$H$2311,Data!$B$4:$B$2311,"UCO",Data!$C$4:$C$2311,"Jamaica",Data!$E$4:$E$2311,2020,Data!$F$4:$F$2311,6) -> 0 | H22: =SUMIFS(Data!$H$4:$H$2311,Data!$B$4:$B$2311,"UCO",Data!$C$4:$C$2311,"Jamaica",Data!$E$4:$E$2311,2020,Data!$F$4:$F$2311,7) -> 0 | I22: =SUMIFS(Data!$H$4:$H$2311,Data!$B$4:$B$2311,"UCO",Data!$C$4:$C$2311,"Jamaica",Data!$E$4:$E$2311,2020,Data!$F$4:$F$2311,8) -> 0 | J22: =SUMIFS(Data!$H$4:$H$2311,Data!$B$4:$B$2311,"UCO",Data!$C$4:$C$2311,"Jamaica",Data!$E$4:$E$2311,2020,Data!$F$4:$F$2311,9) -> 0 | K22: =SUMIFS(Data!$H$4:$H$2311,Data!$B$4:$B$2311,"UCO",Data!$C$4:$C$2311,"Jamaica",Data!$E$4:$E$2311,2020,Data!$F$4:$F$2311,10) -> 0 | L22: =SUMIFS(Data!$H$4:$H$2311,Data!$B$4:$B$2311,"UCO",Data!$C$4:$C$2311,"Jamaica",Data!$E$4:$E$2311,2020,Data!$F$4:$F$2311,11) -> 0 | M22: =SUMIFS(Data!$H$4:$H$2311,Data!$B$4:$B$2311,"UCO",Data!$C$4:$C$2311,"Jamaica",Data!$E$4:$E$2311,2020,Data!$F$4:$F$2311,12) -> 0 | N22: =SUM(B22:M22) -> 0.0042306708
A23: Belgium | B23: =SUMIFS(Data!$H$4:$H$2311,Data!$B$4:$B$2311,"UCO",Data!$C$4:$C$2311,"Belgium",Data!$E$4:$E$2311,2020,Data!$F$4:$F$2311,1) -> 0 | C23: =SUMIFS(Data!$H$4:$H$2311,Data!$B$4:$B$2311,"UCO",Data!$C$4:$C$2311,"Belgium",Data!$E$4:$E$2311,2020,Data!$F$4:$F$2311,2) -> 0 | D23: =SUMIFS(Data!$H$4:$H$2311,Data!$B$4:$B$2311,"UCO",Data!$C$4:$C$2311,"Belgium",Data!$E$4:$E$2311,2020,Data!$F$4:$F$2311,3) -> 0 | E23: =SUMIFS(Data!$H$4:$H$2311,Data!$B$4:$B$2311,"UCO",Data!$C$4:$C$2311,"Belgium",Data!$E$4:$E$2311,2020,Data!$F$4:$F$2311,4) -> 0.0023148538 | F23: =SUMIFS(Data!$H$4:$H$2311,Data!$B$4:$B$2311,"UCO",Data!$C$4:$C$2311,"Belgium",Data!$E$4:$E$2311,2020,Data!$F$4:$F$2311,5) -> 0 | G23: =SUMIFS(Data!$H$4:$H$2311,Data!$B$4:$B$2311,"UCO",Data!$C$4:$C$2311,"Belgium",Data!$E$4:$E$2311,2020,Data!$F$4:$F$2311,6) -> 0 | H23: =SUMIFS(Data!$H$4:$H$2311,Data!$B$4:$B$2311,"UCO",Data!$C$4:$C$2311,"Belgium",Data!$E$4:$E$2311,2020,Data!$F$4:$F$2311,7) -> 0 | I23: =SUMIFS(Data!$H$4:$H$2311,Data!$B$4:$B$2311,"UCO",Data!$C$4:$C$2311,"Belgium",Data!$E$4:$E$2311,2020,Data!$F$4:$F$2311,8) -> 0 | J23: =SUMIFS(Data!$H$4:$H$2311,Data!$B$4:$B$2311,"UCO",Data!$C$4:$C$2311,"Belgium",Data!$E$4:$E$2311,2020,Data!$F$4:$F$2311,9) -> 0 | K23: =SUMIFS(Data!$H$4:$H$2311,Data!$B$4:$B$2311,"UCO",Data!$C$4:$C$2311,"Belgium",Data!$E$4:$E$2311,2020,Data!$F$4:$F$2311,10) -> 0 | L23: =SUMIFS(Data!$H$4:$H$2311,Data!$B$4:$B$2311,"UCO",Data!$C$4:$C$2311,"Belgium",Data!$E$4:$E$2311,2020,Data!$F$4:$F$2311,11) -> 0.0014308001 | M23: =SUMIFS(Data!$H$4:$H$2311,Data!$B$4:$B$2311,"UCO",Data!$C$4:$C$2311,"Belgium",Data!$E$4:$E$2311,2020,Data!$F$4:$F$2311,12) -> 0 | N23: =SUM(B23:M23) -> 0.0037456538
A24: United Kingdom | B24: =SUMIFS(Data!$H$4:$H$2311,Data!$B$4:$B$2311,"UCO",Data!$C$4:$C$2311,"United Kingdom",Data!$E$4:$E$2311,2020,Data!$F$4:$F$2311,1) -> 0 | C24: =SUMIFS(Data!$H$4:$H$2311,Data!$B$4:$B$2311,"UCO",Data!$C$4:$C$2311,"United Kingdom",Data!$E$4:$E$2311,2020,Data!$F$4:$F$2311,2) -> 0 | D24: =SUMIFS(Data!$H$4:$H$2311,Data!$B$4:$B$2311,"UCO",Data!$C$4:$C$2311,"United Kingdom",Data!$E$4:$E$2311,2020,Data!$F$4:$F$2311,3) -> 0.00052910943 | E24: =SUMIFS(Data!$H$4:$H$2311,Data!$B$4:$B$2311,"UCO",Data!$C$4:$C$2311,"United Kingdom",Data!$E$4:$E$2311,2020,Data!$F$4:$F$2311,4) -> 0.0025992501 | F24: =SUMIFS(Data!$H$4:$H$2311,Data!$B$4:$B$2311,"UCO",Data!$C$4:$C$2311,"United Kingdom",Data!$E$4:$E$2311,2020,Data!$F$4:$F$2311,5) -> 0 | G24: =SUMIFS(Data!$H$4:$H$2311,Data!$B$4:$B$2311,"UCO",Data!$C$4:$C$2311,"United Kingdom",Data!$E$4:$E$2311,2020,Data!$F$4:$F$2311,6) -> 0 | H24: =SUMIFS(Data!$H$4:$H$2311,Data!$B$4:$B$2311,"UCO",Data!$C$4:$C$2311,"United Kingdom",Data!$E$4:$E$2311,2020,Data!$F$4:$F$2311,7) -> 0 | I24: =SUMIFS(Data!$H$4:$H$2311,Data!$B$4:$B$2311,"UCO",Data!$C$4:$C$2311,"United Kingdom",Data!$E$4:$E$2311,2020,Data!$F$4:$F$2311,8) -> 0 | J24: =SUMIFS(Data!$H$4:$H$2311,Data!$B$4:$B$2311,"UCO",Data!$C$4:$C$2311,"United Kingdom",Data!$E$4:$E$2311,2020,Data!$F$4:$F$2311,9) -> 0 | K24: =SUMIFS(Data!$H$4:$H$2311,Data!$B$4:$B$2311,"UCO",Data!$C$4:$C$2311,"United Kingdom",Data!$E$4:$E$2311,2020,Data!$F$4:$F$2311,10) -> 0.00046297075 | L24: =SUMIFS(Data!$H$4:$H$2311,Data!$B$4:$B$2311,"UCO",Data!$C$4:$C$2311,"United Kingdom",Data!$E$4:$E$2311,2020,Data!$F$4:$F$2311,11) -> 0 | M24: =SUMIFS(Data!$H$4:$H$2311,Data!$B$4:$B$2311,"UCO",Data!$C$4:$C$2311,"United Kingdom",Data!$E$4:$E$2311,2020,Data!$F$4:$F$2311,12) -> 0 | N24: =SUM(B24:M24) -> 0.0035913303
A25: Vietnam | B25: =SUMIFS(Data!$H$4:$H$2311,Data!$B$4:$B$2311,"UCO",Data!$C$4:$C$2311,"Vietnam",Data!$E$4:$E$2311,2020,Data!$F$4:$F$2311,1) -> 0 | C25: =SUMIFS(Data!$H$4:$H$2311,Data!$B$4:$B$2311,"UCO",Data!$C$4:$C$2311,"Vietnam",Data!$E$4:$E$2311,2020,Data!$F$4:$F$2311,2) -> 0 | D25: =SUMIFS(Data!$H$4:$H$2311,Data!$B$4:$B$2311,"UCO",Data!$C$4:$C$2311,"Vietnam",Data!$E$4:$E$2311,2020,Data!$F$4:$F$2311,3) -> 0 | E25: =SUMIFS(Data!$H$4:$H$2311,Data!$B$4:$B$2311,"UCO",Data!$C$4:$C$2311,"Vietnam",Data!$E$4:$E$2311,2020,Data!$F$4:$F$2311,4) -> 0 | F25: =SUMIFS(Data!$H$4:$H$2311,Data!$B$4:$B$2311,"UCO",Data!$C$4:$C$2311,"Vietnam",Data!$E$4:$E$2311,2020,Data!$F$4:$F$2311,5) -> 0 | G25: =SUMIFS(Data!$H$4:$H$2311,Data!$B$4:$B$2311,"UCO",Data!$C$4:$C$2311,"Vietnam",Data!$E$4:$E$2311,2020,Data!$F$4:$F$2311,6) -> 0 | H25: =SUMIFS(Data!$H$4:$H$2311,Data!$B$4:$B$2311,"UCO",Data!$C$4:$C$2311,"Vietnam",Data!$E$4:$E$2311,2020,Data!$F$4:$F$2311,7) -> 0 | I25: =SUMIFS(Data!$H$4:$H$2311,Data!$B$4:$B$2311,"UCO",Data!$C$4:$C$2311,"Vietnam",Data!$E$4:$E$2311,2020,Data!$F$4:$F$2311,8) -> 0 | J25: =SUMIFS(Data!$H$4:$H$2311,Data!$B$4:$B$2311,"UCO",Data!$C$4:$C$2311,"Vietnam",Data!$E$4:$E$2311,2020,Data!$F$4:$F$2311,9) -> 0 | K25: =SUMIFS(Data!$H$4:$H$2311,Data!$B$4:$B$2311,"UCO",Data!$C$4:$C$2311,"Vietnam",Data!$E$4:$E$2311,2020,Data!$F$4:$F$2311,10) -> 0 | L25: =SUMIFS(Data!$H$4:$H$2311,Data!$B$4:$B$2311,"UCO",Data!$C$4:$C$2311,"Vietnam",Data!$E$4:$E$2311,2020,Data!$F$4:$F$2311,11) -> 0 | M25: =SUMIFS(Data!$H$4:$H$2311,Data!$B$4:$B$2311,"UCO",Data!$C$4:$C$2311,"Vietnam",Data!$E$4:$E$2311,2020,Data!$F$4:$F$2311,12) -> 0.0028086892 | N25: =SUM(B25:M25) -> 0.0028086892
A26: Switzerland | B26: =SUMIFS(Data!$H$4:$H$2311,Data!$B$4:$B$2311,"UCO",Data!$C$4:$C$2311,"Switzerland",Data!$E$4:$E$2311,2020,Data!$F$4:$F$2311,1) -> 0.0004188783 | C26: =SUMIFS(Data!$H$4:$H$2311,Data!$B$4:$B$2311,"UCO",Data!$C$4:$C$2311,"Switzerland",Data!$E$4:$E$2311,2020,Data!$F$4:$F$2311,2) -> 0.0001653467 | D26: =SUMIFS(Data!$H$4:$H$2311,Data!$B$4:$B$2311,"UCO",Data!$C$4:$C$2311,"Switzerland",Data!$E$4:$E$2311,2020,Data!$F$4:$F$2311,3) -> 0.0008377566 | E26: =SUMIFS(Data!$H$4:$H$2311,Data!$B$4:$B$2311,"UCO",Data!$C$4:$C$2311,"Switzerland",Data!$E$4:$E$2311,2020,Data!$F$4:$F$2311,4) -> 0 | F26: =SUMIFS(Data!$H$4:$H$2311,Data!$B$4:$B$2311,"UCO",Data!$C$4:$C$2311,"Switzerland",Data!$E$4:$E$2311,2020,Data!$F$4:$F$2311,5) -> 0 | G26: =SUMIFS(Data!$H$4:$H$2311,Data!$B$4:$B$2311,"UCO",Data!$C$4:$C$2311,"Switzerland",Data!$E$4:$E$2311,2020,Data!$F$4:$F$2311,6) -> 0 | H26: =SUMIFS(Data!$H$4:$H$2311,Data!$B$4:$B$2311,"UCO",Data!$C$4:$C$2311,"Switzerland",Data!$E$4:$E$2311,2020,Data!$F$4:$F$2311,7) -> 0 | I26: =SUMIFS(Data!$H$4:$H$2311,Data!$B$4:$B$2311,"UCO",Data!$C$4:$C$2311,"Switzerland",Data!$E$4:$E$2311,2020,Data!$F$4:$F$2311,8) -> 0 | J26: =SUMIFS(Data!$H$4:$H$2311,Data!$B$4:$B$2311,"UCO",Data!$C$4:$C$2311,"Switzerland",Data!$E$4:$E$2311,2020,Data!$F$4:$F$2311,9) -> 0 | K26: =SUMIFS(Data!$H$4:$H$2311,Data!$B$4:$B$2311,"UCO",Data!$C$4:$C$2311,"Switzerland",Data!$E$4:$E$2311,2020,Data!$F$4:$F$2311,10) -> 0 | L26: =SUMIFS(Data!$H$4:$H$2311,Data!$B$4:$B$2311,"UCO",Data!$C$4:$C$2311,"Switzerland",Data!$E$4:$E$2311,2020,Data!$F$4:$F$2311,11) -> 0 | M26: =SUMIFS(Data!$H$4:$H$2311,Data!$B$4:$B$2311,"UCO",Data!$C$4:$C$2311,"Switzerland",Data!$E$4:$E$2311,2020,Data!$F$4:$F$2311,12) -> 0 | N26: =SUM(B26:M26) -> 0.0014219816
A27: Portugal | B27: =SUMIFS(Data!$H$4:$H$2311,Data!$B$4:$B$2311,"UCO",Data!$C$4:$C$2311,"Portugal",Data!$E$4:$E$2311,2020,Data!$F$4:$F$2311,1) -> 0.0011111298 | C27: =SUMIFS(Data!$H$4:$H$2311,Data!$B$4:$B$2311,"UCO",Data!$C$4:$C$2311,"Portugal",Data!$E$4:$E$2311,2020,Data!$F$4:$F$2311,2) -> 0 | D27: =SUMIFS(Data!$H$4:$H$2311,Data!$B$4:$B$2311,"UCO",Data!$C$4:$C$2311,"Portugal",Data!$E$4:$E$2311,2020,Data!$F$4:$F$2311,3) -> 0 | E27: =SUMIFS(Data!$H$4:$H$2311,Data!$B$4:$B$2311,"UCO",Data!$C$4:$C$2311,"Portugal",Data!$E$4:$E$2311,2020,Data!$F$4:$F$2311,4) -> 0 | F27: =SUMIFS(Data!$H$4:$H$2311,Data!$B$4:$B$2311,"UCO",Data!$C$4:$C$2311,"Portugal",Data!$E$4:$E$2311,2020,Data!$F$4:$F$2311,5) -> 0 | G27: =SUMIFS(Data!$H$4:$H$2311,Data!$B$4:$B$2311,"UCO",Data!$C$4:$C$2311,"Portugal",Data!$E$4:$E$2311,2020,Data!$F$4:$F$2311,6) -> 0 | H27: =SUMIFS(Data!$H$4:$H$2311,Data!$B$4:$B$2311,"UCO",Data!$C$4:$C$2311,"Portugal",Data!$E$4:$E$2311,2020,Data!$F$4:$F$2311,7) -> 0 | I27: =SUMIFS(Data!$H$4:$H$2311,Data!$B$4:$B$2311,"UCO",Data!$C$4:$C$2311,"Portugal",Data!$E$4:$E$2311,2020,Data!$F$4:$F$2311,8) -> 0 | J27: =SUMIFS(Data!$H$4:$H$2311,Data!$B$4:$B$2311,"UCO",Data!$C$4:$C$2311,"Portugal",Data!$E$4:$E$2311,2020,Data!$F$4:$F$2311,9) -> 0 | K27: =SUMIFS(Data!$H$4:$H$2311,Data!$B$4:$B$2311,"UCO",Data!$C$4:$C$2311,"Portugal",Data!$E$4:$E$2311,2020,Data!$F$4:$F$2311,10) -> 0 | L27: =SUMIFS(Data!$H$4:$H$2311,Data!$B$4:$B$2311,"UCO",Data!$C$4:$C$2311,"Portugal",Data!$E$4:$E$2311,2020,Data!$F$4:$F$2311,11) -> 0 | M27: =SUMIFS(Data!$H$4:$H$2311,Data!$B$4:$B$2311,"UCO",Data!$C$4:$C$2311,"Portugal",Data!$E$4:$E$2311,2020,Data!$F$4:$F$2311,12) -> 0 | N27: =SUM(B27:M27) -> 0.0011111298
A28: New Zealand | B28: =SUMIFS(Data!$H$4:$H$2311,Data!$B$4:$B$2311,"UCO",Data!$C$4:$C$2311,"New Zealand",Data!$E$4:$E$2311,2020,Data!$F$4:$F$2311,1) -> 0 | C28: =SUMIFS(Data!$H$4:$H$2311,Data!$B$4:$B$2311,"UCO",Data!$C$4:$C$2311,"New Zealand",Data!$E$4:$E$2311,2020,Data!$F$4:$F$2311,2) -> 0 | D28: =SUMIFS(Data!$H$4:$H$2311,Data!$B$4:$B$2311,"UCO",Data!$C$4:$C$2311,"New Zealand",Data!$E$4:$E$2311,2020,Data!$F$4:$F$2311,3) -> 7.7161792e-05 | E28: =SUMIFS(Data!$H$4:$H$2311,Data!$B$4:$B$2311,"UCO",Data!$C$4:$C$2311,"New Zealand",Data!$E$4:$E$2311,2020,Data!$F$4:$F$2311,4) -> 0 | F28: =SUMIFS(Data!$H$4:$H$2311,Data!$B$4:$B$2311,"UCO",Data!$C$4:$C$2311,"New Zealand",Data!$E$4:$E$2311,2020,Data!$F$4:$F$2311,5) -> 0 | G28: =SUMIFS(Data!$H$4:$H$2311,Data!$B$4:$B$2311,"UCO",Data!$C$4:$C$2311,"New Zealand",Data!$E$4:$E$2311,2020,Data!$F$4:$F$2311,6) -> 0 | H28: =SUMIFS(Data!$H$4:$H$2311,Data!$B$4:$B$2311,"UCO",Data!$C$4:$C$2311,"New Zealand",Data!$E$4:$E$2311,2020,Data!$F$4:$F$2311,7) -> 0 | I28: =SUMIFS(Data!$H$4:$H$2311,Data!$B$4:$B$2311,"UCO",Data!$C$4:$C$2311,"New Zealand",Data!$E$4:$E$2311,2020,Data!$F$4:$F$2311,8) -> 0 | J28: =SUMIFS(Data!$H$4:$H$2311,Data!$B$4:$B$2311,"UCO",Data!$C$4:$C$2311,"New Zealand",Data!$E$4:$E$2311,2020,Data!$F$4:$F$2311,9) -> 0 | K28: =SUMIFS(Data!$H$4:$H$2311,Data!$B$4:$B$2311,"UCO",Data!$C$4:$C$2311,"New Zealand",Data!$E$4:$E$2311,2020,Data!$F$4:$F$2311,10) -> 0 | L28: =SUMIFS(Data!$H$4:$H$2311,Data!$B$4:$B$2311,"UCO",Data!$C$4:$C$2311,"New Zealand",Data!$E$4:$E$2311,2020,Data!$F$4:$F$2311,11) -> 0 | M28: =SUMIFS(Data!$H$4:$H$2311,Data!$B$4:$B$2311,"UCO",Data!$C$4:$C$2311,"New Zealand",Data!$E$4:$E$2311,2020,Data!$F$4:$F$2311,12) -> 0 | N28: =SUM(B28:M28) -> 7.7161792e-05
A29: Italy | B29: =SUMIFS(Data!$H$4:$H$2311,Data!$B$4:$B$2311,"UCO",Data!$C$4:$C$2311,"Italy",Data!$E$4:$E$2311,2020,Data!$F$4:$F$2311,1) -> 0 | C29: =SUMIFS(Data!$H$4:$H$2311,Data!$B$4:$B$2311,"UCO",Data!$C$4:$C$2311,"Italy",Data!$E$4:$E$2311,2020,Data!$F$4:$F$2311,2) -> 0 | D29: =SUMIFS(Data!$H$4:$H$2311,Data!$B$4:$B$2311,"UCO",Data!$C$4:$C$2311,"Italy",Data!$E$4:$E$2311,2020,Data!$F$4:$F$2311,3) -> 0 | E29: =SUMIFS(Data!$H$4:$H$2311,Data!$B$4:$B$2311,"UCO",Data!$C$4:$C$2311,"Italy",Data!$E$4:$E$2311,2020,Data!$F$4:$F$2311,4) -> 0 | F29: =SUMIFS(Data!$H$4:$H$2311,Data!$B$4:$B$2311,"UCO",Data!$C$4:$C$2311,"Italy",Data!$E$4:$E$2311,2020,Data!$F$4:$F$2311,5) -> 0 | G29: =SUMIFS(Data!$H$4:$H$2311,Data!$B$4:$B$2311,"UCO",Data!$C$4:$C$2311,"Italy",Data!$E$4:$E$2311,2020,Data!$F$4:$F$2311,6) -> 0 | H29: =SUMIFS(Data!$H$4:$H$2311,Data!$B$4:$B$2311,"UCO",Data!$C$4:$C$2311,"Italy",Data!$E$4:$E$2311,2020,Data!$F$4:$F$2311,7) -> 0 | I29: =SUMIFS(Data!$H$4:$H$2311,Data!$B$4:$B$2311,"UCO",Data!$C$4:$C$2311,"Italy",Data!$E$4:$E$2311,2020,Data!$F$4:$F$2311,8) -> 0 | J29: =SUMIFS(Data!$H$4:$H$2311,Data!$B$4:$B$2311,"UCO",Data!$C$4:$C$2311,"Italy",Data!$E$4:$E$2311,2020,Data!$F$4:$F$2311,9) -> 2.2046226e-05 | K29: =SUMIFS(Data!$H$4:$H$2311,Data!$B$4:$B$2311,"UCO",Data!$C$4:$C$2311,"Italy",Data!$E$4:$E$2311,2020,Data!$F$4:$F$2311,10) -> 0 | L29: =SUMIFS(Data!$H$4:$H$2311,Data!$B$4:$B$2311,"UCO",Data!$C$4:$C$2311,"Italy",Data!$E$4:$E$2311,2020,Data!$F$4:$F$2311,11) -> 0 | M29: =SUMIFS(Data!$H$4:$H$2311,Data!$B$4:$B$2311,"UCO",Data!$C$4:$C$2311,"Italy",Data!$E$4:$E$2311,2020,Data!$F$4:$F$2311,12) -> 0 | N29: =SUM(B29:M29) -> 2.2046226e-05
B31: Jan-21 | C31: Feb-21 | D31: Mar-21 | E31: Apr-21 | F31: May-21 | G31: Jun-21 | H31: Jul-21 | I31: Aug-21 | J31: Sep-21 | K31: Oct-21 | L31: Nov-21 | M31: Dec-21 | N31: Total
A32: World Total | B32: =SUM(B33:B57) -> 16.636858 | C32: =SUM(C33:C57) -> 18.960098 | D32: =SUM(D33:D57) -> 28.003119 | E32: =SUM(E33:E57) -> 19.755196 | F32: =SUM(F33:F57) -> 23.516207 | G32: =SUM(G33:G57) -> 18.141416 | H32: =SUM(H33:H57) -> 19.58109 | I32: =SUM(I33:I57) -> 21.50892 | ... M32: =SUM(M33:M57) -> 27.701099 | N32: =SUM(B32:M32) -> 283.65253
A33: Canada | B33: =SUMIFS(Data!$H$4:$H$2311,Data!$B$4:$B$2311,"UCO",Data!$C$4:$C$2311,"Canada",Data!$E$4:$E$2311,2021,Data!$F$4:$F$2311,1) -> 14.384276 | C33: =SUMIFS(Data!$H$4:$H$2311,Data!$B$4:$B$2311,"UCO",Data!$C$4:$C$2311,"Canada",Data!$E$4:$E$2311,2021,Data!$F$4:$F$2311,2) -> 16.949685 | D33: =SUMIFS(Data!$H$4:$H$2311,Data!$B$4:$B$2311,"UCO",Data!$C$4:$C$2311,"Canada",Data!$E$4:$E$2311,2021,Data!$F$4:$F$2311,3) -> 25.44116 | E33: =SUMIFS(Data!$H$4:$H$2311,Data!$B$4:$B$2311,"UCO",Data!$C$4:$C$2311,"Canada",Data!$E$4:$E$2311,2021,Data!$F$4:$F$2311,4) -> 18.298967 | F33: =SUMIFS(Data!$H$4:$H$2311,Data!$B$4:$B$2311,"UCO",Data!$C$4:$C$2311,"Canada",Data!$E$4:$E$2311,2021,Data!$F$4:$F$2311,5) -> 21.86856 | G33: =SUMIFS(Data!$H$4:$H$2311,Data!$B$4:$B$2311,"UCO",Data!$C$4:$C$2311,"Canada",Data!$E$4:$E$2311,2021,Data!$F$4:$F$2311,6) -> 16.575768 | H33: =SUMIFS(Data!$H$4:$H$2311,Data!$B$4:$B$2311,"UCO",Data!$C$4:$C$2311,"Canada",Data!$E$4:$E$2311,2021,Data!$F$4:$F$2311,7) -> 16.115787 | I33: =SUMIFS(Data!$H$4:$H$2311,Data!$B$4:$B$2311,"UCO",Data!$C$4:$C$2311,"Canada",Data!$E$4:$E$2311,2021,Data!$F$4:$F$2311,8) -> 16.723257 | J33: =SUMIFS(Data!$H$4:$H$2311,Data!$B$4:$B$2311,"UCO",Data!$C$4:$C$2311,"Canada",Data!$E$4:$E$2311,2021,Data!$F$4:$F$2311,9) -> 14.192591 | K33: =SUMIFS(Data!$H$4:$H$2311,Data!$B$4:$B$2311,"UCO",Data!$C$4:$C$2311,"Canada",Data!$E$4:$E$2311,2021,Data!$F$4:$F$2311,10) -> 25.106108 | L33: =SUMIFS(Data!$H$4:$H$2311,Data!$B$4:$B$2311,"UCO",Data!$C$4:$C$2311,"Canada",Data!$E$4:$E$2311,2021,Data!$F$4:$F$2311,11) -> 28.69089 | M33: =SUMIFS(Data!$H$4:$H$2311,Data!$B$4:$B$2311,"UCO",Data!$C$4:$C$2311,"Canada",Data!$E$4:$E$2311,2021,Data!$F$4:$F$2311,12) -> 23.057762 | N33: =SUM(B33:M33) -> 237.40481
A34: Chile | B34: =SUMIFS(Data!$H$4:$H$2311,Data!$B$4:$B$2311,"UCO",Data!$C$4:$C$2311,"Chile",Data!$E$4:$E$2311,2021,Data!$F$4:$F$2311,1) -> 1.6041474 | C34: =SUMIFS(Data!$H$4:$H$2311,Data!$B$4:$B$2311,"UCO",Data!$C$4:$C$2311,"Chile",Data!$E$4:$E$2311,2021,Data!$F$4:$F$2311,2) -> 1.1377396 | D34: =SUMIFS(Data!$H$4:$H$2311,Data!$B$4:$B$2311,"UCO",Data!$C$4:$C$2311,"Chile",Data!$E$4:$E$2311,2021,Data!$F$4:$F$2311,3) -> 1.7453556 | E34: =SUMIFS(Data!$H$4:$H$2311,Data!$B$4:$B$2311,"UCO",Data!$C$4:$C$2311,"Chile",Data!$E$4:$E$2311,2021,Data!$F$4:$F$2311,4) -> 1.0095628 | F34: =SUMIFS(Data!$H$4:$H$2311,Data!$B$4:$B$2311,"UCO",Data!$C$4:$C$2311,"Chile",Data!$E$4:$E$2311,2021,Data!$F$4:$F$2311,5) -> 0.96518378 | G34: =SUMIFS(Data!$H$4:$H$2311,Data!$B$4:$B$2311,"UCO",Data!$C$4:$C$2311,"Chile",Data!$E$4:$E$2311,2021,Data!$F$4:$F$2311,6) -> 0.22504788 | H34: =SUMIFS(Data!$H$4:$H$2311,Data!$B$4:$B$2311,"UCO",Data!$C$4:$C$2311,"Chile",Data!$E$4:$E$2311,2021,Data!$F$4:$F$2311,7) -> 1.0057047 | I34: =SUMIFS(Data!$H$4:$H$2311,Data!$B$4:$B$2311,"UCO",Data!$C$4:$C$2311,"Chile",Data!$E$4:$E$2311,2021,Data!$F$4:$F$2311,8) -> 0.51072288 | J34: =SUMIFS(Data!$H$4:$H$2311,Data!$B$4:$B$2311,"UCO",Data!$C$4:$C$2311,"Chile",Data!$E$4:$E$2311,2021,Data!$F$4:$F$2311,9) -> 0.92931457 | K34: =SUMIFS(Data!$H$4:$H$2311,Data!$B$4:$B$2311,"UCO",Data!$C$4:$C$2311,"Chile",Data!$E$4:$E$2311,2021,Data!$F$4:$F$2311,10) -> 0.36989158 | L34: =SUMIFS(Data!$H$4:$H$2311,Data!$B$4:$B$2311,"UCO",Data!$C$4:$C$2311,"Chile",Data!$E$4:$E$2311,2021,Data!$F$4:$F$2311,11) -> 6.3257634 | M34: =SUMIFS(Data!$H$4:$H$2311,Data!$B$4:$B$2311,"UCO",Data!$C$4:$C$2311,"Chile",Data!$E$4:$E$2311,2021,Data!$F$4:$F$2311,12) -> 1.7822897 | N34: =SUM(B34:M34) -> 17.610724
